Workbook
Name Cfg_Struttura: CONFIGURATORE!$B$3
Name Cfg_Trave: CONFIGURATORE!$B$4
Name Cfg_SpAsse: CONFIGURATORE!$B$5
Name Cfg_SpOmega: CONFIGURATORE!$B$6
Name Cfg_Infissione: CONFIGURATORE!$B$7
Name Cfg_Luce: CONFIGURATORE!$B$8
Name Cfg_LenFond: CONFIGURATORE!$B$9
Name Cfg_LenCusc: CONFIGURATORE!$B$10
Name Cfg_LenMot: CONFIGURATORE!$B$11
Name Cfg_Pannelli: CONFIGURATORE!$B$12
Name Cfg_Margine: CONFIGURATORE!$B$13
Name Cfg_TraveFrag: CONFIGURATORE!$B$15
Name Cfg_n12: CONFIGURATORE!$B$20
Name Cfg_n18: CONFIGURATORE!$B$21
Name Cfg_n20: CONFIGURATORE!$B$22
Name Cfg_n22: CONFIGURATORE!$B$23
Name Cfg_n36: CONFIGURATORE!$B$24
Name Cfg_n40: CONFIGURATORE!$B$25

Sheet CONFIGURATORE
A1: CONFIGURATORE PREVENTIVO
A3: Struttura | B3: Agrivoltaico
A4: Trave | B4: IPE 140
A5: Spessore asse | B5: 3,0 mm
A6: Spessore omega | B6: 2,0 mm
A7: Altezza infissione (m) - promemoria | B7: 1.5
A8: Luce libera da terra (m) - promemoria | B8: 0.8
A9: Lungh. fondazione [Agri] (suffisso) | B9: 30 | C9: ="= "&VALUE(Cfg_LenFond)/10&" m"
A10: Lungh. pilastro cuscinetto [Basso] | B10: 30 | C10: ="= "&VALUE(Cfg_LenCusc)/10&" m"
A11: Lungh. pilastro motore [Basso] | B11: 30 | C11: ="= "&VALUE(Cfg_LenMot)/10&" m"
A12: Pannelli FV nel preventivo | B12: No
A13: Margine % | B13: 0
A15: Trave (frammento codice) | B15: =IF(Cfg_Trave="IPEA 140","IPEA140","IPE140")
A18: TIPOLOGIE — inserire il numero di tracker
A19: Moduli / tracker | B19: N. tracker
A20: 12 | B20: 0
A21: 18 | B21: 0
A22: 20 | B22: 0
A23: 22 | B23: 0
A24: 36 | B24: 0
A25: 40 | B25: 0
A26: Totale tracker | B26: =SUM(B20:B25)
A29: RIEPILOGO PREVENTIVO
A30: Materiale (da DISTINTA PROGETTO) | B30: =SUM('DISTINTA PROGETTO'!$P$2:$P$344)
A31: Quadro motore (forfait 170 €/tracker) | B31: =170*B26
A32: Costo totale | B32: =B30+B31
A33: Margine | B33: =B32*Cfg_Margine/100
A34: Prezzo di vendita | B34: =B32+B33
A37: Materiale per tipologia
A38: 12 moduli | B38: =SUMPRODUCT('DISTINTA PROGETTO'!$H$2:$H$344,'DISTINTA PROGETTO'!$O$2:$O$344)*Cfg_n12
A39: 18 moduli | B39: =SUMPRODUCT('DISTINTA PROGETTO'!$I$2:$I$344,'DISTINTA PROGETTO'!$O$2:$O$344)*Cfg_n18
A40: 20 moduli | B40: =SUMPRODUCT('DISTINTA PROGETTO'!$J$2:$J$344,'DISTINTA PROGETTO'!$O$2:$O$344)*Cfg_n20
A41: 22 moduli | B41: =SUMPRODUCT('DISTINTA PROGETTO'!$K$2:$K$344,'DISTINTA PROGETTO'!$O$2:$O$344)*Cfg_n22
A42: 36 moduli | B42: =SUMPRODUCT('DISTINTA PROGETTO'!$L$2:$L$344,'DISTINTA PROGETTO'!$O$2:$O$344)*Cfg_n36
A43: 40 moduli | B43: =SUMPRODUCT('DISTINTA PROGETTO'!$M$2:$M$344,'DISTINTA PROGETTO'!$O$2:$O$344)*Cfg_n40

Sheet DISTINTA PROGETTO
A1: Assieme | B1: Sezione | C1: Cod. distinta | D1: Descrizione | E1: Codice progetto | F1: Tag | G1: Guard | H1: q12 | I1: q18 | J1: q20 | K1: q22 | L1: q36 | M1: q40 | N1: Q.tà progetto | O1: Prezzo € | P1: Importo € | Q1: In preventivo
A2: ='DISTINTA COMPLETA'!A2 | B2: ='DISTINTA COMPLETA'!B2 | C2: ='DISTINTA COMPLETA'!D2 | D2: ='DISTINTA COMPLETA'!E2 | E2: ="TTS.PF.001."&Cfg_TraveFrag&"."&Cfg_LenFond | F2: FOND_MOT | G2: =IF(Cfg_Struttura="Agrivoltaico",1,0) | H2: =$G2*1 | I2: =$G2*1 | J2: =$G2*1 | K2: =$G2*1 | L2: =$G2*1 | M2: =$G2*1 | N2: =Cfg_n12*H2+Cfg_n18*I2+Cfg_n20*J2+Cfg_n22*K2+Cfg_n36*L2+Cfg_n40*M2 | O2: =IFERROR(VLOOKUP($E2,LISTINO!$B:$G,6,FALSE),0) | P2: =$N2*$O2 | Q2: =IF($N2>0,"SI","")
A3: ='DISTINTA COMPLETA'!A3 | B3: ='DISTINTA COMPLETA'!B3 | C3: ='DISTINTA COMPLETA'!D3 | D3: ='DISTINTA COMPLETA'!E3 | E3: ='DISTINTA COMPLETA'!D3 | F3: SKIP | G3: =0 | H3: =$G3*0 | I3: =$G3*0 | J3: =$G3*0 | K3: =$G3*0 | L3: =$G3*0 | M3: =$G3*0 | N3: =Cfg_n12*H3+Cfg_n18*I3+Cfg_n20*J3+Cfg_n22*K3+Cfg_n36*L3+Cfg_n40*M3 | O3: =IFERROR(VLOOKUP($E3,LISTINO!$B:$G,6,FALSE),0) | P3: =$N3*$O3 | Q3: =IF($N3>0,"SI","")
A4: ='DISTINTA COMPLETA'!A4 | B4: ='DISTINTA COMPLETA'!B4 | C4: ='DISTINTA COMPLETA'!D4 | D4: ='DISTINTA COMPLETA'!E4 | E4: ='DISTINTA COMPLETA'!D4 | F4: SKIP | G4: =0 | H4: =$G4*0 | I4: =$G4*0 | J4: =$G4*0 | K4: =$G4*0 | L4: =$G4*0 | M4: =$G4*0 | N4: =Cfg_n12*H4+Cfg_n18*I4+Cfg_n20*J4+Cfg_n22*K4+Cfg_n36*L4+Cfg_n40*M4 | O4: =IFERROR(VLOOKUP($E4,LISTINO!$B:$G,6,FALSE),0) | P4: =$N4*$O4 | Q4: =IF($N4>0,"SI","")
A5: ='DISTINTA COMPLETA'!A5 | B5: ='DISTINTA COMPLETA'!B5 | C5: ='DISTINTA COMPLETA'!D5 | D5: ='DISTINTA COMPLETA'!E5 | E5: ='DISTINTA COMPLETA'!D5 | F5: SKIP | G5: =0 | H5: =$G5*0 | I5: =$G5*0 | J5: =$G5*0 | K5: =$G5*0 | L5: =$G5*0 | M5: =$G5*0 | N5: =Cfg_n12*H5+Cfg_n18*I5+Cfg_n20*J5+Cfg_n22*K5+Cfg_n36*L5+Cfg_n40*M5 | O5: =IFERROR(VLOOKUP($E5,LISTINO!$B:$G,6,FALSE),0) | P5: =$N5*$O5 | Q5: =IF($N5>0,"SI","")
A6: ='DISTINTA COMPLETA'!A6 | B6: ='DISTINTA COMPLETA'!B6 | C6: ='DISTINTA COMPLETA'!D6 | D6: ='DISTINTA COMPLETA'!E6 | E6: ='DISTINTA COMPLETA'!D6 | F6: SKIP | G6: =0 | H6: =$G6*0 | I6: =$G6*0 | J6: =$G6*0 | K6: =$G6*0 | L6: =$G6*0 | M6: =$G6*0 | N6: =Cfg_n12*H6+Cfg_n18*I6+Cfg_n20*J6+Cfg_n22*K6+Cfg_n36*L6+Cfg_n40*M6 | O6: =IFERROR(VLOOKUP($E6,LISTINO!$B:$G,6,FALSE),0) | P6: =$N6*$O6 | Q6: =IF($N6>0,"SI","")
A7: ='DISTINTA COMPLETA'!A7 | B7: ='DISTINTA COMPLETA'!B7 | C7: ='DISTINTA COMPLETA'!D7 | D7: ='DISTINTA COMPLETA'!E7 | E7: ='DISTINTA COMPLETA'!D7 | F7: SKIP | G7: =0 | H7: =$G7*0 | I7: =$G7*0 | J7: =$G7*0 | K7: =$G7*0 | L7: =$G7*0 | M7: =$G7*0 | N7: =Cfg_n12*H7+Cfg_n18*I7+Cfg_n20*J7+Cfg_n22*K7+Cfg_n36*L7+Cfg_n40*M7 | O7: =IFERROR(VLOOKUP($E7,LISTINO!$B:$G,6,FALSE),0) | P7: =$N7*$O7 | Q7: =IF($N7>0,"SI","")
A8: ='DISTINTA COMPLETA'!A8 | B8: ='DISTINTA COMPLETA'!B8 | C8: ='DISTINTA COMPLETA'!D8 | D8: ='DISTINTA COMPLETA'!E8 | E8: ='DISTINTA COMPLETA'!D8 | F8: SKIP | G8: =0 | H8: =$G8*0 | I8: =$G8*0 | J8: =$G8*0 | K8: =$G8*0 | L8: =$G8*0 | M8: =$G8*0 | N8: =Cfg_n12*H8+Cfg_n18*I8+Cfg_n20*J8+Cfg_n22*K8+Cfg_n36*L8+Cfg_n40*M8 | O8: =IFERROR(VLOOKUP($E8,LISTINO!$B:$G,6,FALSE),0) | P8: =$N8*$O8 | Q8: =IF($N8>0,"SI","")
A9: ='DISTINTA COMPLETA'!A9 | B9: ='DISTINTA COMPLETA'!B9 | C9: ='DISTINTA COMPLETA'!D9 | D9: ='DISTINTA COMPLETA'!E9 | E9: ='DISTINTA COMPLETA'!D9 | F9: SKIP | G9: =0 | H9: =$G9*0 | I9: =$G9*0 | J9: =$G9*0 | K9: =$G9*0 | L9: =$G9*0 | M9: =$G9*0 | N9: =Cfg_n12*H9+Cfg_n18*I9+Cfg_n20*J9+Cfg_n22*K9+Cfg_n36*L9+Cfg_n40*M9 | O9: =IFERROR(VLOOKUP($E9,LISTINO!$B:$G,6,FALSE),0) | P9: =$N9*$O9 | Q9: =IF($N9>0,"SI","")
A10: ='DISTINTA COMPLETA'!A10 | B10: ='DISTINTA COMPLETA'!B10 | C10: ='DISTINTA COMPLETA'!D10 | D10: ='DISTINTA COMPLETA'!E10 | E10: ='DISTINTA COMPLETA'!D10 | F10: SKIP | G10: =0 | H10: =$G10*0 | I10: =$G10*0 | J10: =$G10*0 | K10: =$G10*0 | L10: =$G10*0 | M10: =$G10*0 | N10: =Cfg_n12*H10+Cfg_n18*I10+Cfg_n20*J10+Cfg_n22*K10+Cfg_n36*L10+Cfg_n40*M10 | O10: =IFERROR(VLOOKUP($E10,LISTINO!$B:$G,6,FALSE),0) | P10: =$N10*$O10 | Q10: =IF($N10>0,"SI","")
A11: ='DISTINTA COMPLETA'!A11 | B11: ='DISTINTA COMPLETA'!B11 | C11: ='DISTINTA COMPLETA'!D11 | D11: ='DISTINTA COMPLETA'!E11 | E11: ='DISTINTA COMPLETA'!D11 | F11: SKIP | G11: =0 | H11: =$G11*0 | I11: =$G11*0 | J11: =$G11*0 | K11: =$G11*0 | L11: =$G11*0 | M11: =$G11*0 | N11: =Cfg_n12*H11+Cfg_n18*I11+Cfg_n20*J11+Cfg_n22*K11+Cfg_n36*L11+Cfg_n40*M11 | O11: =IFERROR(VLOOKUP($E11,LISTINO!$B:$G,6,FALSE),0) | P11: =$N11*$O11 | Q11: =IF($N11>0,"SI","")
A12: ='DISTINTA COMPLETA'!A12 | B12: ='DISTINTA COMPLETA'!B12 | C12: ='DISTINTA COMPLETA'!D12 | D12: ='DISTINTA COMPLETA'!E12 | E12: ='DISTINTA COMPLETA'!D12 | F12: SKIP | G12: =0 | H12: =$G12*0 | I12: =$G12*0 | J12: =$G12*0 | K12: =$G12*0 | L12: =$G12*0 | M12: =$G12*0 | N12: =Cfg_n12*H12+Cfg_n18*I12+Cfg_n20*J12+Cfg_n22*K12+Cfg_n36*L12+Cfg_n40*M12 | O12: =IFERROR(VLOOKUP($E12,LISTINO!$B:$G,6,FALSE),0) | P12: =$N12*$O12 | Q12: =IF($N12>0,"SI","")
A13: ='DISTINTA COMPLETA'!A13 | B13: ='DISTINTA COMPLETA'!B13 | C13: ='DISTINTA COMPLETA'!D13 | D13: ='DISTINTA COMPLETA'!E13 | E13: ='DISTINTA COMPLETA'!D13 | F13: SKIP | G13: =0 | H13: =$G13*0 | I13: =$G13*0 | J13: =$G13*0 | K13: =$G13*0 | L13: =$G13*0 | M13: =$G13*0 | N13: =Cfg_n12*H13+Cfg_n18*I13+Cfg_n20*J13+Cfg_n22*K13+Cfg_n36*L13+Cfg_n40*M13 | O13: =IFERROR(VLOOKUP($E13,LISTINO!$B:$G,6,FALSE),0) | P13: =$N13*$O13 | Q13: =IF($N13>0,"SI","")
A14: ='DISTINTA COMPLETA'!A14 | B14: ='DISTINTA COMPLETA'!B14 | C14: ='DISTINTA COMPLETA'!D14 | D14: ='DISTINTA COMPLETA'!E14 | E14: ='DISTINTA COMPLETA'!D14 | F14: SKIP | G14: =0 | H14: =$G14*0 | I14: =$G14*0 | J14: =$G14*0 | K14: =$G14*0 | L14: =$G14*0 | M14: =$G14*0 | N14: =Cfg_n12*H14+Cfg_n18*I14+Cfg_n20*J14+Cfg_n22*K14+Cfg_n36*L14+Cfg_n40*M14 | O14: =IFERROR(VLOOKUP($E14,LISTINO!$B:$G,6,FALSE),0) | P14: =$N14*$O14 | Q14: =IF($N14>0,"SI","")
... A23: ='DISTINTA COMPLETA'!A23 | B23: ='DISTINTA COMPLETA'!B23 | C23: ='DISTINTA COMPLETA'!D23 | D23: ='DISTINTA COMPLETA'!E23 | E23: ='DISTINTA COMPLETA'!D23 | F23: SKIP | G23: =0 | H23: =$G23*0 | I23: =$G23*0 | J23: =$G23*0 | K23: =$G23*0 | L23: =$G23*0 | M23: =$G23*0 | N23: =Cfg_n12*H23+Cfg_n18*I23+Cfg_n20*J23+Cfg_n22*K23+Cfg_n36*L23+Cfg_n40*M23 | O23: =IFERROR(VLOOKUP($E23,LISTINO!$B:$G,6,FALSE),0) | P23: =$N23*$O23 | Q23: =IF($N23>0,"SI","")
A24: ='DISTINTA COMPLETA'!A24 | B24: ='DISTINTA COMPLETA'!B24 | C24: ='DISTINTA COMPLETA'!D24 | D24: ='DISTINTA COMPLETA'!E24 | E24: ="TTS.PM.001."&Cfg_TraveFrag&"."&IF(Cfg_Struttura="Agrivoltaico","22",Cfg_LenMot) | F24: PIL_MOT | G24: =1 | H24: =$G24*1 | I24: =$G24*1 | J24: =$G24*1 | K24: =$G24*1 | L24: =$G24*1 | M24: =$G24*1 | N24: =Cfg_n12*H24+Cfg_n18*I24+Cfg_n20*J24+Cfg_n22*K24+Cfg_n36*L24+Cfg_n40*M24 | O24: =IFERROR(VLOOKUP($E24,LISTINO!$B:$G,6,FALSE),0) | P24: =$N24*$O24 | Q24: =IF($N24>0,"SI","")
A25: ='DISTINTA COMPLETA'!A25 | B25: ='DISTINTA COMPLETA'!B25 | C25: ='DISTINTA COMPLETA'!D25 | D25: ='DISTINTA COMPLETA'!E25 | E25: ='DISTINTA COMPLETA'!D25 | F25: SKIP | G25: =0 | H25: =$G25*0 | I25: =$G25*0 | J25: =$G25*0 | K25: =$G25*0 | L25: =$G25*0 | M25: =$G25*0 | N25: =Cfg_n12*H25+Cfg_n18*I25+Cfg_n20*J25+Cfg_n22*K25+Cfg_n36*L25+Cfg_n40*M25 | O25: =IFERROR(VLOOKUP($E25,LISTINO!$B:$G,6,FALSE),0) | P25: =$N25*$O25 | Q25: =IF($N25>0,"SI","")
A26: ='DISTINTA COMPLETA'!A26 | B26: ='DISTINTA COMPLETA'!B26 | C26: ='DISTINTA COMPLETA'!D26 | D26: ='DISTINTA COMPLETA'!E26 | E26: ='DISTINTA COMPLETA'!D26 | F26: SKIP | G26: =0 | H26: =$G26*0 | I26: =$G26*0 | J26: =$G26*0 | K26: =$G26*0 | L26: =$G26*0 | M26: =$G26*0 | N26: =Cfg_n12*H26+Cfg_n18*I26+Cfg_n20*J26+Cfg_n22*K26+Cfg_n36*L26+Cfg_n40*M26 | O26: =IFERROR(VLOOKUP($E26,LISTINO!$B:$G,6,FALSE),0) | P26: =$N26*$O26 | Q26: =IF($N26>0,"SI","")
A27: ='DISTINTA COMPLETA'!A27 | B27: ='DISTINTA COMPLETA'!B27 | C27: ='DISTINTA COMPLETA'!D27 | D27: ='DISTINTA COMPLETA'!E27 | E27: ='DISTINTA COMPLETA'!D27 | F27: SKIP | G27: =0 | H27: =$G27*0 | I27: =$G27*0 | J27: =$G27*0 | K27: =$G27*0 | L27: =$G27*0 | M27: =$G27*0 | N27: =Cfg_n12*H27+Cfg_n18*I27+Cfg_n20*J27+Cfg_n22*K27+Cfg_n36*L27+Cfg_n40*M27 | O27: =IFERROR(VLOOKUP($E27,LISTINO!$B:$G,6,FALSE),0) | P27: =$N27*$O27 | Q27: =IF($N27>0,"SI","")
A28: ='DISTINTA COMPLETA'!A28 | B28: ='DISTINTA COMPLETA'!B28 | C28: ='DISTINTA COMPLETA'!D28 | D28: ='DISTINTA COMPLETA'!E28 | E28: ='DISTINTA COMPLETA'!D28 | F28: SKIP | G28: =0 | H28: =$G28*0 | I28: =$G28*0 | J28: =$G28*0 | K28: =$G28*0 | L28: =$G28*0 | M28: =$G28*0 | N28: =Cfg_n12*H28+Cfg_n18*I28+Cfg_n20*J28+Cfg_n22*K28+Cfg_n36*L28+Cfg_n40*M28 | O28: =IFERROR(VLOOKUP($E28,LISTINO!$B:$G,6,FALSE),0) | P28: =$N28*$O28 | Q28: =IF($N28>0,"SI","")
A29: ='DISTINTA COMPLETA'!A29 | B29: ='DISTINTA COMPLETA'!B29 | C29: ='DISTINTA COMPLETA'!D29 | D29: ='DISTINTA COMPLETA'!E29 | E29: ='DISTINTA COMPLETA'!D29 | F29: SKIP | G29: =0 | H29: =$G29*0 | I29: =$G29*0 | J29: =$G29*0 | K29: =$G29*0 | L29: =$G29*0 | M29: =$G29*0 | N29: =Cfg_n12*H29+Cfg_n18*I29+Cfg_n20*J29+Cfg_n22*K29+Cfg_n36*L29+Cfg_n40*M29 | O29: =IFERROR(VLOOKUP($E29,LISTINO!$B:$G,6,FALSE),0) | P29: =$N29*$O29 | Q29: =IF($N29>0,"SI","")
A30: ='DISTINTA COMPLETA'!A30 | B30: ='DISTINTA COMPLETA'!B30 | C30: ='DISTINTA COMPLETA'!D30 | D30: ='DISTINTA COMPLETA'!E30 | E30: ='DISTINTA COMPLETA'!D30 | F30: SKIP | G30: =0 | H30: =$G30*0 | I30: =$G30*0 | J30: =$G30*0 | K30: =$G30*0 | L30: =$G30*0 | M30: =$G30*0 | N30: =Cfg_n12*H30+Cfg_n18*I30+Cfg_n20*J30+Cfg_n22*K30+Cfg_n36*L30+Cfg_n40*M30 | O30: =IFERROR(VLOOKUP($E30,LISTINO!$B:$G,6,FALSE),0) | P30: =$N30*$O30 | Q30: =IF($N30>0,"SI","")
A31: ='DISTINTA COMPLETA'!A31 | B31: ='DISTINTA COMPLETA'!B31 | C31: ='DISTINTA COMPLETA'!D31 | D31: ='DISTINTA COMPLETA'!E31 | E31: ='DISTINTA COMPLETA'!D31 | F31: SKIP | G31: =0 | H31: =$G31*0 | I31: =$G31*0 | J31: =$G31*0 | K31: =$G31*0 | L31: =$G31*0 | M31: =$G31*0 | N31: =Cfg_n12*H31+Cfg_n18*I31+Cfg_n20*J31+Cfg_n22*K31+Cfg_n36*L31+Cfg_n40*M31 | O31: =IFERROR(VLOOKUP($E31,LISTINO!$B:$G,6,FALSE),0) | P31: =$N31*$O31 | Q31: =IF($N31>0,"SI","")
A32: ='DISTINTA COMPLETA'!A32 | B32: ='DISTINTA COMPLETA'!B32 | C32: ='DISTINTA COMPLETA'!D32 | D32: ='DISTINTA COMPLETA'!E32 | E32: ='DISTINTA COMPLETA'!D32 | F32: SKIP | G32: =0 | H32: =$G32*0 | I32: =$G32*0 | J32: =$G32*0 | K32: =$G32*0 | L32: =$G32*0 | M32: =$G32*0 | N32: =Cfg_n12*H32+Cfg_n18*I32+Cfg_n20*J32+Cfg_n22*K32+Cfg_n36*L32+Cfg_n40*M32 | O32: =IFERROR(VLOOKUP($E32,LISTINO!$B:$G,6,FALSE),0) | P32: =$N32*$O32 | Q32: =IF($N32>0,"SI","")
A33: ='DISTINTA COMPLETA'!A33 | B33: ='DISTINTA COMPLETA'!B33 | C33: ='DISTINTA COMPLETA'!D33 | D33: ='DISTINTA COMPLETA'!E33 | E33: ='DISTINTA COMPLETA'!D33 | F33: SKIP | G33: =0 | H33: =$G33*0 | I33: =$G33*0 | J33: =$G33*0 | K33: =$G33*0 | L33: =$G33*0 | M33: =$G33*0 | N33: =Cfg_n12*H33+Cfg_n18*I33+Cfg_n20*J33+Cfg_n22*K33+Cfg_n36*L33+Cfg_n40*M33 | O33: =IFERROR(VLOOKUP($E33,LISTINO!$B:$G,6,FALSE),0) | P33: =$N33*$O33 | Q33: =IF($N33>0,"SI","")
A34: ='DISTINTA COMPLETA'!A34 | B34: ='DISTINTA COMPLETA'!B34 | C34: ='DISTINTA COMPLETA'!D34 | D34: ='DISTINTA COMPLETA'!E34 | E34: ='DISTINTA COMPLETA'!D34 | F34: SKIP | G34: =0 | H34: =$G34*0 | I34: =$G34*0 | J34: =$G34*0 | K34: =$G34*0 | L34: =$G34*0 | M34: =$G34*0 | N34: =Cfg_n12*H34+Cfg_n18*I34+Cfg_n20*J34+Cfg_n22*K34+Cfg_n36*L34+Cfg_n40*M34 | O34: =IFERROR(VLOOKUP($E34,LISTINO!$B:$G,6,FALSE),0) | P34: =$N34*$O34 | Q34: =IF($N34>0,"SI","")
A35: ='DISTINTA COMPLETA'!A35 | B35: ='DISTINTA COMPLETA'!B35 | C35: ='DISTINTA COMPLETA'!D35 | D35: ='DISTINTA COMPLETA'!E35 | E35: ='DISTINTA COMPLETA'!D35 | F35: SKIP | G35: =0 | H35: =$G35*0 | I35: =$G35*0 | J35: =$G35*0 | K35: =$G35*0 | L35: =$G35*0 | M35: =$G35*0 | N35: =Cfg_n12*H35+Cfg_n18*I35+Cfg_n20*J35+Cfg_n22*K35+Cfg_n36*L35+Cfg_n40*M35 | O35: =IFERROR(VLOOKUP($E35,LISTINO!$B:$G,6,FALSE),0) | P35: =$N35*$O35 | Q35: =IF($N35>0,"SI","")
A36: ='DISTINTA COMPLETA'!A36 | B36: ='DISTINTA COMPLETA'!B36 | C36: ='DISTINTA COMPLETA'!D36 | D36: ='DISTINTA COMPLETA'!E36 | E36: ='DISTINTA COMPLETA'!D36 | F36: SKIP | G36: =0 | H36: =$G36*0 | I36: =$G36*0 | J36: =$G36*0 | K36: =$G36*0 | L36: =$G36*0 | M36: =$G36*0 | N36: =Cfg_n12*H36+Cfg_n18*I36+Cfg_n20*J36+Cfg_n22*K36+Cfg_n36*L36+Cfg_n40*M36 | O36: =IFERROR(VLOOKUP($E36,LISTINO!$B:$G,6,FALSE),0) | P36: =$N36*$O36 | Q36: =IF($N36>0,"SI","")
... A61: ='DISTINTA COMPLETA'!A61 | B61: ='DISTINTA COMPLETA'!B61 | C61: ='DISTINTA COMPLETA'!D61 | D61: ='DISTINTA COMPLETA'!E61 | E61: ='DISTINTA COMPLETA'!D61 | F61: SKIP | G61: =0 | H61: =$G61*0 | I61: =$G61*0 | J61: =$G61*0 | K61: =$G61*0 | L61: =$G61*0 | M61: =$G61*0 | N61: =Cfg_n12*H61+Cfg_n18*I61+Cfg_n20*J61+Cfg_n22*K61+Cfg_n36*L61+Cfg_n40*M61 | O61: =IFERROR(VLOOKUP($E61,LISTINO!$B:$G,6,FALSE),0) | P61: =$N61*$O61 | Q61: =IF($N61>0,"SI","")
A62: ='DISTINTA COMPLETA'!A62 | B62: ='DISTINTA COMPLETA'!B62 | C62: ='DISTINTA COMPLETA'!D62 | D62: ='DISTINTA COMPLETA'!E62 | E62: ='DISTINTA COMPLETA'!D62 | F62: GIUNZ | G62: =IF(Cfg_Struttura="Agrivoltaico",1,0) | H62: =$G62*2 | I62: =$G62*2 | J62: =$G62*2 | K62: =$G62*2 | L62: =$G62*2 | M62: =$G62*2 | N62: =Cfg_n12*H62+Cfg_n18*I62+Cfg_n20*J62+Cfg_n22*K62+Cfg_n36*L62+Cfg_n40*M62 | O62: =IFERROR(VLOOKUP($E62,LISTINO!$B:$G,6,FALSE),0) | P62: =$N62*$O62 | Q62: =IF($N62>0,"SI","")
A63: ='DISTINTA COMPLETA'!A63 | B63: ='DISTINTA COMPLETA'!B63 | C63: ='DISTINTA COMPLETA'!D63 | D63: ='DISTINTA COMPLETA'!E63 | E63: ='DISTINTA COMPLETA'!D63 | F63: GIUNZ | G63: =IF(Cfg_Struttura="Agrivoltaico",1,0) | H63: =$G63*8 | I63: =$G63*8 | J63: =$G63*8 | K63: =$G63*8 | L63: =$G63*8 | M63: =$G63*8 | N63: =Cfg_n12*H63+Cfg_n18*I63+Cfg_n20*J63+Cfg_n22*K63+Cfg_n36*L63+Cfg_n40*M63 | O63: =IFERROR(VLOOKUP($E63,LISTINO!$B:$G,6,FALSE),0) | P63: =$N63*$O63 | Q63: =IF($N63>0,"SI","")
A64: ='DISTINTA COMPLETA'!A64 | B64: ='DISTINTA COMPLETA'!B64 | C64: ='DISTINTA COMPLETA'!D64 | D64: ='DISTINTA COMPLETA'!E64 | E64: ='DISTINTA COMPLETA'!D64 | F64: GIUNZ | G64: =IF(Cfg_Struttura="Agrivoltaico",1,0) | H64: =$G64*8 | I64: =$G64*8 | J64: =$G64*8 | K64: =$G64*8 | L64: =$G64*8 | M64: =$G64*8 | N64: =Cfg_n12*H64+Cfg_n18*I64+Cfg_n20*J64+Cfg_n22*K64+Cfg_n36*L64+Cfg_n40*M64 | O64: =IFERROR(VLOOKUP($E64,LISTINO!$B:$G,6,FALSE),0) | P64: =$N64*$O64 | Q64: =IF($N64>0,"SI","")
A65: ='DISTINTA COMPLETA'!A65 | B65: ='DISTINTA COMPLETA'!B65 | C65: ='DISTINTA COMPLETA'!D65 | D65: ='DISTINTA COMPLETA'!E65 | E65: ='DISTINTA COMPLETA'!D65 | F65: GIUNZ | G65: =IF(Cfg_Struttura="Agrivoltaico",1,0) | H65: =$G65*8 | I65: =$G65*8 | J65: =$G65*8 | K65: =$G65*8 | L65: =$G65*8 | M65: =$G65*8 | N65: =Cfg_n12*H65+Cfg_n18*I65+Cfg_n20*J65+Cfg_n22*K65+Cfg_n36*L65+Cfg_n40*M65 | O65: =IFERROR(VLOOKUP($E65,LISTINO!$B:$G,6,FALSE),0) | P65: =$N65*$O65 | Q65: =IF($N65>0,"SI","")
A66: ='DISTINTA COMPLETA'!A66 | B66: ='DISTINTA COMPLETA'!B66 | C66: ='DISTINTA COMPLETA'!D66 | D66: ='DISTINTA COMPLETA'!E66 | E66: ='DISTINTA COMPLETA'!D66 | F66: GIUNZ | G66: =IF(Cfg_Struttura="Agrivoltaico",1,0) | H66: =$G66*8 | I66: =$G66*8 | J66: =$G66*8 | K66: =$G66*8 | L66: =$G66*8 | M66: =$G66*8 | N66: =Cfg_n12*H66+Cfg_n18*I66+Cfg_n20*J66+Cfg_n22*K66+Cfg_n36*L66+Cfg_n40*M66 | O66: =IFERROR(VLOOKUP($E66,LISTINO!$B:$G,6,FALSE),0) | P66: =$N66*$O66 | Q66: =IF($N66>0,"SI","")
A67: ='DISTINTA COMPLETA'!A67 | B67: ='DISTINTA COMPLETA'!B67 | C67: ='DISTINTA COMPLETA'!D67 | D67: ='DISTINTA COMPLETA'!E67 | E67: ='DISTINTA COMPLETA'!D67 | F67: GIUNZ | G67: =IF(Cfg_Struttura="Agrivoltaico",1,0) | H67: =$G67*2 | I67: =$G67*2 | J67: =$G67*2 | K67: =$G67*2 | L67: =$G67*2 | M67: =$G67*2 | N67: =Cfg_n12*H67+Cfg_n18*I67+Cfg_n20*J67+Cfg_n22*K67+Cfg_n36*L67+Cfg_n40*M67 | O67: =IFERROR(VLOOKUP($E67,LISTINO!$B:$G,6,FALSE),0) | P67: =$N67*$O67 | Q67: =IF($N67>0,"SI","")
A68: ='DISTINTA COMPLETA'!A68 | B68: ='DISTINTA COMPLETA'!B68 | C68: ='DISTINTA COMPLETA'!D68 | D68: ='DISTINTA COMPLETA'!E68 | E68: ='DISTINTA COMPLETA'!D68 | F68: GIUNZ | G68: =IF(Cfg_Struttura="Agrivoltaico",1,0) | H68: =$G68*4 | I68: =$G68*4 | J68: =$G68*4 | K68: =$G68*4 | L68: =$G68*4 | M68: =$G68*4 | N68: =Cfg_n12*H68+Cfg_n18*I68+Cfg_n20*J68+Cfg_n22*K68+Cfg_n36*L68+Cfg_n40*M68 | O68: =IFERROR(VLOOKUP($E68,LISTINO!$B:$G,6,FALSE),0) | P68: =$N68*$O68 | Q68: =IF($N68>0,"SI","")
A69: ='DISTINTA COMPLETA'!A69 | B69: ='DISTINTA COMPLETA'!B69 | C69: ='DISTINTA COMPLETA'!D69 | D69: ='DISTINTA COMPLETA'!E69 | E69: ='DISTINTA COMPLETA'!D69 | F69: GIUNZ | G69: =IF(Cfg_Struttura="Agrivoltaico",1,0) | H69: =$G69*24 | I69: =$G69*24 | J69: =$G69*24 | K69: =$G69*24 | L69: =$G69*24 | M69: =$G69*24 | N69: =Cfg_n12*H69+Cfg_n18*I69+Cfg_n20*J69+Cfg_n22*K69+Cfg_n36*L69+Cfg_n40*M69 | O69: =IFERROR(VLOOKUP($E69,LISTINO!$B:$G,6,FALSE),0) | P69: =$N69*$O69 | Q69: =IF($N69>0,"SI","")
A70: ='DISTINTA COMPLETA'!A70 | B70: ='DISTINTA COMPLETA'!B70 | C70: ='DISTINTA COMPLETA'!D70 | D70: ='DISTINTA COMPLETA'!E70 | E70: ='DISTINTA COMPLETA'!D70 | F70: GIUNZ | G70: =IF(Cfg_Struttura="Agrivoltaico",1,0) | H70: =$G70*24 | I70: =$G70*24 | J70: =$G70*24 | K70: =$G70*24 | L70: =$G70*24 | M70: =$G70*24 | N70: =Cfg_n12*H70+Cfg_n18*I70+Cfg_n20*J70+Cfg_n22*K70+Cfg_n36*L70+Cfg_n40*M70 | O70: =IFERROR(VLOOKUP($E70,LISTINO!$B:$G,6,FALSE),0) | P70: =$N70*$O70 | Q70: =IF($N70>0,"SI","")
A71: ='DISTINTA COMPLETA'!A71 | B71: ='DISTINTA COMPLETA'!B71 | C71: ='DISTINTA COMPLETA'!D71 | D71: ='DISTINTA COMPLETA'!E71 | E71: ='DISTINTA COMPLETA'!D71 | F71: GIUNZ | G71: =IF(Cfg_Struttura="Agrivoltaico",1,0) | H71: =$G71*24 | I71: =$G71*24 | J71: =$G71*24 | K71: =$G71*24 | L71: =$G71*24 | M71: =$G71*24 | N71: =Cfg_n12*H71+Cfg_n18*I71+Cfg_n20*J71+Cfg_n22*K71+Cfg_n36*L71+Cfg_n40*M71 | O71: =IFERROR(VLOOKUP($E71,LISTINO!$B:$G,6,FALSE),0) | P71: =$N71*$O71 | Q71: =IF($N71>0,"SI","")
A72: ='DISTINTA COMPLETA'!A72 | B72: ='DISTINTA COMPLETA'!B72 | C72: ='DISTINTA COMPLETA'!D72 | D72: ='DISTINTA COMPLETA'!E72 | E72: ='DISTINTA COMPLETA'!D72 | F72: GIUNZ | G72: =IF(Cfg_Struttura="Agrivoltaico",1,0) | H72: =$G72*24 | I72: =$G72*24 | J72: =$G72*24 | K72: =$G72*24 | L72: =$G72*24 | M72: =$G72*24 | N72: =Cfg_n12*H72+Cfg_n18*I72+Cfg_n20*J72+Cfg_n22*K72+Cfg_n36*L72+Cfg_n40*M72 | O72: =IFERROR(VLOOKUP($E72,LISTINO!$B:$G,6,FALSE),0) | P72: =$N72*$O72 | Q72: =IF($N72>0,"SI","")
...

Sheet SCHEDA STRUTTURA
A1: SCHEDA STRUTTURA — parametri peso e costo di acquisto/zincatura (compilare kg/m, % zincatura, €/kg acquisto e €/kg zincatura)
A2: Blocco 'Profili': travi IPE/IPEA, assi di rotazione, omega, staffe supporto pannello (supporto a L/V, gaffa) e gaffa giunzione asse con peso al metro, % zincatura, €/kg acquisto e €/kg zincatura. Peso elemento (kg) include la maggiorazione zincatura; Costo acquisto (€) = peso al netto × €/kg acquisto (indipendente dalla zincatura); Costo zincatura (€) = peso al netto × (1 + magg. %) × €/kg zincatura, solo se la maggiorazione è presente. I pezzi 'a pezzo' (piastre di giunzione, supporti, angolari, pali MAX, aste) sono nel foglio 'SCHEDA PEZZI SPECIALI'. L'omega supporto pannello e le sue staffe (supporto a L/V, gaffa) sono in fondo all'Elenco qui sotto, con profilo dedicato nel blocco 'Profili'.
A4: Profilo | B4: Peso teorico (kg/m) | C4: Magg. zincatura % | D4: Peso finale (kg/m) | E4: Costo acquisto (€/kg) | F4: Costo zincatura (€/kg)
A5: IPE 140 | B5: 12.9 | C5: 0.025 | D5: =IF(ISNUMBER($B5),$B5*(1+IF(ISNUMBER($C5),$C5,0)),"") | E5: 0.95 | F5: 0.5
A6: IPEA 140 | B6: 10.9 | C6: 0.025 | D6: =IF(ISNUMBER($B6),$B6*(1+IF(ISNUMBER($C6),$C6,0)),"") | E6: 1.05 | F6: 0.5
A7: ASSE 120x120x3 | B7: 11.8 | C7: 0.025 | D7: =IF(ISNUMBER($B7),$B7*(1+IF(ISNUMBER($C7),$C7,0)),"") | E7: 1.25
A8: ASSE 120x120x2,5 | B8: 9.2 | C8: 0.025 | D8: =IF(ISNUMBER($B8),$B8*(1+IF(ISNUMBER($C8),$C8,0)),"") | E8: 1.25
A9: OMEGA 2,0 | B9: 3.9 | C9: 0.025 | D9: =IF(ISNUMBER($B9),$B9*(1+IF(ISNUMBER($C9),$C9,0)),"") | E9: 0.95
A10: OMEGA 1,8 | B10: 3.51 | C10: 0.025 | D10: =IF(ISNUMBER($B10),$B10*(1+IF(ISNUMBER($C10),$C10,0)),"") | E10: 0.95
A11: SUPPORTO L | B11: 1.36 | C11: 0.025 | D11: =IF(ISNUMBER($B11),$B11*(1+IF(ISNUMBER($C11),$C11,0)),"") | E11: 1.18
A12: SUPPORTO V | B12: 0.41 | C12: 0.025 | D12: =IF(ISNUMBER($B12),$B12*(1+IF(ISNUMBER($C12),$C12,0)),"") | E12: 1.1
A13: GAFFA | B13: 1.28 | C13: 0.025 | D13: =IF(ISNUMBER($B13),$B13*(1+IF(ISNUMBER($C13),$C13,0)),"") | E13: 0.85 | F13: 0.8
A14: GAFFA GIUNZIONE ASSE | B14: 5.07 | C14: 0.025 | D14: =IF(ISNUMBER($B14),$B14*(1+IF(ISNUMBER($C14),$C14,0)),"") | E14: 0.85 | F14: 0.8
A16: Codice | B16: Descrizione | C16: Profilo | D16: Lunghezza (m) | E16: Peso elemento (kg) | F16: Costo acquisto (€) | G16: Costo zincatura (€)
A17: TTS.PC.001.IPE140.23 | B17: Pilastro cuscinetto trave IPE 140 mt.2,30 | C17: IPE 140 | D17: 2.3 | E17: =IF(AND(ISNUMBER($D17),ISNUMBER(VLOOKUP($C17,$A$5:$F$14,4,FALSE))),$D17*VLOOKUP($C17,$A$5:$F$14,4,FALSE),"") | F17: =IF(AND(ISNUMBER($D17),ISNUMBER(VLOOKUP($C17,$A$5:$F$14,2,FALSE)),ISNUMBER(VLOOKUP($C17,$A$5:$F$14,5,FALSE))),$D17*VLOOKUP($C17,$A$5:$F$14,2,FALSE)*VLOOKUP($C17,$A$5:$F$14,5,FALSE),"") | G17: =IF(AND(ISNUMBER($D17),ISNUMBER(VLOOKUP($C17,$A$5:$F$14,2,FALSE)),ISNUMBER(VLOOKUP($C17,$A$5:$F$14,3,FALSE)),VLOOKUP($C17,$A$5:$F$14,3,FALSE)>0,ISNUMBER(VLOOKUP($C17,$A$5:$F$14,6,FALSE))),$D17*VLOOKUP($C17,$A$5:$F$14,2,FALSE)*(1+VLOOKUP($C17,$A$5:$F$14,3,FALSE))*VLOOKUP($C17,$A$5:$F$14,6,FALSE),"")
A18: TTS.PC.001.IPE140.23.FI | B18: Pilastro cuscinetto trave ipe140 x mt. 2,30 con foratura alloggiamento inverter | C18: IPE 140 | D18: 2.3 | E18: =IF(AND(ISNUMBER($D18),ISNUMBER(VLOOKUP($C18,$A$5:$F$14,4,FALSE))),$D18*VLOOKUP($C18,$A$5:$F$14,4,FALSE),"") | F18: =IF(AND(ISNUMBER($D18),ISNUMBER(VLOOKUP($C18,$A$5:$F$14,2,FALSE)),ISNUMBER(VLOOKUP($C18,$A$5:$F$14,5,FALSE))),$D18*VLOOKUP($C18,$A$5:$F$14,2,FALSE)*VLOOKUP($C18,$A$5:$F$14,5,FALSE),"") | G18: =IF(AND(ISNUMBER($D18),ISNUMBER(VLOOKUP($C18,$A$5:$F$14,2,FALSE)),ISNUMBER(VLOOKUP($C18,$A$5:$F$14,3,FALSE)),VLOOKUP($C18,$A$5:$F$14,3,FALSE)>0,ISNUMBER(VLOOKUP($C18,$A$5:$F$14,6,FALSE))),$D18*VLOOKUP($C18,$A$5:$F$14,2,FALSE)*(1+VLOOKUP($C18,$A$5:$F$14,3,FALSE))*VLOOKUP($C18,$A$5:$F$14,6,FALSE),"")
A19: TTS.PC.001.IPE140.23.FQA | B19: Pilastro cuscinetto trave ipe140 x mt. 2,30 con foratura alloggiamento quadro area | C19: IPE 140 | D19: 2.3 | E19: =IF(AND(ISNUMBER($D19),ISNUMBER(VLOOKUP($C19,$A$5:$F$14,4,FALSE))),$D19*VLOOKUP($C19,$A$5:$F$14,4,FALSE),"") | F19: =IF(AND(ISNUMBER($D19),ISNUMBER(VLOOKUP($C19,$A$5:$F$14,2,FALSE)),ISNUMBER(VLOOKUP($C19,$A$5:$F$14,5,FALSE))),$D19*VLOOKUP($C19,$A$5:$F$14,2,FALSE)*VLOOKUP($C19,$A$5:$F$14,5,FALSE),"") | G19: =IF(AND(ISNUMBER($D19),ISNUMBER(VLOOKUP($C19,$A$5:$F$14,2,FALSE)),ISNUMBER(VLOOKUP($C19,$A$5:$F$14,3,FALSE)),VLOOKUP($C19,$A$5:$F$14,3,FALSE)>0,ISNUMBER(VLOOKUP($C19,$A$5:$F$14,6,FALSE))),$D19*VLOOKUP($C19,$A$5:$F$14,2,FALSE)*(1+VLOOKUP($C19,$A$5:$F$14,3,FALSE))*VLOOKUP($C19,$A$5:$F$14,6,FALSE),"")
A20: TTS.PC.001.IPE140.28 | B20: Pilastro cuscinetto trave IPE 140 mt.2,80 | C20: IPE 140 | D20: 2.8 | E20: =IF(AND(ISNUMBER($D20),ISNUMBER(VLOOKUP($C20,$A$5:$F$14,4,FALSE))),$D20*VLOOKUP($C20,$A$5:$F$14,4,FALSE),"") | F20: =IF(AND(ISNUMBER($D20),ISNUMBER(VLOOKUP($C20,$A$5:$F$14,2,FALSE)),ISNUMBER(VLOOKUP($C20,$A$5:$F$14,5,FALSE))),$D20*VLOOKUP($C20,$A$5:$F$14,2,FALSE)*VLOOKUP($C20,$A$5:$F$14,5,FALSE),"") | G20: =IF(AND(ISNUMBER($D20),ISNUMBER(VLOOKUP($C20,$A$5:$F$14,2,FALSE)),ISNUMBER(VLOOKUP($C20,$A$5:$F$14,3,FALSE)),VLOOKUP($C20,$A$5:$F$14,3,FALSE)>0,ISNUMBER(VLOOKUP($C20,$A$5:$F$14,6,FALSE))),$D20*VLOOKUP($C20,$A$5:$F$14,2,FALSE)*(1+VLOOKUP($C20,$A$5:$F$14,3,FALSE))*VLOOKUP($C20,$A$5:$F$14,6,FALSE),"")
A21: TTS.PC.001.IPE140.29 | B21: Pilastro cuscinetto trave IPE 140 mt.2,90 | C21: IPE 140 | D21: 2.9 | E21: =IF(AND(ISNUMBER($D21),ISNUMBER(VLOOKUP($C21,$A$5:$F$14,4,FALSE))),$D21*VLOOKUP($C21,$A$5:$F$14,4,FALSE),"") | F21: =IF(AND(ISNUMBER($D21),ISNUMBER(VLOOKUP($C21,$A$5:$F$14,2,FALSE)),ISNUMBER(VLOOKUP($C21,$A$5:$F$14,5,FALSE))),$D21*VLOOKUP($C21,$A$5:$F$14,2,FALSE)*VLOOKUP($C21,$A$5:$F$14,5,FALSE),"") | G21: =IF(AND(ISNUMBER($D21),ISNUMBER(VLOOKUP($C21,$A$5:$F$14,2,FALSE)),ISNUMBER(VLOOKUP($C21,$A$5:$F$14,3,FALSE)),VLOOKUP($C21,$A$5:$F$14,3,FALSE)>0,ISNUMBER(VLOOKUP($C21,$A$5:$F$14,6,FALSE))),$D21*VLOOKUP($C21,$A$5:$F$14,2,FALSE)*(1+VLOOKUP($C21,$A$5:$F$14,3,FALSE))*VLOOKUP($C21,$A$5:$F$14,6,FALSE),"")
A22: TTS.PC.001.IPE140.30 | B22: Pilastro cuscinetto trave IPE 140 mt.3,00 | C22: IPE 140 | D22: 3 | E22: =IF(AND(ISNUMBER($D22),ISNUMBER(VLOOKUP($C22,$A$5:$F$14,4,FALSE))),$D22*VLOOKUP($C22,$A$5:$F$14,4,FALSE),"") | F22: =IF(AND(ISNUMBER($D22),ISNUMBER(VLOOKUP($C22,$A$5:$F$14,2,FALSE)),ISNUMBER(VLOOKUP($C22,$A$5:$F$14,5,FALSE))),$D22*VLOOKUP($C22,$A$5:$F$14,2,FALSE)*VLOOKUP($C22,$A$5:$F$14,5,FALSE),"") | G22: =IF(AND(ISNUMBER($D22),ISNUMBER(VLOOKUP($C22,$A$5:$F$14,2,FALSE)),ISNUMBER(VLOOKUP($C22,$A$5:$F$14,3,FALSE)),VLOOKUP($C22,$A$5:$F$14,3,FALSE)>0,ISNUMBER(VLOOKUP($C22,$A$5:$F$14,6,FALSE))),$D22*VLOOKUP($C22,$A$5:$F$14,2,FALSE)*(1+VLOOKUP($C22,$A$5:$F$14,3,FALSE))*VLOOKUP($C22,$A$5:$F$14,6,FALSE),"")
A23: TTS.PC.001.IPE140.31 | B23: Pilastro cuscinetto trave IPE 140 mt.3,10 | C23: IPE 140 | D23: 3.1 | E23: =IF(AND(ISNUMBER($D23),ISNUMBER(VLOOKUP($C23,$A$5:$F$14,4,FALSE))),$D23*VLOOKUP($C23,$A$5:$F$14,4,FALSE),"") | F23: =IF(AND(ISNUMBER($D23),ISNUMBER(VLOOKUP($C23,$A$5:$F$14,2,FALSE)),ISNUMBER(VLOOKUP($C23,$A$5:$F$14,5,FALSE))),$D23*VLOOKUP($C23,$A$5:$F$14,2,FALSE)*VLOOKUP($C23,$A$5:$F$14,5,FALSE),"") | G23: =IF(AND(ISNUMBER($D23),ISNUMBER(VLOOKUP($C23,$A$5:$F$14,2,FALSE)),ISNUMBER(VLOOKUP($C23,$A$5:$F$14,3,FALSE)),VLOOKUP($C23,$A$5:$F$14,3,FALSE)>0,ISNUMBER(VLOOKUP($C23,$A$5:$F$14,6,FALSE))),$D23*VLOOKUP($C23,$A$5:$F$14,2,FALSE)*(1+VLOOKUP($C23,$A$5:$F$14,3,FALSE))*VLOOKUP($C23,$A$5:$F$14,6,FALSE),"")
A24: TTS.PC.001.IPE140.32 | B24: Pilastro cuscinetto trave IPE 140 mt.3,20 | C24: IPE 140 | D24: 3.2 | E24: =IF(AND(ISNUMBER($D24),ISNUMBER(VLOOKUP($C24,$A$5:$F$14,4,FALSE))),$D24*VLOOKUP($C24,$A$5:$F$14,4,FALSE),"") | F24: =IF(AND(ISNUMBER($D24),ISNUMBER(VLOOKUP($C24,$A$5:$F$14,2,FALSE)),ISNUMBER(VLOOKUP($C24,$A$5:$F$14,5,FALSE))),$D24*VLOOKUP($C24,$A$5:$F$14,2,FALSE)*VLOOKUP($C24,$A$5:$F$14,5,FALSE),"") | G24: =IF(AND(ISNUMBER($D24),ISNUMBER(VLOOKUP($C24,$A$5:$F$14,2,FALSE)),ISNUMBER(VLOOKUP($C24,$A$5:$F$14,3,FALSE)),VLOOKUP($C24,$A$5:$F$14,3,FALSE)>0,ISNUMBER(VLOOKUP($C24,$A$5:$F$14,6,FALSE))),$D24*VLOOKUP($C24,$A$5:$F$14,2,FALSE)*(1+VLOOKUP($C24,$A$5:$F$14,3,FALSE))*VLOOKUP($C24,$A$5:$F$14,6,FALSE),"")
A25: TTS.PC.001.IPE140.33 | B25: Pilastro cuscinetto trave IPE 140 mt.3,30 | C25: IPE 140 | D25: 3.3 | E25: =IF(AND(ISNUMBER($D25),ISNUMBER(VLOOKUP($C25,$A$5:$F$14,4,FALSE))),$D25*VLOOKUP($C25,$A$5:$F$14,4,FALSE),"") | F25: =IF(AND(ISNUMBER($D25),ISNUMBER(VLOOKUP($C25,$A$5:$F$14,2,FALSE)),ISNUMBER(VLOOKUP($C25,$A$5:$F$14,5,FALSE))),$D25*VLOOKUP($C25,$A$5:$F$14,2,FALSE)*VLOOKUP($C25,$A$5:$F$14,5,FALSE),"") | G25: =IF(AND(ISNUMBER($D25),ISNUMBER(VLOOKUP($C25,$A$5:$F$14,2,FALSE)),ISNUMBER(VLOOKUP($C25,$A$5:$F$14,3,FALSE)),VLOOKUP($C25,$A$5:$F$14,3,FALSE)>0,ISNUMBER(VLOOKUP($C25,$A$5:$F$14,6,FALSE))),$D25*VLOOKUP($C25,$A$5:$F$14,2,FALSE)*(1+VLOOKUP($C25,$A$5:$F$14,3,FALSE))*VLOOKUP($C25,$A$5:$F$14,6,FALSE),"")
A26: TTS.PC.001.IPE140.34 | B26: Pilastro cuscinetto trave IPE 140 mt.3,40 | C26: IPE 140 | D26: 3.4 | E26: =IF(AND(ISNUMBER($D26),ISNUMBER(VLOOKUP($C26,$A$5:$F$14,4,FALSE))),$D26*VLOOKUP($C26,$A$5:$F$14,4,FALSE),"") | F26: =IF(AND(ISNUMBER($D26),ISNUMBER(VLOOKUP($C26,$A$5:$F$14,2,FALSE)),ISNUMBER(VLOOKUP($C26,$A$5:$F$14,5,FALSE))),$D26*VLOOKUP($C26,$A$5:$F$14,2,FALSE)*VLOOKUP($C26,$A$5:$F$14,5,FALSE),"") | G26: =IF(AND(ISNUMBER($D26),ISNUMBER(VLOOKUP($C26,$A$5:$F$14,2,FALSE)),ISNUMBER(VLOOKUP($C26,$A$5:$F$14,3,FALSE)),VLOOKUP($C26,$A$5:$F$14,3,FALSE)>0,ISNUMBER(VLOOKUP($C26,$A$5:$F$14,6,FALSE))),$D26*VLOOKUP($C26,$A$5:$F$14,2,FALSE)*(1+VLOOKUP($C26,$A$5:$F$14,3,FALSE))*VLOOKUP($C26,$A$5:$F$14,6,FALSE),"")
A27: TTS.PC.001.IPE140.35 | B27: Pilastro cuscinetto trave IPE 140 mt.3,50 | C27: IPE 140 | D27: 3.5 | E27: =IF(AND(ISNUMBER($D27),ISNUMBER(VLOOKUP($C27,$A$5:$F$14,4,FALSE))),$D27*VLOOKUP($C27,$A$5:$F$14,4,FALSE),"") | F27: =IF(AND(ISNUMBER($D27),ISNUMBER(VLOOKUP($C27,$A$5:$F$14,2,FALSE)),ISNUMBER(VLOOKUP($C27,$A$5:$F$14,5,FALSE))),$D27*VLOOKUP($C27,$A$5:$F$14,2,FALSE)*VLOOKUP($C27,$A$5:$F$14,5,FALSE),"") | G27: =IF(AND(ISNUMBER($D27),ISNUMBER(VLOOKUP($C27,$A$5:$F$14,2,FALSE)),ISNUMBER(VLOOKUP($C27,$A$5:$F$14,3,FALSE)),VLOOKUP($C27,$A$5:$F$14,3,FALSE)>0,ISNUMBER(VLOOKUP($C27,$A$5:$F$14,6,FALSE))),$D27*VLOOKUP($C27,$A$5:$F$14,2,FALSE)*(1+VLOOKUP($C27,$A$5:$F$14,3,FALSE))*VLOOKUP($C27,$A$5:$F$14,6,FALSE),"")
A28: TTS.PC.001.IPE140.36 | B28: Pilastro cuscinetto trave IPE 140 mt.3,60 | C28: IPE 140 | D28: 3.6 | E28: =IF(AND(ISNUMBER($D28),ISNUMBER(VLOOKUP($C28,$A$5:$F$14,4,FALSE))),$D28*VLOOKUP($C28,$A$5:$F$14,4,FALSE),"") | F28: =IF(AND(ISNUMBER($D28),ISNUMBER(VLOOKUP($C28,$A$5:$F$14,2,FALSE)),ISNUMBER(VLOOKUP($C28,$A$5:$F$14,5,FALSE))),$D28*VLOOKUP($C28,$A$5:$F$14,2,FALSE)*VLOOKUP($C28,$A$5:$F$14,5,FALSE),"") | G28: =IF(AND(ISNUMBER($D28),ISNUMBER(VLOOKUP($C28,$A$5:$F$14,2,FALSE)),ISNUMBER(VLOOKUP($C28,$A$5:$F$14,3,FALSE)),VLOOKUP($C28,$A$5:$F$14,3,FALSE)>0,ISNUMBER(VLOOKUP($C28,$A$5:$F$14,6,FALSE))),$D28*VLOOKUP($C28,$A$5:$F$14,2,FALSE)*(1+VLOOKUP($C28,$A$5:$F$14,3,FALSE))*VLOOKUP($C28,$A$5:$F$14,6,FALSE),"")
... A147: TTS.AR.2011 | B147: Gaffa giunzione asse | C147: GAFFA GIUNZIONE ASSE | D147: 1 | E147: =IF(AND(ISNUMBER($D147),ISNUMBER(VLOOKUP($C147,$A$5:$F$14,4,FALSE))),$D147*VLOOKUP($C147,$A$5:$F$14,4,FALSE),"") | F147: =IF(AND(ISNUMBER($D147),ISNUMBER(VLOOKUP($C147,$A$5:$F$14,2,FALSE)),ISNUMBER(VLOOKUP($C147,$A$5:$F$14,5,FALSE))),$D147*VLOOKUP($C147,$A$5:$F$14,2,FALSE)*VLOOKUP($C147,$A$5:$F$14,5,FALSE),"") | G147: =IF(AND(ISNUMBER($D147),ISNUMBER(VLOOKUP($C147,$A$5:$F$14,2,FALSE)),ISNUMBER(VLOOKUP($C147,$A$5:$F$14,3,FALSE)),VLOOKUP($C147,$A$5:$F$14,3,FALSE)>0,ISNUMBER(VLOOKUP($C147,$A$5:$F$14,6,FALSE))),$D147*VLOOKUP($C147,$A$5:$F$14,2,FALSE)*(1+VLOOKUP($C147,$A$5:$F$14,3,FALSE))*VLOOKUP($C147,$A$5:$F$14,6,FALSE),"")

Sheet SCHEDA PEZZI SPECIALI
A1: SCHEDA PEZZI SPECIALI — parametri peso e costo di acquisto/zincatura dei pezzi 'a pezzo' di carpenteria metallica (piastre di giunzione, supporti, angolari, omega, pali MAX, aste sensori)
A2: Un rigo per voce nel blocco 'Parametri'. Compilare Peso pezzo (kg) al netto, % zincatura, €/kg acquisto e €/kg zincatura. Peso elemento (kg) include la maggiorazione zincatura; Costo acquisto (€) = peso al netto × €/kg acquisto (indipendente dalla zincatura); Costo zincatura (€) = peso al netto × (1 + magg. %) × €/kg zincatura, solo se la maggiorazione è presente. La Descrizione si compila qui nei Parametri; nell'Elenco è richiamata automaticamente. Il LISTINO pesca il 'Peso elemento' dal blocco 'Elenco'.
A4: PEZZI SPECIALI — parametri (compilare Descrizione, Peso pezzo, % zincatura e €/kg)
A5: Voce | B5: Descrizione | C5: Peso pezzo (kg) | D5: Magg. zincatura % | E5: Peso finale (kg) | F5: Costo acquisto (€/kg) | G5: Costo zincatura (€/kg)
A6: TTS.PF.002.IPE140 | B6: Piastra giunzione montanti centrali 200x100x4 (8 fori Ø 11) | C6: 0.624 | D6: 0.025 | E6: =IF(ISNUMBER($C6),$C6*(1+IF(ISNUMBER($D6),$D6,0)),"") | F6: 0.85 | G6: 0.85
A7: TTS.PF.003.IPE140 | B7: Piastra giunzione montanti esterna 240x70x6 (12 fori Ø 11) | C7: 0.7862 | D7: 0.025 | E7: =IF(ISNUMBER($C7),$C7*(1+IF(ISNUMBER($D7),$D7,0)),"") | F7: 0.85 | G7: 0.85
A8: TTS.PF.004.IPE140 | B8: Piastra giunzione montanti interna 240x25x6 (6 fori Ø 11) | C8: 0.2808 | D8: 0.025 | E8: =IF(ISNUMBER($C8),$C8*(1+IF(ISNUMBER($D8),$D8,0)),"") | F8: 0.85 | G8: 0.85
A9: TTS.AR.4011 | B9: Supporto superiore inclinometro | C9: 0.8424 | D9: 0 | E9: =IF(ISNUMBER($C9),$C9*(1+IF(ISNUMBER($D9),$D9,0)),"") | F9: 1.2
A10: TTS.AR.4012 | B10: Supporto inferiore inclinometro | C10: 2.9484 | D10: 0 | E10: =IF(ISNUMBER($C10),$C10*(1+IF(ISNUMBER($D10),$D10,0)),"") | F10: 1.2
A11: TTS.AR.5011 | B11: Piastra ad L supporto fine corsa | C11: 0.2184 | D11: 0.025 | E11: =IF(ISNUMBER($C11),$C11*(1+IF(ISNUMBER($D11),$D11,0)),"") | F11: 1.2
A12: TTS.AR.5012 | B12: Leva battente sensore fine corsa | C12: 0.6524 | D12: 0.025 | E12: =IF(ISNUMBER($C12),$C12*(1+IF(ISNUMBER($D12),$D12,0)),"") | F12: 1.2
A13: TTS.PC.002.IPE140 | B13: Supporto laterale testa cuscinetto | C13: 2.1528 | D13: 0.025 | E13: =IF(ISNUMBER($C13),$C13*(1+IF(ISNUMBER($D13),$D13,0)),"") | F13: 0.95 | G13: 0.9
A14: TTS.PC.003.IPE140 | B14: Supporto testa cuscinetto | C14: 2.7256 | D14: 0.025 | E14: =IF(ISNUMBER($C14),$C14*(1+IF(ISNUMBER($D14),$D14,0)),"") | F14: 0.95 | G14: 0.9
A15: TTS.PC.2011.1076 | B15: Angolare 40x40x4 lungo 1076 mm. supporto inferiore | C15: 2.685696 | D15: 0.025 | E15: =IF(ISNUMBER($C15),$C15*(1+IF(ISNUMBER($D15),$D15,0)),"") | F15: 1.2
A16: TTS.PC.2012.1076 | B16: Angolare 40x40x4 lungo1076 mm. supporto superiore | C16: 2.685696 | D16: 0.025 | E16: =IF(ISNUMBER($C16),$C16*(1+IF(ISNUMBER($D16),$D16,0)),"") | F16: 1.2
A17: TTS.PC.2013 | B17: Palo MAX lungo mt.2,040 | C17: 7.00128 | D17: 0.025 | E17: =IF(ISNUMBER($C17),$C17*(1+IF(ISNUMBER($D17),$D17,0)),"") | F17: 0.95
A18: TTS.PC.3011 | B18: Angolare 40x40x4 lungo 869 mm. superiore | C18: 2.169 | D18: 0.025 | E18: =IF(ISNUMBER($C18),$C18*(1+IF(ISNUMBER($D18),$D18,0)),"") | F18: 1.2
A19: TTS.PC.3012 | B19: Angolare 40x40x4 lungo 869 mm. inferiore | C19: 2.169 | D19: 0.025 | E19: =IF(ISNUMBER($C19),$C19*(1+IF(ISNUMBER($D19),$D19,0)),"") | F19: 1.2
A20: TTS.PC.3013 | B20: Palo MAX lungo mt.2,150 | C20: 7.3788 | D20: 0.025 | E20: =IF(ISNUMBER($C20),$C20*(1+IF(ISNUMBER($D20),$D20,0)),"") | F20: 0.95
A21: TTS.PM.002.IPE140 | B21: Supporto laterale testa riduttore | C21: 4.5708 | D21: 0.025 | E21: =IF(ISNUMBER($C21),$C21*(1+IF(ISNUMBER($D21),$D21,0)),"") | F21: 0.9 | G21: 0.9
A22: TTS.PM.003.IPE140 | B22: Testa riduttore pilastro motore | C22: 2.54 | D22: 0.025 | E22: =IF(ISNUMBER($C22),$C22*(1+IF(ISNUMBER($D22),$D22,0)),"") | F22: 0.9 | G22: 0.9
A23: TTS.PM.2011 | B23: Angolare 30x30x4 lungo 370 mm. superiore | C23: 0.5195 | D23: 0.025 | E23: =IF(ISNUMBER($C23),$C23*(1+IF(ISNUMBER($D23),$D23,0)),"") | F23: 1.2
A24: TTS.PM.2012 | B24: Angolare 30x30x4 lungo 370 mm. inferiore | C24: 0.5195 | D24: 0.025 | E24: =IF(ISNUMBER($C24),$C24*(1+IF(ISNUMBER($D24),$D24,0)),"") | F24: 1.2
A25: TTS.SM.001 | B25: Piatto 50X5X230 supporto sensori | C25: 0.451375 | D25: 0.025 | E25: =IF(ISNUMBER($C25),$C25*(1+IF(ISNUMBER($D25),$D25,0)),"") | F25: 1.2
A26: TTS.SM.002 | B26: Piatto 30X3X193 leva sensore temperatura pannello | C26: 0.136355 | D26: 0.025 | E26: =IF(ISNUMBER($C26),$C26*(1+IF(ISNUMBER($D26),$D26,0)),"") | F26: 1.2
A27: TTS.SM.003 | B27: Asta supporto anemometro | E27: =IF(ISNUMBER($C27),$C27*(1+IF(ISNUMBER($D27),$D27,0)),"")
A36: PEZZI SPECIALI — elenco (descrizione, peso e costi richiamati dai parametri qui sopra)
A37: Codice | B37: Descrizione | C37: Voce | D37: Peso elemento (kg) | E37: Costo acquisto (€) | F37: Costo zincatura (€)
A38: TTS.PF.002.IPE140 | B38: =IFERROR(VLOOKUP($C38,$A$6:$G$27,2,FALSE),"") | C38: TTS.PF.002.IPE140 | D38: =IF(ISNUMBER(VLOOKUP($C38,$A$6:$G$27,5,FALSE)),VLOOKUP($C38,$A$6:$G$27,5,FALSE),"") | E38: =IF(AND(ISNUMBER(VLOOKUP($C38,$A$6:$G$27,3,FALSE)),ISNUMBER(VLOOKUP($C38,$A$6:$G$27,6,FALSE))),VLOOKUP($C38,$A$6:$G$27,3,FALSE)*VLOOKUP($C38,$A$6:$G$27,6,FALSE),"") | F38: =IF(AND(ISNUMBER(VLOOKUP($C38,$A$6:$G$27,3,FALSE)),ISNUMBER(VLOOKUP($C38,$A$6:$G$27,4,FALSE)),VLOOKUP($C38,$A$6:$G$27,4,FALSE)>0,ISNUMBER(VLOOKUP($C38,$A$6:$G$27,7,FALSE))),VLOOKUP($C38,$A$6:$G$27,3,FALSE)*(1+VLOOKUP($C38,$A$6:$G$27,4,FALSE))*VLOOKUP($C38,$A$6:$G$27,7,FALSE),"")
A39: TTS.PF.003.IPE140 | B39: =IFERROR(VLOOKUP($C39,$A$6:$G$27,2,FALSE),"") | C39: TTS.PF.003.IPE140 | D39: =IF(ISNUMBER(VLOOKUP($C39,$A$6:$G$27,5,FALSE)),VLOOKUP($C39,$A$6:$G$27,5,FALSE),"") | E39: =IF(AND(ISNUMBER(VLOOKUP($C39,$A$6:$G$27,3,FALSE)),ISNUMBER(VLOOKUP($C39,$A$6:$G$27,6,FALSE))),VLOOKUP($C39,$A$6:$G$27,3,FALSE)*VLOOKUP($C39,$A$6:$G$27,6,FALSE),"") | F39: =IF(AND(ISNUMBER(VLOOKUP($C39,$A$6:$G$27,3,FALSE)),ISNUMBER(VLOOKUP($C39,$A$6:$G$27,4,FALSE)),VLOOKUP($C39,$A$6:$G$27,4,FALSE)>0,ISNUMBER(VLOOKUP($C39,$A$6:$G$27,7,FALSE))),VLOOKUP($C39,$A$6:$G$27,3,FALSE)*(1+VLOOKUP($C39,$A$6:$G$27,4,FALSE))*VLOOKUP($C39,$A$6:$G$27,7,FALSE),"")
A40: TTS.PF.004.IPE140 | B40: =IFERROR(VLOOKUP($C40,$A$6:$G$27,2,FALSE),"") | C40: TTS.PF.004.IPE140 | D40: =IF(ISNUMBER(VLOOKUP($C40,$A$6:$G$27,5,FALSE)),VLOOKUP($C40,$A$6:$G$27,5,FALSE),"") | E40: =IF(AND(ISNUMBER(VLOOKUP($C40,$A$6:$G$27,3,FALSE)),ISNUMBER(VLOOKUP($C40,$A$6:$G$27,6,FALSE))),VLOOKUP($C40,$A$6:$G$27,3,FALSE)*VLOOKUP($C40,$A$6:$G$27,6,FALSE),"") | F40: =IF(AND(ISNUMBER(VLOOKUP($C40,$A$6:$G$27,3,FALSE)),ISNUMBER(VLOOKUP($C40,$A$6:$G$27,4,FALSE)),VLOOKUP($C40,$A$6:$G$27,4,FALSE)>0,ISNUMBER(VLOOKUP($C40,$A$6:$G$27,7,FALSE))),VLOOKUP($C40,$A$6:$G$27,3,FALSE)*(1+VLOOKUP($C40,$A$6:$G$27,4,FALSE))*VLOOKUP($C40,$A$6:$G$27,7,FALSE),"")
A41: TTS.AR.4011 | B41: =IFERROR(VLOOKUP($C41,$A$6:$G$27,2,FALSE),"") | C41: TTS.AR.4011 | D41: =IF(ISNUMBER(VLOOKUP($C41,$A$6:$G$27,5,FALSE)),VLOOKUP($C41,$A$6:$G$27,5,FALSE),"") | E41: =IF(AND(ISNUMBER(VLOOKUP($C41,$A$6:$G$27,3,FALSE)),ISNUMBER(VLOOKUP($C41,$A$6:$G$27,6,FALSE))),VLOOKUP($C41,$A$6:$G$27,3,FALSE)*VLOOKUP($C41,$A$6:$G$27,6,FALSE),"") | F41: =IF(AND(ISNUMBER(VLOOKUP($C41,$A$6:$G$27,3,FALSE)),ISNUMBER(VLOOKUP($C41,$A$6:$G$27,4,FALSE)),VLOOKUP($C41,$A$6:$G$27,4,FALSE)>0,ISNUMBER(VLOOKUP($C41,$A$6:$G$27,7,FALSE))),VLOOKUP($C41,$A$6:$G$27,3,FALSE)*(1+VLOOKUP($C41,$A$6:$G$27,4,FALSE))*VLOOKUP($C41,$A$6:$G$27,7,FALSE),"")
A42: TTS.AR.4012 | B42: =IFERROR(VLOOKUP($C42,$A$6:$G$27,2,FALSE),"") | C42: TTS.AR.4012 | D42: =IF(ISNUMBER(VLOOKUP($C42,$A$6:$G$27,5,FALSE)),VLOOKUP($C42,$A$6:$G$27,5,FALSE),"") | E42: =IF(AND(ISNUMBER(VLOOKUP($C42,$A$6:$G$27,3,FALSE)),ISNUMBER(VLOOKUP($C42,$A$6:$G$27,6,FALSE))),VLOOKUP($C42,$A$6:$G$27,3,FALSE)*VLOOKUP($C42,$A$6:$G$27,6,FALSE),"") | F42: =IF(AND(ISNUMBER(VLOOKUP($C42,$A$6:$G$27,3,FALSE)),ISNUMBER(VLOOKUP($C42,$A$6:$G$27,4,FALSE)),VLOOKUP($C42,$A$6:$G$27,4,FALSE)>0,ISNUMBER(VLOOKUP($C42,$A$6:$G$27,7,FALSE))),VLOOKUP($C42,$A$6:$G$27,3,FALSE)*(1+VLOOKUP($C42,$A$6:$G$27,4,FALSE))*VLOOKUP($C42,$A$6:$G$27,7,FALSE),"")
A43: TTS.AR.5011 | B43: =IFERROR(VLOOKUP($C43,$A$6:$G$27,2,FALSE),"") | C43: TTS.AR.5011 | D43: =IF(ISNUMBER(VLOOKUP($C43,$A$6:$G$27,5,FALSE)),VLOOKUP($C43,$A$6:$G$27,5,FALSE),"") | E43: =IF(AND(ISNUMBER(VLOOKUP($C43,$A$6:$G$27,3,FALSE)),ISNUMBER(VLOOKUP($C43,$A$6:$G$27,6,FALSE))),VLOOKUP($C43,$A$6:$G$27,3,FALSE)*VLOOKUP($C43,$A$6:$G$27,6,FALSE),"") | F43: =IF(AND(ISNUMBER(VLOOKUP($C43,$A$6:$G$27,3,FALSE)),ISNUMBER(VLOOKUP($C43,$A$6:$G$27,4,FALSE)),VLOOKUP($C43,$A$6:$G$27,4,FALSE)>0,ISNUMBER(VLOOKUP($C43,$A$6:$G$27,7,FALSE))),VLOOKUP($C43,$A$6:$G$27,3,FALSE)*(1+VLOOKUP($C43,$A$6:$G$27,4,FALSE))*VLOOKUP($C43,$A$6:$G$27,7,FALSE),"")
A44: TTS.AR.5012 | B44: =IFERROR(VLOOKUP($C44,$A$6:$G$27,2,FALSE),"") | C44: TTS.AR.5012 | D44: =IF(ISNUMBER(VLOOKUP($C44,$A$6:$G$27,5,FALSE)),VLOOKUP($C44,$A$6:$G$27,5,FALSE),"") | E44: =IF(AND(ISNUMBER(VLOOKUP($C44,$A$6:$G$27,3,FALSE)),ISNUMBER(VLOOKUP($C44,$A$6:$G$27,6,FALSE))),VLOOKUP($C44,$A$6:$G$27,3,FALSE)*VLOOKUP($C44,$A$6:$G$27,6,FALSE),"") | F44: =IF(AND(ISNUMBER(VLOOKUP($C44,$A$6:$G$27,3,FALSE)),ISNUMBER(VLOOKUP($C44,$A$6:$G$27,4,FALSE)),VLOOKUP($C44,$A$6:$G$27,4,FALSE)>0,ISNUMBER(VLOOKUP($C44,$A$6:$G$27,7,FALSE))),VLOOKUP($C44,$A$6:$G$27,3,FALSE)*(1+VLOOKUP($C44,$A$6:$G$27,4,FALSE))*VLOOKUP($C44,$A$6:$G$27,7,FALSE),"")
A45: TTS.PC.002.IPE140 | B45: =IFERROR(VLOOKUP($C45,$A$6:$G$27,2,FALSE),"") | C45: TTS.PC.002.IPE140 | D45: =IF(ISNUMBER(VLOOKUP($C45,$A$6:$G$27,5,FALSE)),VLOOKUP($C45,$A$6:$G$27,5,FALSE),"") | E45: =IF(AND(ISNUMBER(VLOOKUP($C45,$A$6:$G$27,3,FALSE)),ISNUMBER(VLOOKUP($C45,$A$6:$G$27,6,FALSE))),VLOOKUP($C45,$A$6:$G$27,3,FALSE)*VLOOKUP($C45,$A$6:$G$27,6,FALSE),"") | F45: =IF(AND(ISNUMBER(VLOOKUP($C45,$A$6:$G$27,3,FALSE)),ISNUMBER(VLOOKUP($C45,$A$6:$G$27,4,FALSE)),VLOOKUP($C45,$A$6:$G$27,4,FALSE)>0,ISNUMBER(VLOOKUP($C45,$A$6:$G$27,7,FALSE))),VLOOKUP($C45,$A$6:$G$27,3,FALSE)*(1+VLOOKUP($C45,$A$6:$G$27,4,FALSE))*VLOOKUP($C45,$A$6:$G$27,7,FALSE),"")
A46: TTS.PC.003.IPE140 | B46: =IFERROR(VLOOKUP($C46,$A$6:$G$27,2,FALSE),"") | C46: TTS.PC.003.IPE140 | D46: =IF(ISNUMBER(VLOOKUP($C46,$A$6:$G$27,5,FALSE)),VLOOKUP($C46,$A$6:$G$27,5,FALSE),"") | E46: =IF(AND(ISNUMBER(VLOOKUP($C46,$A$6:$G$27,3,FALSE)),ISNUMBER(VLOOKUP($C46,$A$6:$G$27,6,FALSE))),VLOOKUP($C46,$A$6:$G$27,3,FALSE)*VLOOKUP($C46,$A$6:$G$27,6,FALSE),"") | F46: =IF(AND(ISNUMBER(VLOOKUP($C46,$A$6:$G$27,3,FALSE)),ISNUMBER(VLOOKUP($C46,$A$6:$G$27,4,FALSE)),VLOOKUP($C46,$A$6:$G$27,4,FALSE)>0,ISNUMBER(VLOOKUP($C46,$A$6:$G$27,7,FALSE))),VLOOKUP($C46,$A$6:$G$27,3,FALSE)*(1+VLOOKUP($C46,$A$6:$G$27,4,FALSE))*VLOOKUP($C46,$A$6:$G$27,7,FALSE),"")
A47: TTS.PC.2011.1076 | B47: =IFERROR(VLOOKUP($C47,$A$6:$G$27,2,FALSE),"") | C47: TTS.PC.2011.1076 | D47: =IF(ISNUMBER(VLOOKUP($C47,$A$6:$G$27,5,FALSE)),VLOOKUP($C47,$A$6:$G$27,5,FALSE),"") | E47: =IF(AND(ISNUMBER(VLOOKUP($C47,$A$6:$G$27,3,FALSE)),ISNUMBER(VLOOKUP($C47,$A$6:$G$27,6,FALSE))),VLOOKUP($C47,$A$6:$G$27,3,FALSE)*VLOOKUP($C47,$A$6:$G$27,6,FALSE),"") | F47: =IF(AND(ISNUMBER(VLOOKUP($C47,$A$6:$G$27,3,FALSE)),ISNUMBER(VLOOKUP($C47,$A$6:$G$27,4,FALSE)),VLOOKUP($C47,$A$6:$G$27,4,FALSE)>0,ISNUMBER(VLOOKUP($C47,$A$6:$G$27,7,FALSE))),VLOOKUP($C47,$A$6:$G$27,3,FALSE)*(1+VLOOKUP($C47,$A$6:$G$27,4,FALSE))*VLOOKUP($C47,$A$6:$G$27,7,FALSE),"")
A48: TTS.PC.2012.1076 | B48: =IFERROR(VLOOKUP($C48,$A$6:$G$27,2,FALSE),"") | C48: TTS.PC.2012.1076 | D48: =IF(ISNUMBER(VLOOKUP($C48,$A$6:$G$27,5,FALSE)),VLOOKUP($C48,$A$6:$G$27,5,FALSE),"") | E48: =IF(AND(ISNUMBER(VLOOKUP($C48,$A$6:$G$27,3,FALSE)),ISNUMBER(VLOOKUP($C48,$A$6:$G$27,6,FALSE))),VLOOKUP($C48,$A$6:$G$27,3,FALSE)*VLOOKUP($C48,$A$6:$G$27,6,FALSE),"") | F48: =IF(AND(ISNUMBER(VLOOKUP($C48,$A$6:$G$27,3,FALSE)),ISNUMBER(VLOOKUP($C48,$A$6:$G$27,4,FALSE)),VLOOKUP($C48,$A$6:$G$27,4,FALSE)>0,ISNUMBER(VLOOKUP($C48,$A$6:$G$27,7,FALSE))),VLOOKUP($C48,$A$6:$G$27,3,FALSE)*(1+VLOOKUP($C48,$A$6:$G$27,4,FALSE))*VLOOKUP($C48,$A$6:$G$27,7,FALSE),"")
A49: TTS.PC.2013 | B49: =IFERROR(VLOOKUP($C49,$A$6:$G$27,2,FALSE),"") | C49: TTS.PC.2013 | D49: =IF(ISNUMBER(VLOOKUP($C49,$A$6:$G$27,5,FALSE)),VLOOKUP($C49,$A$6:$G$27,5,FALSE),"") | E49: =IF(AND(ISNUMBER(VLOOKUP($C49,$A$6:$G$27,3,FALSE)),ISNUMBER(VLOOKUP($C49,$A$6:$G$27,6,FALSE))),VLOOKUP($C49,$A$6:$G$27,3,FALSE)*VLOOKUP($C49,$A$6:$G$27,6,FALSE),"") | F49: =IF(AND(ISNUMBER(VLOOKUP($C49,$A$6:$G$27,3,FALSE)),ISNUMBER(VLOOKUP($C49,$A$6:$G$27,4,FALSE)),VLOOKUP($C49,$A$6:$G$27,4,FALSE)>0,ISNUMBER(VLOOKUP($C49,$A$6:$G$27,7,FALSE))),VLOOKUP($C49,$A$6:$G$27,3,FALSE)*(1+VLOOKUP($C49,$A$6:$G$27,4,FALSE))*VLOOKUP($C49,$A$6:$G$27,7,FALSE),"")
...

Sheet SCHEDA BULLONERIA
A1: SCHEDA BULLONERIA — peso unitario e costo della minuteria/bulloneria commerciale (bulloni, dadi, rondelle)
A2: Un rigo per codice. Peso unitario (kg) pre-compilato con valori nominali da tabelle standard (DIN 933/931 bulloni, DIN 985 dadi autobloccanti, DIN 125A rondelle) — da confermare/aggiornare a mano. Compilare il Costo (€/pz). Il LISTINO pesca da qui 'Peso elemento (kg)' e 'Prezzo unitario €' per questi codici.
A4: BULLONERIA — peso unitario e costo (confermare Peso unitario, compilare Costo €/pz)
A5: Codice | B5: Descrizione | C5: Peso unitario (kg) | D5: Costo (€/pz)
A6: 06TAP120X120 | B6: Tappo profilato 120x120
A7: 10BZ10X30 | B7: Bullone testa esagonale M10X30 | C7: 0.0245
A8: 10BZ10X40 | B8: Bullone testa esagonale zn M10X40 | C8: 0.0305
A9: 10BZ16X140 | B9: Bullone testa esagonale M16x140 mezzo filetto | C9: 0.21
A10: 10BZM10X160 | B10: Bullone testa esagonale zn M10X160 | C10: 0.095
A11: 10BZM10X30 | B11: Bullone testa esagonale zn M10X30 | C11: 0.0245
A12: 10BZM10X40 | B12: Bullone testa esagonale M10X40 | C12: 0.0305
A13: 10BZM16X25 | B13: Bullone testa esagonale zn M16X25 | C13: 0.052
A14: 10BZM16X60 | B14: Bullone testa esagonale M16X60 | C14: 0.11
A15: 10BZM5X20 | B15: Bullone testa esagonale zn M5x20 | C15: 0.0031
A16: 10BZM5X30 | B16: Bullone testa esagonale zn M5x30 | C16: 0.0042
A17: 10BZM6X150 | B17: Bullone testa esagonale zn M6X150 | C17: 0.026
A18: 10BZM6X20 | B18: Bullone testa esagonale zn M6X20 | C18: 0.0054
... A36: M5X30 8.8 ISO1207 | B36: Bullone testa esagonale con intaglio M5x30 | C36: 0.0042

Sheet SCHEDA ELETTROMECCANICA
A1: SCHEDA ELETTROMECCANICA — peso unitario e costo dei materiali elettromeccanici commerciali
A2: Motoriduttore, cuscinetto asse, quadri/box, sensori e strumentazione. Articoli acquistati completi: compilare a mano 'Peso unitario (kg)' e 'Costo (€/pz)'. Il LISTINO pesca da qui 'Peso elemento (kg)' e 'Prezzo unitario €' per questi codici.
A4: Codice | B4: Descrizione | C4: Peso unitario (kg) | D4: Costo (€/pz)
A5: CHSD7-60-S112-24.15.300-L1.2 | B5: Motoriduttore | C5: 50 | D5: 300
A6: ESQM_2_0_120_1 | B6: Cuscinetto asse di rotazione | C6: 2 | D6: 13
A7: 15T-JUNCTBOXIP65 | B7: Box centralina meteo
A8: B04601 | B8: Quadro in vetroresina Pedro VTR 01
A9: 10S-FC | B9: Sensore fine corsa elettrico
A10: 15T-PIRANOMETRO | B10: Piranometro
A11: 15T-SENSVELVEN | B11: Anemometro
A12: 15T-TERMARIA | B12: Termometro Aria_ mSTA.l
A13: 15T-TERMCONTP10 | B13: Termometro a contatto P100_STC-i
A14: TK1024S | B14: Inclinometro

Sheet LISTINO
A1: LISTINO COMPONENTI — Tracker TTS moduli 1303 (rev. 5)
A2: Elenco unico di tutti i componenti presenti nella distinta materiali. Compilare la colonna 'Prezzo unitario' per ottenere un listino valorizzato.
A4: N° | B4: Codice | C4: Descrizione | D4: Categoria | E4: U.M. | F4: Peso elemento (kg) | G4: Prezzo unitario € | H4: Presente nei kit / assiemi | I4: N° righe distinta
A5: 1 | B5: TTS.AR.001.7200 | C5: Asse lato motore 120x120x3 mm. lunghezza mt.7,20 | D5: Carpenteria metallica | E5: pz | F5: =IFERROR(VLOOKUP($B5,'SCHEDA STRUTTURA'!$A$17:$E$417,5,FALSE),"") | G5: =IF($B5="","",IF(ISNUMBER(MATCH($B5,'SCHEDA STRUTTURA'!$A$17:$A$147,0)),IFERROR(VLOOKUP($B5,'SCHEDA STRUTTURA'!$A$17:$G$147,6,FALSE)*1,0)+IFERROR(VLOOKUP($B5,'SCHEDA STRUTTURA'!$A$17:$G$147,7,FALSE)*1,0),IF(ISNUMBER(MATCH($B5,'SCHEDA PEZZI SPECIALI'!$A$38:$A$59,0)),IFERROR(VLOOKUP($B5,'SCHEDA PEZZI SPECIALI'!$A$38:$F$59,5,FALSE)*1,0)+IFERROR(VLOOKUP($B5,'SCHEDA PEZZI SPECIALI'!$A$38:$F$59,6,FALSE)*1,0),IF(ISNUMBER(MATCH($B5,'SCHEDA ELETTROMECCANICA'!$A$5:$A$14,0)),IFERROR(VLOOKUP($B5,'SCHEDA ELETTROMECCANICA'!$A$5:$D$14,4,FALSE)*1,0),IF(ISNUMBER(MATCH($B5,'SCHEDA BULLONERIA'!$A$6:$A$36,0)),IFERROR(VLOOKUP($B5,'SCHEDA BULLONERIA'!$A$6:$D$36,4,FALSE)*1,0),""))))) | H5: ASSI DI ROTAZIONE 1303 | I5: 2
A6: 2 | B6: TTS.AR.001.7200.25 | C6: Asse lato motore 120x120x2,5 mm. lunghezza mt.7,20 | D6: Carpenteria metallica | E6: pz | F6: =IFERROR(VLOOKUP($B6,'SCHEDA STRUTTURA'!$A$17:$E$417,5,FALSE),"") | G6: =IF($B6="","",IF(ISNUMBER(MATCH($B6,'SCHEDA STRUTTURA'!$A$17:$A$147,0)),IFERROR(VLOOKUP($B6,'SCHEDA STRUTTURA'!$A$17:$G$147,6,FALSE)*1,0)+IFERROR(VLOOKUP($B6,'SCHEDA STRUTTURA'!$A$17:$G$147,7,FALSE)*1,0),IF(ISNUMBER(MATCH($B6,'SCHEDA PEZZI SPECIALI'!$A$38:$A$59,0)),IFERROR(VLOOKUP($B6,'SCHEDA PEZZI SPECIALI'!$A$38:$F$59,5,FALSE)*1,0)+IFERROR(VLOOKUP($B6,'SCHEDA PEZZI SPECIALI'!$A$38:$F$59,6,FALSE)*1,0),IF(ISNUMBER(MATCH($B6,'SCHEDA ELETTROMECCANICA'!$A$5:$A$14,0)),IFERROR(VLOOKUP($B6,'SCHEDA ELETTROMECCANICA'!$A$5:$D$14,4,FALSE)*1,0),IF(ISNUMBER(MATCH($B6,'SCHEDA BULLONERIA'!$A$6:$A$36,0)),IFERROR(VLOOKUP($B6,'SCHEDA BULLONERIA'!$A$6:$D$36,4,FALSE)*1,0),""))))) | H6: ASSI DI ROTAZIONE 1303 | I6: 1
A7: 3 | B7: TTS.AR.001.8250 | C7: Asse lato motore 120x120x3 mm. lunghezza mt.8,25 | D7: Carpenteria metallica | E7: pz | F7: =IFERROR(VLOOKUP($B7,'SCHEDA STRUTTURA'!$A$17:$E$417,5,FALSE),"") | G7: =IF($B7="","",IF(ISNUMBER(MATCH($B7,'SCHEDA STRUTTURA'!$A$17:$A$147,0)),IFERROR(VLOOKUP($B7,'SCHEDA STRUTTURA'!$A$17:$G$147,6,FALSE)*1,0)+IFERROR(VLOOKUP($B7,'SCHEDA STRUTTURA'!$A$17:$G$147,7,FALSE)*1,0),IF(ISNUMBER(MATCH($B7,'SCHEDA PEZZI SPECIALI'!$A$38:$A$59,0)),IFERROR(VLOOKUP($B7,'SCHEDA PEZZI SPECIALI'!$A$38:$F$59,5,FALSE)*1,0)+IFERROR(VLOOKUP($B7,'SCHEDA PEZZI SPECIALI'!$A$38:$F$59,6,FALSE)*1,0),IF(ISNUMBER(MATCH($B7,'SCHEDA ELETTROMECCANICA'!$A$5:$A$14,0)),IFERROR(VLOOKUP($B7,'SCHEDA ELETTROMECCANICA'!$A$5:$D$14,4,FALSE)*1,0),IF(ISNUMBER(MATCH($B7,'SCHEDA BULLONERIA'!$A$6:$A$36,0)),IFERROR(VLOOKUP($B7,'SCHEDA BULLONERIA'!$A$6:$D$36,4,FALSE)*1,0),""))))) | H7: ASSI DI ROTAZIONE 1303 | I7: 1
A8: 4 | B8: TTS.AR.001.8250.25 | C8: Asse lato motore 120x120x2,5 mm. lunghezza mt.8,25 | D8: Carpenteria metallica | E8: pz | F8: =IFERROR(VLOOKUP($B8,'SCHEDA STRUTTURA'!$A$17:$E$417,5,FALSE),"") | G8: =IF($B8="","",IF(ISNUMBER(MATCH($B8,'SCHEDA STRUTTURA'!$A$17:$A$147,0)),IFERROR(VLOOKUP($B8,'SCHEDA STRUTTURA'!$A$17:$G$147,6,FALSE)*1,0)+IFERROR(VLOOKUP($B8,'SCHEDA STRUTTURA'!$A$17:$G$147,7,FALSE)*1,0),IF(ISNUMBER(MATCH($B8,'SCHEDA PEZZI SPECIALI'!$A$38:$A$59,0)),IFERROR(VLOOKUP($B8,'SCHEDA PEZZI SPECIALI'!$A$38:$F$59,5,FALSE)*1,0)+IFERROR(VLOOKUP($B8,'SCHEDA PEZZI SPECIALI'!$A$38:$F$59,6,FALSE)*1,0),IF(ISNUMBER(MATCH($B8,'SCHEDA ELETTROMECCANICA'!$A$5:$A$14,0)),IFERROR(VLOOKUP($B8,'SCHEDA ELETTROMECCANICA'!$A$5:$D$14,4,FALSE)*1,0),IF(ISNUMBER(MATCH($B8,'SCHEDA BULLONERIA'!$A$6:$A$36,0)),IFERROR(VLOOKUP($B8,'SCHEDA BULLONERIA'!$A$6:$D$36,4,FALSE)*1,0),""))))) | H8: ASSI DI ROTAZIONE 1303 | I8: 1
A9: 5 | B9: TTS.AR.001.8700 | C9: Asse lato motore 120x120x3 mm. lunghezza mt.8,70 | D9: Carpenteria metallica | E9: pz | F9: =IFERROR(VLOOKUP($B9,'SCHEDA STRUTTURA'!$A$17:$E$417,5,FALSE),"") | G9: =IF($B9="","",IF(ISNUMBER(MATCH($B9,'SCHEDA STRUTTURA'!$A$17:$A$147,0)),IFERROR(VLOOKUP($B9,'SCHEDA STRUTTURA'!$A$17:$G$147,6,FALSE)*1,0)+IFERROR(VLOOKUP($B9,'SCHEDA STRUTTURA'!$A$17:$G$147,7,FALSE)*1,0),IF(ISNUMBER(MATCH($B9,'SCHEDA PEZZI SPECIALI'!$A$38:$A$59,0)),IFERROR(VLOOKUP($B9,'SCHEDA PEZZI SPECIALI'!$A$38:$F$59,5,FALSE)*1,0)+IFERROR(VLOOKUP($B9,'SCHEDA PEZZI SPECIALI'!$A$38:$F$59,6,FALSE)*1,0),IF(ISNUMBER(MATCH($B9,'SCHEDA ELETTROMECCANICA'!$A$5:$A$14,0)),IFERROR(VLOOKUP($B9,'SCHEDA ELETTROMECCANICA'!$A$5:$D$14,4,FALSE)*1,0),IF(ISNUMBER(MATCH($B9,'SCHEDA BULLONERIA'!$A$6:$A$36,0)),IFERROR(VLOOKUP($B9,'SCHEDA BULLONERIA'!$A$6:$D$36,4,FALSE)*1,0),""))))) | H9: ASSI DI ROTAZIONE 1303 | I9: 3
A10: 6 | B10: TTS.AR.001.8700.25 | C10: Asse lato motore 120x120x2,5 mm. lunghezza mt.8,70 | D10: Carpenteria metallica | E10: pz | F10: =IFERROR(VLOOKUP($B10,'SCHEDA STRUTTURA'!$A$17:$E$417,5,FALSE),"") | G10: =IF($B10="","",IF(ISNUMBER(MATCH($B10,'SCHEDA STRUTTURA'!$A$17:$A$147,0)),IFERROR(VLOOKUP($B10,'SCHEDA STRUTTURA'!$A$17:$G$147,6,FALSE)*1,0)+IFERROR(VLOOKUP($B10,'SCHEDA STRUTTURA'!$A$17:$G$147,7,FALSE)*1,0),IF(ISNUMBER(MATCH($B10,'SCHEDA PEZZI SPECIALI'!$A$38:$A$59,0)),IFERROR(VLOOKUP($B10,'SCHEDA PEZZI SPECIALI'!$A$38:$F$59,5,FALSE)*1,0)+IFERROR(VLOOKUP($B10,'SCHEDA PEZZI SPECIALI'!$A$38:$F$59,6,FALSE)*1,0),IF(ISNUMBER(MATCH($B10,'SCHEDA ELETTROMECCANICA'!$A$5:$A$14,0)),IFERROR(VLOOKUP($B10,'SCHEDA ELETTROMECCANICA'!$A$5:$D$14,4,FALSE)*1,0),IF(ISNUMBER(MATCH($B10,'SCHEDA BULLONERIA'!$A$6:$A$36,0)),IFERROR(VLOOKUP($B10,'SCHEDA BULLONERIA'!$A$6:$D$36,4,FALSE)*1,0),""))))) | H10: ASSI DI ROTAZIONE 1303 | I10: 1
A11: 7 | B11: TTS.AR.002.5000 | C11: Asse esterno 120x120x3 mm. lunghezza mt.5,00 | D11: Carpenteria metallica | E11: pz | F11: =IFERROR(VLOOKUP($B11,'SCHEDA STRUTTURA'!$A$17:$E$417,5,FALSE),"") | G11: =IF($B11="","",IF(ISNUMBER(MATCH($B11,'SCHEDA STRUTTURA'!$A$17:$A$147,0)),IFERROR(VLOOKUP($B11,'SCHEDA STRUTTURA'!$A$17:$G$147,6,FALSE)*1,0)+IFERROR(VLOOKUP($B11,'SCHEDA STRUTTURA'!$A$17:$G$147,7,FALSE)*1,0),IF(ISNUMBER(MATCH($B11,'SCHEDA PEZZI SPECIALI'!$A$38:$A$59,0)),IFERROR(VLOOKUP($B11,'SCHEDA PEZZI SPECIALI'!$A$38:$F$59,5,FALSE)*1,0)+IFERROR(VLOOKUP($B11,'SCHEDA PEZZI SPECIALI'!$A$38:$F$59,6,FALSE)*1,0),IF(ISNUMBER(MATCH($B11,'SCHEDA ELETTROMECCANICA'!$A$5:$A$14,0)),IFERROR(VLOOKUP($B11,'SCHEDA ELETTROMECCANICA'!$A$5:$D$14,4,FALSE)*1,0),IF(ISNUMBER(MATCH($B11,'SCHEDA BULLONERIA'!$A$6:$A$36,0)),IFERROR(VLOOKUP($B11,'SCHEDA BULLONERIA'!$A$6:$D$36,4,FALSE)*1,0),""))))) | H11: ASSI DI ROTAZIONE 1303 | I11: 1
A12: 8 | B12: TTS.AR.002.5000.25 | C12: Asse esterno 120x120x2,5 mm. lunghezza mt.5,00 | D12: Carpenteria metallica | E12: pz | F12: =IFERROR(VLOOKUP($B12,'SCHEDA STRUTTURA'!$A$17:$E$417,5,FALSE),"") | G12: =IF($B12="","",IF(ISNUMBER(MATCH($B12,'SCHEDA STRUTTURA'!$A$17:$A$147,0)),IFERROR(VLOOKUP($B12,'SCHEDA STRUTTURA'!$A$17:$G$147,6,FALSE)*1,0)+IFERROR(VLOOKUP($B12,'SCHEDA STRUTTURA'!$A$17:$G$147,7,FALSE)*1,0),IF(ISNUMBER(MATCH($B12,'SCHEDA PEZZI SPECIALI'!$A$38:$A$59,0)),IFERROR(VLOOKUP($B12,'SCHEDA PEZZI SPECIALI'!$A$38:$F$59,5,FALSE)*1,0)+IFERROR(VLOOKUP($B12,'SCHEDA PEZZI SPECIALI'!$A$38:$F$59,6,FALSE)*1,0),IF(ISNUMBER(MATCH($B12,'SCHEDA ELETTROMECCANICA'!$A$5:$A$14,0)),IFERROR(VLOOKUP($B12,'SCHEDA ELETTROMECCANICA'!$A$5:$D$14,4,FALSE)*1,0),IF(ISNUMBER(MATCH($B12,'SCHEDA BULLONERIA'!$A$6:$A$36,0)),IFERROR(VLOOKUP($B12,'SCHEDA BULLONERIA'!$A$6:$D$36,4,FALSE)*1,0),""))))) | H12: ASSI DI ROTAZIONE 1303 | I12: 1
A13: 9 | B13: TTS.AR.002.6150 | C13: Asse esterno 120x120x3 mm. lunghezza mt.6,15 | D13: Carpenteria metallica | E13: pz | F13: =IFERROR(VLOOKUP($B13,'SCHEDA STRUTTURA'!$A$17:$E$417,5,FALSE),"") | G13: =IF($B13="","",IF(ISNUMBER(MATCH($B13,'SCHEDA STRUTTURA'!$A$17:$A$147,0)),IFERROR(VLOOKUP($B13,'SCHEDA STRUTTURA'!$A$17:$G$147,6,FALSE)*1,0)+IFERROR(VLOOKUP($B13,'SCHEDA STRUTTURA'!$A$17:$G$147,7,FALSE)*1,0),IF(ISNUMBER(MATCH($B13,'SCHEDA PEZZI SPECIALI'!$A$38:$A$59,0)),IFERROR(VLOOKUP($B13,'SCHEDA PEZZI SPECIALI'!$A$38:$F$59,5,FALSE)*1,0)+IFERROR(VLOOKUP($B13,'SCHEDA PEZZI SPECIALI'!$A$38:$F$59,6,FALSE)*1,0),IF(ISNUMBER(MATCH($B13,'SCHEDA ELETTROMECCANICA'!$A$5:$A$14,0)),IFERROR(VLOOKUP($B13,'SCHEDA ELETTROMECCANICA'!$A$5:$D$14,4,FALSE)*1,0),IF(ISNUMBER(MATCH($B13,'SCHEDA BULLONERIA'!$A$6:$A$36,0)),IFERROR(VLOOKUP($B13,'SCHEDA BULLONERIA'!$A$6:$D$36,4,FALSE)*1,0),""))))) | H13: ASSI DI ROTAZIONE 1303 | I13: 1
A14: 10 | B14: TTS.AR.002.6150.25 | C14: Asse esterno 120x120x2,5 mm. lunghezza mt.6,15 | D14: Carpenteria metallica | E14: pz | F14: =IFERROR(VLOOKUP($B14,'SCHEDA STRUTTURA'!$A$17:$E$417,5,FALSE),"") | G14: =IF($B14="","",IF(ISNUMBER(MATCH($B14,'SCHEDA STRUTTURA'!$A$17:$A$147,0)),IFERROR(VLOOKUP($B14,'SCHEDA STRUTTURA'!$A$17:$G$147,6,FALSE)*1,0)+IFERROR(VLOOKUP($B14,'SCHEDA STRUTTURA'!$A$17:$G$147,7,FALSE)*1,0),IF(ISNUMBER(MATCH($B14,'SCHEDA PEZZI SPECIALI'!$A$38:$A$59,0)),IFERROR(VLOOKUP($B14,'SCHEDA PEZZI SPECIALI'!$A$38:$F$59,5,FALSE)*1,0)+IFERROR(VLOOKUP($B14,'SCHEDA PEZZI SPECIALI'!$A$38:$F$59,6,FALSE)*1,0),IF(ISNUMBER(MATCH($B14,'SCHEDA ELETTROMECCANICA'!$A$5:$A$14,0)),IFERROR(VLOOKUP($B14,'SCHEDA ELETTROMECCANICA'!$A$5:$D$14,4,FALSE)*1,0),IF(ISNUMBER(MATCH($B14,'SCHEDA BULLONERIA'!$A$6:$A$36,0)),IFERROR(VLOOKUP($B14,'SCHEDA BULLONERIA'!$A$6:$D$36,4,FALSE)*1,0),""))))) | H14: ASSI DI ROTAZIONE 1303 | I14: 1
A15: 11 | B15: TTS.AR.002.6300 | C15: Asse esterno 120x120x3 mm. lunghezza mt.6,30 | D15: Carpenteria metallica | E15: pz | F15: =IFERROR(VLOOKUP($B15,'SCHEDA STRUTTURA'!$A$17:$E$417,5,FALSE),"") | G15: =IF($B15="","",IF(ISNUMBER(MATCH($B15,'SCHEDA STRUTTURA'!$A$17:$A$147,0)),IFERROR(VLOOKUP($B15,'SCHEDA STRUTTURA'!$A$17:$G$147,6,FALSE)*1,0)+IFERROR(VLOOKUP($B15,'SCHEDA STRUTTURA'!$A$17:$G$147,7,FALSE)*1,0),IF(ISNUMBER(MATCH($B15,'SCHEDA PEZZI SPECIALI'!$A$38:$A$59,0)),IFERROR(VLOOKUP($B15,'SCHEDA PEZZI SPECIALI'!$A$38:$F$59,5,FALSE)*1,0)+IFERROR(VLOOKUP($B15,'SCHEDA PEZZI SPECIALI'!$A$38:$F$59,6,FALSE)*1,0),IF(ISNUMBER(MATCH($B15,'SCHEDA ELETTROMECCANICA'!$A$5:$A$14,0)),IFERROR(VLOOKUP($B15,'SCHEDA ELETTROMECCANICA'!$A$5:$D$14,4,FALSE)*1,0),IF(ISNUMBER(MATCH($B15,'SCHEDA BULLONERIA'!$A$6:$A$36,0)),IFERROR(VLOOKUP($B15,'SCHEDA BULLONERIA'!$A$6:$D$36,4,FALSE)*1,0),""))))) | H15: ASSI DI ROTAZIONE 1303 | I15: 1
A16: 12 | B16: TTS.AR.002.6300.25 | C16: Asse esterno 120x120x2,5 mm. lunghezza mt.6,30 | D16: Carpenteria metallica | E16: pz | F16: =IFERROR(VLOOKUP($B16,'SCHEDA STRUTTURA'!$A$17:$E$417,5,FALSE),"") | G16: =IF($B16="","",IF(ISNUMBER(MATCH($B16,'SCHEDA STRUTTURA'!$A$17:$A$147,0)),IFERROR(VLOOKUP($B16,'SCHEDA STRUTTURA'!$A$17:$G$147,6,FALSE)*1,0)+IFERROR(VLOOKUP($B16,'SCHEDA STRUTTURA'!$A$17:$G$147,7,FALSE)*1,0),IF(ISNUMBER(MATCH($B16,'SCHEDA PEZZI SPECIALI'!$A$38:$A$59,0)),IFERROR(VLOOKUP($B16,'SCHEDA PEZZI SPECIALI'!$A$38:$F$59,5,FALSE)*1,0)+IFERROR(VLOOKUP($B16,'SCHEDA PEZZI SPECIALI'!$A$38:$F$59,6,FALSE)*1,0),IF(ISNUMBER(MATCH($B16,'SCHEDA ELETTROMECCANICA'!$A$5:$A$14,0)),IFERROR(VLOOKUP($B16,'SCHEDA ELETTROMECCANICA'!$A$5:$D$14,4,FALSE)*1,0),IF(ISNUMBER(MATCH($B16,'SCHEDA BULLONERIA'!$A$6:$A$36,0)),IFERROR(VLOOKUP($B16,'SCHEDA BULLONERIA'!$A$6:$D$36,4,FALSE)*1,0),""))))) | H16: ASSI DI ROTAZIONE 1303 | I16: 1
... A26: 22 | B26: TTS.AR.004.4800.25 | C26: Asse esterno 120x120x2,5 mm. lunghezza mt.4,800 | D26: Carpenteria metallica | E26: pz | F26: =IFERROR(VLOOKUP($B26,'SCHEDA STRUTTURA'!$A$17:$E$417,5,FALSE),"") | G26: =IF($B26="","",IF(ISNUMBER(MATCH($B26,'SCHEDA STRUTTURA'!$A$17:$A$147,0)),IFERROR(VLOOKUP($B26,'SCHEDA STRUTTURA'!$A$17:$G$147,6,FALSE)*1,0)+IFERROR(VLOOKUP($B26,'SCHEDA STRUTTURA'!$A$17:$G$147,7,FALSE)*1,0),IF(ISNUMBER(MATCH($B26,'SCHEDA PEZZI SPECIALI'!$A$38:$A$59,0)),IFERROR(VLOOKUP($B26,'SCHEDA PEZZI SPECIALI'!$A$38:$F$59,5,FALSE)*1,0)+IFERROR(VLOOKUP($B26,'SCHEDA PEZZI SPECIALI'!$A$38:$F$59,6,FALSE)*1,0),IF(ISNUMBER(MATCH($B26,'SCHEDA ELETTROMECCANICA'!$A$5:$A$14,0)),IFERROR(VLOOKUP($B26,'SCHEDA ELETTROMECCANICA'!$A$5:$D$14,4,FALSE)*1,0),IF(ISNUMBER(MATCH($B26,'SCHEDA BULLONERIA'!$A$6:$A$36,0)),IFERROR(VLOOKUP($B26,'SCHEDA BULLONERIA'!$A$6:$D$36,4,FALSE)*1,0),""))))) | H26: ASSI DI ROTAZIONE 1303 | I26: 1
