Workbook

Sheet SCHEDA STRUTTURA
A1: SCHEDA STRUTTURA — parametri peso e costo di acquisto/zincatura (compilare kg/m, % zincatura, €/kg acquisto e €/kg zincatura)
A2: Per ogni profilo: peso teorico al metro, maggiorazione peso per zincatura (%), costo di acquisto al kg e costo di zincatura al kg. Il peso finale include la maggiorazione. Nell'elenco: Costo acquisto (€) = Peso elemento × €/kg acquisto; Costo zincatura (€) = Peso elemento × magg. zincatura % × €/kg zincatura, solo se la maggiorazione è presente.
A4: Profilo | B4: Peso teorico (kg/m) | C4: Magg. zincatura % | D4: Peso finale (kg/m) | E4: Costo acquisto (€/kg) | F4: Costo zincatura (€/kg)
A5: IPE 140 | D5: =IF(ISNUMBER($B5),$B5*(1+IF(ISNUMBER($C5),$C5,0)),"")
A6: IPEA 140 | D6: =IF(ISNUMBER($B6),$B6*(1+IF(ISNUMBER($C6),$C6,0)),"")
A7: ASSE 120x120x3 | B7: 11.8 | D7: =IF(ISNUMBER($B7),$B7*(1+IF(ISNUMBER($C7),$C7,0)),"")
A8: ASSE 120x120x2,5 | B8: 9.2 | D8: =IF(ISNUMBER($B8),$B8*(1+IF(ISNUMBER($C8),$C8,0)),"")
A12: Codice | B12: Descrizione | C12: Profilo | D12: Lunghezza (m) | E12: Peso elemento (kg) | F12: Costo acquisto (€) | G12: Costo zincatura (€)
A13: TTS.PC.001.IPE140.23 | B13: Pilastro cuscinetto trave IPE 140 mt.2,30 | C13: IPE 140 | D13: 2.3 | E13: =IF(AND(ISNUMBER($D13),ISNUMBER(VLOOKUP($C13,$A$5:$F$11,4,FALSE))),$D13*VLOOKUP($C13,$A$5:$F$11,4,FALSE),"") | F13: =IF(AND(ISNUMBER($E13),ISNUMBER(VLOOKUP($C13,$A$5:$F$11,5,FALSE))),$E13*VLOOKUP($C13,$A$5:$F$11,5,FALSE),"") | G13: =IF(AND(ISNUMBER($E13),ISNUMBER(VLOOKUP($C13,$A$5:$F$11,3,FALSE)),VLOOKUP($C13,$A$5:$F$11,3,FALSE)>0,ISNUMBER(VLOOKUP($C13,$A$5:$F$11,6,FALSE))),$E13*VLOOKUP($C13,$A$5:$F$11,3,FALSE)*VLOOKUP($C13,$A$5:$F$11,6,FALSE),"")
A14: TTS.PC.001.IPE140.23.FI | B14: Pilastro cuscinetto trave ipe140 x mt. 2,30 con foratura alloggiamento inverter | C14: IPE 140 | D14: 2.3 | E14: =IF(AND(ISNUMBER($D14),ISNUMBER(VLOOKUP($C14,$A$5:$F$11,4,FALSE))),$D14*VLOOKUP($C14,$A$5:$F$11,4,FALSE),"") | F14: =IF(AND(ISNUMBER($E14),ISNUMBER(VLOOKUP($C14,$A$5:$F$11,5,FALSE))),$E14*VLOOKUP($C14,$A$5:$F$11,5,FALSE),"") | G14: =IF(AND(ISNUMBER($E14),ISNUMBER(VLOOKUP($C14,$A$5:$F$11,3,FALSE)),VLOOKUP($C14,$A$5:$F$11,3,FALSE)>0,ISNUMBER(VLOOKUP($C14,$A$5:$F$11,6,FALSE))),$E14*VLOOKUP($C14,$A$5:$F$11,3,FALSE)*VLOOKUP($C14,$A$5:$F$11,6,FALSE),"")
A15: TTS.PC.001.IPE140.23.FQA | B15: Pilastro cuscinetto trave ipe140 x mt. 2,30 con foratura alloggiamento quadro area | C15: IPE 140 | D15: 2.3 | E15: =IF(AND(ISNUMBER($D15),ISNUMBER(VLOOKUP($C15,$A$5:$F$11,4,FALSE))),$D15*VLOOKUP($C15,$A$5:$F$11,4,FALSE),"") | F15: =IF(AND(ISNUMBER($E15),ISNUMBER(VLOOKUP($C15,$A$5:$F$11,5,FALSE))),$E15*VLOOKUP($C15,$A$5:$F$11,5,FALSE),"") | G15: =IF(AND(ISNUMBER($E15),ISNUMBER(VLOOKUP($C15,$A$5:$F$11,3,FALSE)),VLOOKUP($C15,$A$5:$F$11,3,FALSE)>0,ISNUMBER(VLOOKUP($C15,$A$5:$F$11,6,FALSE))),$E15*VLOOKUP($C15,$A$5:$F$11,3,FALSE)*VLOOKUP($C15,$A$5:$F$11,6,FALSE),"")
A16: TTS.PC.001.IPE140.28 | B16: Pilastro cuscinetto trave IPE 140 mt.2,80 | C16: IPE 140 | D16: 2.8 | E16: =IF(AND(ISNUMBER($D16),ISNUMBER(VLOOKUP($C16,$A$5:$F$11,4,FALSE))),$D16*VLOOKUP($C16,$A$5:$F$11,4,FALSE),"") | F16: =IF(AND(ISNUMBER($E16),ISNUMBER(VLOOKUP($C16,$A$5:$F$11,5,FALSE))),$E16*VLOOKUP($C16,$A$5:$F$11,5,FALSE),"") | G16: =IF(AND(ISNUMBER($E16),ISNUMBER(VLOOKUP($C16,$A$5:$F$11,3,FALSE)),VLOOKUP($C16,$A$5:$F$11,3,FALSE)>0,ISNUMBER(VLOOKUP($C16,$A$5:$F$11,6,FALSE))),$E16*VLOOKUP($C16,$A$5:$F$11,3,FALSE)*VLOOKUP($C16,$A$5:$F$11,6,FALSE),"")
A17: TTS.PC.001.IPE140.29 | B17: Pilastro cuscinetto trave IPE 140 mt.2,90 | C17: IPE 140 | D17: 2.9 | E17: =IF(AND(ISNUMBER($D17),ISNUMBER(VLOOKUP($C17,$A$5:$F$11,4,FALSE))),$D17*VLOOKUP($C17,$A$5:$F$11,4,FALSE),"") | F17: =IF(AND(ISNUMBER($E17),ISNUMBER(VLOOKUP($C17,$A$5:$F$11,5,FALSE))),$E17*VLOOKUP($C17,$A$5:$F$11,5,FALSE),"") | G17: =IF(AND(ISNUMBER($E17),ISNUMBER(VLOOKUP($C17,$A$5:$F$11,3,FALSE)),VLOOKUP($C17,$A$5:$F$11,3,FALSE)>0,ISNUMBER(VLOOKUP($C17,$A$5:$F$11,6,FALSE))),$E17*VLOOKUP($C17,$A$5:$F$11,3,FALSE)*VLOOKUP($C17,$A$5:$F$11,6,FALSE),"")
A18: TTS.PC.001.IPE140.30 | B18: Pilastro cuscinetto trave IPE 140 mt.3,00 | C18: IPE 140 | D18: 3 | E18: =IF(AND(ISNUMBER($D18),ISNUMBER(VLOOKUP($C18,$A$5:$F$11,4,FALSE))),$D18*VLOOKUP($C18,$A$5:$F$11,4,FALSE),"") | F18: =IF(AND(ISNUMBER($E18),ISNUMBER(VLOOKUP($C18,$A$5:$F$11,5,FALSE))),$E18*VLOOKUP($C18,$A$5:$F$11,5,FALSE),"") | G18: =IF(AND(ISNUMBER($E18),ISNUMBER(VLOOKUP($C18,$A$5:$F$11,3,FALSE)),VLOOKUP($C18,$A$5:$F$11,3,FALSE)>0,ISNUMBER(VLOOKUP($C18,$A$5:$F$11,6,FALSE))),$E18*VLOOKUP($C18,$A$5:$F$11,3,FALSE)*VLOOKUP($C18,$A$5:$F$11,6,FALSE),"")
A19: TTS.PC.001.IPE140.31 | B19: Pilastro cuscinetto trave IPE 140 mt.3,10 | C19: IPE 140 | D19: 3.1 | E19: =IF(AND(ISNUMBER($D19),ISNUMBER(VLOOKUP($C19,$A$5:$F$11,4,FALSE))),$D19*VLOOKUP($C19,$A$5:$F$11,4,FALSE),"") | F19: =IF(AND(ISNUMBER($E19),ISNUMBER(VLOOKUP($C19,$A$5:$F$11,5,FALSE))),$E19*VLOOKUP($C19,$A$5:$F$11,5,FALSE),"") | G19: =IF(AND(ISNUMBER($E19),ISNUMBER(VLOOKUP($C19,$A$5:$F$11,3,FALSE)),VLOOKUP($C19,$A$5:$F$11,3,FALSE)>0,ISNUMBER(VLOOKUP($C19,$A$5:$F$11,6,FALSE))),$E19*VLOOKUP($C19,$A$5:$F$11,3,FALSE)*VLOOKUP($C19,$A$5:$F$11,6,FALSE),"")
A20: TTS.PC.001.IPE140.32 | B20: Pilastro cuscinetto trave IPE 140 mt.3,20 | C20: IPE 140 | D20: 3.2 | E20: =IF(AND(ISNUMBER($D20),ISNUMBER(VLOOKUP($C20,$A$5:$F$11,4,FALSE))),$D20*VLOOKUP($C20,$A$5:$F$11,4,FALSE),"") | F20: =IF(AND(ISNUMBER($E20),ISNUMBER(VLOOKUP($C20,$A$5:$F$11,5,FALSE))),$E20*VLOOKUP($C20,$A$5:$F$11,5,FALSE),"") | G20: =IF(AND(ISNUMBER($E20),ISNUMBER(VLOOKUP($C20,$A$5:$F$11,3,FALSE)),VLOOKUP($C20,$A$5:$F$11,3,FALSE)>0,ISNUMBER(VLOOKUP($C20,$A$5:$F$11,6,FALSE))),$E20*VLOOKUP($C20,$A$5:$F$11,3,FALSE)*VLOOKUP($C20,$A$5:$F$11,6,FALSE),"")
A21: TTS.PC.001.IPE140.33 | B21: Pilastro cuscinetto trave IPE 140 mt.3,30 | C21: IPE 140 | D21: 3.3 | E21: =IF(AND(ISNUMBER($D21),ISNUMBER(VLOOKUP($C21,$A$5:$F$11,4,FALSE))),$D21*VLOOKUP($C21,$A$5:$F$11,4,FALSE),"") | F21: =IF(AND(ISNUMBER($E21),ISNUMBER(VLOOKUP($C21,$A$5:$F$11,5,FALSE))),$E21*VLOOKUP($C21,$A$5:$F$11,5,FALSE),"") | G21: =IF(AND(ISNUMBER($E21),ISNUMBER(VLOOKUP($C21,$A$5:$F$11,3,FALSE)),VLOOKUP($C21,$A$5:$F$11,3,FALSE)>0,ISNUMBER(VLOOKUP($C21,$A$5:$F$11,6,FALSE))),$E21*VLOOKUP($C21,$A$5:$F$11,3,FALSE)*VLOOKUP($C21,$A$5:$F$11,6,FALSE),"")
A22: TTS.PC.001.IPE140.34 | B22: Pilastro cuscinetto trave IPE 140 mt.3,40 | C22: IPE 140 | D22: 3.4 | E22: =IF(AND(ISNUMBER($D22),ISNUMBER(VLOOKUP($C22,$A$5:$F$11,4,FALSE))),$D22*VLOOKUP($C22,$A$5:$F$11,4,FALSE),"") | F22: =IF(AND(ISNUMBER($E22),ISNUMBER(VLOOKUP($C22,$A$5:$F$11,5,FALSE))),$E22*VLOOKUP($C22,$A$5:$F$11,5,FALSE),"") | G22: =IF(AND(ISNUMBER($E22),ISNUMBER(VLOOKUP($C22,$A$5:$F$11,3,FALSE)),VLOOKUP($C22,$A$5:$F$11,3,FALSE)>0,ISNUMBER(VLOOKUP($C22,$A$5:$F$11,6,FALSE))),$E22*VLOOKUP($C22,$A$5:$F$11,3,FALSE)*VLOOKUP($C22,$A$5:$F$11,6,FALSE),"")
A23: TTS.PC.001.IPE140.35 | B23: Pilastro cuscinetto trave IPE 140 mt.3,50 | C23: IPE 140 | D23: 3.5 | E23: =IF(AND(ISNUMBER($D23),ISNUMBER(VLOOKUP($C23,$A$5:$F$11,4,FALSE))),$D23*VLOOKUP($C23,$A$5:$F$11,4,FALSE),"") | F23: =IF(AND(ISNUMBER($E23),ISNUMBER(VLOOKUP($C23,$A$5:$F$11,5,FALSE))),$E23*VLOOKUP($C23,$A$5:$F$11,5,FALSE),"") | G23: =IF(AND(ISNUMBER($E23),ISNUMBER(VLOOKUP($C23,$A$5:$F$11,3,FALSE)),VLOOKUP($C23,$A$5:$F$11,3,FALSE)>0,ISNUMBER(VLOOKUP($C23,$A$5:$F$11,6,FALSE))),$E23*VLOOKUP($C23,$A$5:$F$11,3,FALSE)*VLOOKUP($C23,$A$5:$F$11,6,FALSE),"")
A24: TTS.PC.001.IPE140.36 | B24: Pilastro cuscinetto trave IPE 140 mt.3,60 | C24: IPE 140 | D24: 3.6 | E24: =IF(AND(ISNUMBER($D24),ISNUMBER(VLOOKUP($C24,$A$5:$F$11,4,FALSE))),$D24*VLOOKUP($C24,$A$5:$F$11,4,FALSE),"") | F24: =IF(AND(ISNUMBER($E24),ISNUMBER(VLOOKUP($C24,$A$5:$F$11,5,FALSE))),$E24*VLOOKUP($C24,$A$5:$F$11,5,FALSE),"") | G24: =IF(AND(ISNUMBER($E24),ISNUMBER(VLOOKUP($C24,$A$5:$F$11,3,FALSE)),VLOOKUP($C24,$A$5:$F$11,3,FALSE)>0,ISNUMBER(VLOOKUP($C24,$A$5:$F$11,6,FALSE))),$E24*VLOOKUP($C24,$A$5:$F$11,3,FALSE)*VLOOKUP($C24,$A$5:$F$11,6,FALSE),"")
... A138: TTS.AR.004.4800.25 | B138: Asse esterno 120x120x2,5 mm. lunghezza mt.4,800 | C138: ASSE 120x120x2,5 | D138: 4.8 | E138: =IF(AND(ISNUMBER($D138),ISNUMBER(VLOOKUP($C138,$A$5:$F$11,4,FALSE))),$D138*VLOOKUP($C138,$A$5:$F$11,4,FALSE),"") | F138: =IF(AND(ISNUMBER($E138),ISNUMBER(VLOOKUP($C138,$A$5:$F$11,5,FALSE))),$E138*VLOOKUP($C138,$A$5:$F$11,5,FALSE),"") | G138: =IF(AND(ISNUMBER($E138),ISNUMBER(VLOOKUP($C138,$A$5:$F$11,3,FALSE)),VLOOKUP($C138,$A$5:$F$11,3,FALSE)>0,ISNUMBER(VLOOKUP($C138,$A$5:$F$11,6,FALSE))),$E138*VLOOKUP($C138,$A$5:$F$11,3,FALSE)*VLOOKUP($C138,$A$5:$F$11,6,FALSE),"")

Sheet LISTINO
A1: LISTINO COMPONENTI — Tracker TTS moduli 1303 (rev. 5)
A2: Elenco unico di tutti i componenti presenti nella distinta materiali. Compilare la colonna 'Prezzo unitario' per ottenere un listino valorizzato.
A4: N° | B4: Codice | C4: Descrizione | D4: Categoria | E4: U.M. | F4: Peso elemento (kg) | G4: Prezzo unitario € | H4: Presente nei kit / assiemi | I4: N° righe distinta
A5: 1 | B5: TTS.AR.001.7200 | C5: Asse lato motore 120x120x3 mm. lunghezza mt.7,20 | D5: Carpenteria metallica | E5: pz | F5: =IFERROR(VLOOKUP($B5,'SCHEDA STRUTTURA'!$A$13:$E$413,5,FALSE),"") | H5: ASSI DI ROTAZIONE 1303 | I5: 2
A6: 2 | B6: TTS.AR.001.7200.25 | C6: Asse lato motore 120x120x2,5 mm. lunghezza mt.7,20 | D6: Carpenteria metallica | E6: pz | F6: =IFERROR(VLOOKUP($B6,'SCHEDA STRUTTURA'!$A$13:$E$413,5,FALSE),"") | H6: ASSI DI ROTAZIONE 1303 | I6: 1
A7: 3 | B7: TTS.AR.001.8250 | C7: Asse lato motore 120x120x3 mm. lunghezza mt.8,25 | D7: Carpenteria metallica | E7: pz | F7: =IFERROR(VLOOKUP($B7,'SCHEDA STRUTTURA'!$A$13:$E$413,5,FALSE),"") | H7: ASSI DI ROTAZIONE 1303 | I7: 1
A8: 4 | B8: TTS.AR.001.8250.25 | C8: Asse lato motore 120x120x2,5 mm. lunghezza mt.8,25 | D8: Carpenteria metallica | E8: pz | F8: =IFERROR(VLOOKUP($B8,'SCHEDA STRUTTURA'!$A$13:$E$413,5,FALSE),"") | H8: ASSI DI ROTAZIONE 1303 | I8: 1
A9: 5 | B9: TTS.AR.001.8700 | C9: Asse lato motore 120x120x3 mm. lunghezza mt.8,70 | D9: Carpenteria metallica | E9: pz | F9: =IFERROR(VLOOKUP($B9,'SCHEDA STRUTTURA'!$A$13:$E$413,5,FALSE),"") | H9: ASSI DI ROTAZIONE 1303 | I9: 3
A10: 6 | B10: TTS.AR.001.8700.25 | C10: Asse lato motore 120x120x2,5 mm. lunghezza mt.8,70 | D10: Carpenteria metallica | E10: pz | F10: =IFERROR(VLOOKUP($B10,'SCHEDA STRUTTURA'!$A$13:$E$413,5,FALSE),"") | H10: ASSI DI ROTAZIONE 1303 | I10: 1
A11: 7 | B11: TTS.AR.002.5000 | C11: Asse esterno 120x120x3 mm. lunghezza mt.5,00 | D11: Carpenteria metallica | E11: pz | F11: =IFERROR(VLOOKUP($B11,'SCHEDA STRUTTURA'!$A$13:$E$413,5,FALSE),"") | H11: ASSI DI ROTAZIONE 1303 | I11: 1
A12: 8 | B12: TTS.AR.002.5000.25 | C12: Asse esterno 120x120x2,5 mm. lunghezza mt.5,00 | D12: Carpenteria metallica | E12: pz | F12: =IFERROR(VLOOKUP($B12,'SCHEDA STRUTTURA'!$A$13:$E$413,5,FALSE),"") | H12: ASSI DI ROTAZIONE 1303 | I12: 1
A13: 9 | B13: TTS.AR.002.6150 | C13: Asse esterno 120x120x3 mm. lunghezza mt.6,15 | D13: Carpenteria metallica | E13: pz | F13: =IFERROR(VLOOKUP($B13,'SCHEDA STRUTTURA'!$A$13:$E$413,5,FALSE),"") | H13: ASSI DI ROTAZIONE 1303 | I13: 1
A14: 10 | B14: TTS.AR.002.6150.25 | C14: Asse esterno 120x120x2,5 mm. lunghezza mt.6,15 | D14: Carpenteria metallica | E14: pz | F14: =IFERROR(VLOOKUP($B14,'SCHEDA STRUTTURA'!$A$13:$E$413,5,FALSE),"") | H14: ASSI DI ROTAZIONE 1303 | I14: 1
A15: 11 | B15: TTS.AR.002.6300 | C15: Asse esterno 120x120x3 mm. lunghezza mt.6,30 | D15: Carpenteria metallica | E15: pz | F15: =IFERROR(VLOOKUP($B15,'SCHEDA STRUTTURA'!$A$13:$E$413,5,FALSE),"") | H15: ASSI DI ROTAZIONE 1303 | I15: 1
A16: 12 | B16: TTS.AR.002.6300.25 | C16: Asse esterno 120x120x2,5 mm. lunghezza mt.6,30 | D16: Carpenteria metallica | E16: pz | F16: =IFERROR(VLOOKUP($B16,'SCHEDA STRUTTURA'!$A$13:$E$413,5,FALSE),"") | H16: ASSI DI ROTAZIONE 1303 | I16: 1
... A26: 22 | B26: TTS.AR.004.4800.25 | C26: Asse esterno 120x120x2,5 mm. lunghezza mt.4,800 | D26: Carpenteria metallica | E26: pz | F26: =IFERROR(VLOOKUP($B26,'SCHEDA STRUTTURA'!$A$13:$E$413,5,FALSE),"") | H26: ASSI DI ROTAZIONE 1303 | I26: 1
A27: 23 | B27: TTS.AR.201 | C27: Kit giunzione asse di collegamento | D27: Carpenteria metallica | E27: pz | H27: ASSI DI ROTAZIONE 1303 | I27: 5
A28: 24 | B28: TTS.AR.2011 | C28: Gaffa giunzione asse | D28: Carpenteria metallica | E28: pz | H28: ASSI DI ROTAZIONE 1303 | I28: 5
A29: 25 | B29: TTS.AR.3011 | C29: Supporto a L superiore omega | D29: Carpenteria metallica | E29: pz | H29: KIT OMEGA+pannelli | I29: 1
A30: 26 | B30: TTS.AR.3012 | C30: Supporto a V inferiore omega | D30: Carpenteria metallica | E30: pz | H30: KIT OMEGA+pannelli | I30: 1
A31: 27 | B31: TTS.AR.3013 | C31: Gaffa sotto omega | D31: Carpenteria metallica | E31: pz | H31: KIT OMEGA+pannelli | I31: 1
A32: 28 | B32: TTS.AR.3014 | C32: Omega supporto pannello | D32: Carpenteria metallica | E32: pz | H32: KIT OMEGA+pannelli | I32: 1
A33: 29 | B33: TTS.AR.3014.18 | C33: Omega supporto pannello mm1,8 | D33: Carpenteria metallica | E33: pz | H33: KIT OMEGA+pannelli | I33: 1
A34: 30 | B34: TTS.AR.4011 | C34: Supporto superiore inclinometro | D34: Carpenteria metallica | E34: pz | H34: KIT INCLINOMETRO | I34: 1
A35: 31 | B35: TTS.AR.4012 | C35: Supporto inferiore inclinometro | D35: Carpenteria metallica | E35: pz | H35: KIT INCLINOMETRO | I35: 1
A36: 32 | B36: TTS.AR.5011 | C36: Piastra ad L supporto fine corsa | D36: Carpenteria metallica | E36: pz | H36: KIT FINE CORSA | I36: 1
A37: 33 | B37: TTS.AR.5012 | C37: Leva battente sensore fine corsa | D37: Carpenteria metallica | E37: pz | H37: KIT FINE CORSA | I37: 1
A38: 34 | B38: TTS.PC.001.IPE140.23 | C38: Pilastro cuscinetto trave IPE 140 mt.2,30 | D38: Carpenteria metallica | E38: pz | F38: =IFERROR(VLOOKUP($B38,'SCHEDA STRUTTURA'!$A$13:$E$413,5,FALSE),"") | H38: PILASTRO CUSCINETTO | I38: 1
A39: 35 | B39: TTS.PC.001.IPEA140.23 | C39: Pilastro cuscinetto trave IPEA 140 mt.2,30 (alleggerita) | D39: Carpenteria metallica | E39: pz | F39: =IFERROR(VLOOKUP($B39,'SCHEDA STRUTTURA'!$A$13:$E$413,5,FALSE),"") | H39: PILASTRO CUSCINETTO | I39: 1
A40: 36 | B40: TTS.PC.001.IPE140.28 | C40: Pilastro cuscinetto trave IPE 140 mt.2,80 | D40: Carpenteria metallica | E40: pz | F40: =IFERROR(VLOOKUP($B40,'SCHEDA STRUTTURA'!$A$13:$E$413,5,FALSE),"") | H40: PILASTRO CUSCINETTO | I40: 1
A41: 37 | B41: TTS.PC.001.IPEA140.28 | C41: Pilastro cuscinetto trave IPEA 140 mt.2,80 (alleggerita) | D41: Carpenteria metallica | E41: pz | F41: =IFERROR(VLOOKUP($B41,'SCHEDA STRUTTURA'!$A$13:$E$413,5,FALSE),"") | H41: PILASTRO CUSCINETTO | I41: 1
A42: 38 | B42: TTS.PC.001.IPE140.29 | C42: Pilastro cuscinetto trave IPE 140 mt.2,90 | D42: Carpenteria metallica | E42: pz | F42: =IFERROR(VLOOKUP($B42,'SCHEDA STRUTTURA'!$A$13:$E$413,5,FALSE),"") | H42: PILASTRO CUSCINETTO | I42: 1
A43: 39 | B43: TTS.PC.001.IPEA140.29 | C43: Pilastro cuscinetto trave IPEA 140 mt.2,90 (alleggerita) | D43: Carpenteria metallica | E43: pz | F43: =IFERROR(VLOOKUP($B43,'SCHEDA STRUTTURA'!$A$13:$E$413,5,FALSE),"") | H43: PILASTRO CUSCINETTO | I43: 1
A44: 40 | B44: TTS.PC.001.IPE140.30 | C44: Pilastro cuscinetto trave IPE 140 mt.3,00 | D44: Carpenteria metallica | E44: pz | F44: =IFERROR(VLOOKUP($B44,'SCHEDA STRUTTURA'!$A$13:$E$413,5,FALSE),"") | H44: PILASTRO CUSCINETTO | I44: 1
A45: 41 | B45: TTS.PC.001.IPEA140.30 | C45: Pilastro cuscinetto trave IPEA 140 mt.3,00 (alleggerita) | D45: Carpenteria metallica | E45: pz | F45: =IFERROR(VLOOKUP($B45,'SCHEDA STRUTTURA'!$A$13:$E$413,5,FALSE),"") | H45: PILASTRO CUSCINETTO | I45: 1
A46: 42 | B46: TTS.PC.001.IPE140.31 | C46: Pilastro cuscinetto trave IPE 140 mt.3,10 | D46: Carpenteria metallica | E46: pz | F46: =IFERROR(VLOOKUP($B46,'SCHEDA STRUTTURA'!$A$13:$E$413,5,FALSE),"") | H46: PILASTRO CUSCINETTO | I46: 1
A47: 43 | B47: TTS.PC.001.IPEA140.31 | C47: Pilastro cuscinetto trave IPEA 140 mt.3,10 (alleggerita) | D47: Carpenteria metallica | E47: pz | F47: =IFERROR(VLOOKUP($B47,'SCHEDA STRUTTURA'!$A$13:$E$413,5,FALSE),"") | H47: PILASTRO CUSCINETTO | I47: 1
A48: 44 | B48: TTS.PC.001.IPE140.32 | C48: Pilastro cuscinetto trave IPE 140 mt.3,20 | D48: Carpenteria metallica | E48: pz | F48: =IFERROR(VLOOKUP($B48,'SCHEDA STRUTTURA'!$A$13:$E$413,5,FALSE),"") | H48: PILASTRO CUSCINETTO | I48: 1
A49: 45 | B49: TTS.PC.001.IPEA140.32 | C49: Pilastro cuscinetto trave IPEA 140 mt.3,20 (alleggerita) | D49: Carpenteria metallica | E49: pz | F49: =IFERROR(VLOOKUP($B49,'SCHEDA STRUTTURA'!$A$13:$E$413,5,FALSE),"") | H49: PILASTRO CUSCINETTO | I49: 1
... A79: 75 | B79: TTS.PC.001.IPEA140.23.FQA | C79: Pilastro cuscinetto trave ipea140 x mt. 2,30 con foratura alloggiamento quadro area (alleggerita) | D79: Carpenteria metallica | E79: pz | F79: =IFERROR(VLOOKUP($B79,'SCHEDA STRUTTURA'!$A$13:$E$413,5,FALSE),"") | H79: kit quadri area | I79: 1
...

Sheet DISTINTA COMPLETA
A1: Assieme / Kit | B1: Sezione | C1: Pos. | D1: Codice | E1: Descrizione | F1: Categoria | G1: Q.tà | H1: Q.tà 12 mod | I1: Q.tà 18 mod | J1: Q.tà 20 mod | K1: Q.tà 22 mod | L1: Q.tà 36 mod | M1: Q.tà 40 mod | N1: Già caricato altrove | O1: U.M. | P1: Peso elemento (kg) | Q1: Prezzo unitario € | R1: Importo €
A2: PILASTRO MOTORE | C2: 1 | D2: TTS.PF.001.IPE140.30 | E2: Pilastro fondazione trave IPE140 mt.3,00 | F2: Carpenteria metallica | G2: 1 | O2: pz | Q2: =IFERROR(VLOOKUP($D2,LISTINO!$B:$I,6,FALSE),IFERROR(VLOOKUP($E2,LISTINO!$C:$I,5,FALSE),"")) | R2: =IF(AND(ISNUMBER(G2),ISNUMBER(Q2)),G2*Q2,"")
A3: PILASTRO MOTORE | C3: 1 | D3: TTS.PF.001.IPEA140.30 | E3: Pilastro fondazione trave IPEA140 mt.3,00 (alleggerita) | F3: Carpenteria metallica | G3: 0 | O3: pz | Q3: =IFERROR(VLOOKUP($D3,LISTINO!$B:$I,6,FALSE),IFERROR(VLOOKUP($E3,LISTINO!$C:$I,5,FALSE),"")) | R3: =IF(AND(ISNUMBER(G3),ISNUMBER(Q3)),G3*Q3,"")
A4: PILASTRO MOTORE | C4: 1 | D4: TTS.PF.001.IPE140.26 | E4: Pilastro fondazione trave IPE140 mt.2,60 | F4: Carpenteria metallica | G4: 0 | O4: pz | Q4: =IFERROR(VLOOKUP($D4,LISTINO!$B:$I,6,FALSE),IFERROR(VLOOKUP($E4,LISTINO!$C:$I,5,FALSE),"")) | R4: =IF(AND(ISNUMBER(G4),ISNUMBER(Q4)),G4*Q4,"")
A5: PILASTRO MOTORE | C5: 1 | D5: TTS.PF.001.IPEA140.26 | E5: Pilastro fondazione trave IPEA140 mt.2,60 (alleggerita) | F5: Carpenteria metallica | G5: 0 | O5: pz | Q5: =IFERROR(VLOOKUP($D5,LISTINO!$B:$I,6,FALSE),IFERROR(VLOOKUP($E5,LISTINO!$C:$I,5,FALSE),"")) | R5: =IF(AND(ISNUMBER(G5),ISNUMBER(Q5)),G5*Q5,"")
A6: PILASTRO MOTORE | C6: 1 | D6: TTS.PF.001.IPE140.27 | E6: Pilastro fondazione trave IPE140 mt.2,70 | F6: Carpenteria metallica | G6: 0 | O6: pz | Q6: =IFERROR(VLOOKUP($D6,LISTINO!$B:$I,6,FALSE),IFERROR(VLOOKUP($E6,LISTINO!$C:$I,5,FALSE),"")) | R6: =IF(AND(ISNUMBER(G6),ISNUMBER(Q6)),G6*Q6,"")
A7: PILASTRO MOTORE | C7: 1 | D7: TTS.PF.001.IPEA140.27 | E7: Pilastro fondazione trave IPEA140 mt.2,70 (alleggerita) | F7: Carpenteria metallica | G7: 0 | O7: pz | Q7: =IFERROR(VLOOKUP($D7,LISTINO!$B:$I,6,FALSE),IFERROR(VLOOKUP($E7,LISTINO!$C:$I,5,FALSE),"")) | R7: =IF(AND(ISNUMBER(G7),ISNUMBER(Q7)),G7*Q7,"")
A8: PILASTRO MOTORE | C8: 1 | D8: TTS.PF.001.IPE140.28 | E8: Pilastro fondazione trave IPE140 mt.2,80 | F8: Carpenteria metallica | G8: 0 | O8: pz | Q8: =IFERROR(VLOOKUP($D8,LISTINO!$B:$I,6,FALSE),IFERROR(VLOOKUP($E8,LISTINO!$C:$I,5,FALSE),"")) | R8: =IF(AND(ISNUMBER(G8),ISNUMBER(Q8)),G8*Q8,"")
A9: PILASTRO MOTORE | C9: 1 | D9: TTS.PF.001.IPEA140.28 | E9: Pilastro fondazione trave IPEA140 mt.2,80 (alleggerita) | F9: Carpenteria metallica | G9: 0 | O9: pz | Q9: =IFERROR(VLOOKUP($D9,LISTINO!$B:$I,6,FALSE),IFERROR(VLOOKUP($E9,LISTINO!$C:$I,5,FALSE),"")) | R9: =IF(AND(ISNUMBER(G9),ISNUMBER(Q9)),G9*Q9,"")
A10: PILASTRO MOTORE | C10: 1 | D10: TTS.PF.001.IPE140.29 | E10: Pilastro fondazione trave IPE140 mt.2,90 | F10: Carpenteria metallica | G10: 0 | O10: pz | Q10: =IFERROR(VLOOKUP($D10,LISTINO!$B:$I,6,FALSE),IFERROR(VLOOKUP($E10,LISTINO!$C:$I,5,FALSE),"")) | R10: =IF(AND(ISNUMBER(G10),ISNUMBER(Q10)),G10*Q10,"")
A11: PILASTRO MOTORE | C11: 1 | D11: TTS.PF.001.IPEA140.29 | E11: Pilastro fondazione trave IPEA140 mt.2,90 (alleggerita) | F11: Carpenteria metallica | G11: 0 | O11: pz | Q11: =IFERROR(VLOOKUP($D11,LISTINO!$B:$I,6,FALSE),IFERROR(VLOOKUP($E11,LISTINO!$C:$I,5,FALSE),"")) | R11: =IF(AND(ISNUMBER(G11),ISNUMBER(Q11)),G11*Q11,"")
A12: PILASTRO MOTORE | C12: 1 | D12: TTS.PF.001.IPE140.31 | E12: Pilastro fondazione trave IPE140 mt.3,10 | F12: Carpenteria metallica | G12: 0 | O12: pz | Q12: =IFERROR(VLOOKUP($D12,LISTINO!$B:$I,6,FALSE),IFERROR(VLOOKUP($E12,LISTINO!$C:$I,5,FALSE),"")) | R12: =IF(AND(ISNUMBER(G12),ISNUMBER(Q12)),G12*Q12,"")
A13: PILASTRO MOTORE | C13: 1 | D13: TTS.PF.001.IPEA140.31 | E13: Pilastro fondazione trave IPEA140 mt.3,10 (alleggerita) | F13: Carpenteria metallica | G13: 0 | O13: pz | Q13: =IFERROR(VLOOKUP($D13,LISTINO!$B:$I,6,FALSE),IFERROR(VLOOKUP($E13,LISTINO!$C:$I,5,FALSE),"")) | R13: =IF(AND(ISNUMBER(G13),ISNUMBER(Q13)),G13*Q13,"")
... A84: PILASTRO MOTORE | C84: 6 | D84: 10DAZAM16 | E84: Dado autobloccante M16 | F84: Bulloneria e minuteria | G84: 4 | O84: pz | Q84: =IFERROR(VLOOKUP($D84,LISTINO!$B:$I,6,FALSE),IFERROR(VLOOKUP($E84,LISTINO!$C:$I,5,FALSE),"")) | R84: =IF(AND(ISNUMBER(G84),ISNUMBER(Q84)),G84*Q84,"")
A85: PILASTRO CUSCINETTO | C85: 1 | D85: TTS.PF.001.IPE140.30 | E85: Pilastro fondazione trave IPE140 mt3,00 | F85: Carpenteria metallica | G85: 1 | H85: 2 | I85: 4 | J85: 4 | K85: 4 | L85: 8 | M85: 10 | O85: pz | Q85: =IFERROR(VLOOKUP($D85,LISTINO!$B:$I,6,FALSE),IFERROR(VLOOKUP($E85,LISTINO!$C:$I,5,FALSE),"")) | R85: =IF(AND(ISNUMBER(G85),ISNUMBER(Q85)),G85*Q85,"")
A86: PILASTRO CUSCINETTO | C86: 2 | D86: TTS.PC.001.IPE140.23 | E86: Pilastro cuscinetto trave IPE 140 mt.2,30 | F86: Carpenteria metallica | G86: 1 | H86: 2 | I86: 4 | J86: 4 | K86: 4 | L86: 8 | M86: 10 | O86: pz | Q86: =IFERROR(VLOOKUP($D86,LISTINO!$B:$I,6,FALSE),IFERROR(VLOOKUP($E86,LISTINO!$C:$I,5,FALSE),"")) | R86: =IF(AND(ISNUMBER(G86),ISNUMBER(Q86)),G86*Q86,"")
A87: PILASTRO CUSCINETTO | C87: 2 | D87: TTS.PC.001.IPEA140.23 | E87: Pilastro cuscinetto trave IPEA 140 mt.2,30 (alleggerita) | F87: Carpenteria metallica | G87: 0 | O87: pz | Q87: =IFERROR(VLOOKUP($D87,LISTINO!$B:$I,6,FALSE),IFERROR(VLOOKUP($E87,LISTINO!$C:$I,5,FALSE),"")) | R87: =IF(AND(ISNUMBER(G87),ISNUMBER(Q87)),G87*Q87,"")
A88: PILASTRO CUSCINETTO | C88: 2 | D88: TTS.PC.001.IPE140.28 | E88: Pilastro cuscinetto trave IPE 140 mt.2,80 | F88: Carpenteria metallica | G88: 0 | O88: pz | Q88: =IFERROR(VLOOKUP($D88,LISTINO!$B:$I,6,FALSE),IFERROR(VLOOKUP($E88,LISTINO!$C:$I,5,FALSE),"")) | R88: =IF(AND(ISNUMBER(G88),ISNUMBER(Q88)),G88*Q88,"")
A89: PILASTRO CUSCINETTO | C89: 2 | D89: TTS.PC.001.IPEA140.28 | E89: Pilastro cuscinetto trave IPEA 140 mt.2,80 (alleggerita) | F89: Carpenteria metallica | G89: 0 | O89: pz | Q89: =IFERROR(VLOOKUP($D89,LISTINO!$B:$I,6,FALSE),IFERROR(VLOOKUP($E89,LISTINO!$C:$I,5,FALSE),"")) | R89: =IF(AND(ISNUMBER(G89),ISNUMBER(Q89)),G89*Q89,"")
A90: PILASTRO CUSCINETTO | C90: 2 | D90: TTS.PC.001.IPE140.29 | E90: Pilastro cuscinetto trave IPE 140 mt.2,90 | F90: Carpenteria metallica | G90: 0 | O90: pz | Q90: =IFERROR(VLOOKUP($D90,LISTINO!$B:$I,6,FALSE),IFERROR(VLOOKUP($E90,LISTINO!$C:$I,5,FALSE),"")) | R90: =IF(AND(ISNUMBER(G90),ISNUMBER(Q90)),G90*Q90,"")
A91: PILASTRO CUSCINETTO | C91: 2 | D91: TTS.PC.001.IPEA140.29 | E91: Pilastro cuscinetto trave IPEA 140 mt.2,90 (alleggerita) | F91: Carpenteria metallica | G91: 0 | O91: pz | Q91: =IFERROR(VLOOKUP($D91,LISTINO!$B:$I,6,FALSE),IFERROR(VLOOKUP($E91,LISTINO!$C:$I,5,FALSE),"")) | R91: =IF(AND(ISNUMBER(G91),ISNUMBER(Q91)),G91*Q91,"")
A92: PILASTRO CUSCINETTO | C92: 2 | D92: TTS.PC.001.IPE140.30 | E92: Pilastro cuscinetto trave IPE 140 mt.3,00 | F92: Carpenteria metallica | G92: 0 | O92: pz | Q92: =IFERROR(VLOOKUP($D92,LISTINO!$B:$I,6,FALSE),IFERROR(VLOOKUP($E92,LISTINO!$C:$I,5,FALSE),"")) | R92: =IF(AND(ISNUMBER(G92),ISNUMBER(Q92)),G92*Q92,"")
A93: PILASTRO CUSCINETTO | C93: 2 | D93: TTS.PC.001.IPEA140.30 | E93: Pilastro cuscinetto trave IPEA 140 mt.3,00 (alleggerita) | F93: Carpenteria metallica | G93: 0 | O93: pz | Q93: =IFERROR(VLOOKUP($D93,LISTINO!$B:$I,6,FALSE),IFERROR(VLOOKUP($E93,LISTINO!$C:$I,5,FALSE),"")) | R93: =IF(AND(ISNUMBER(G93),ISNUMBER(Q93)),G93*Q93,"")
A94: PILASTRO CUSCINETTO | C94: 2 | D94: TTS.PC.001.IPE140.31 | E94: Pilastro cuscinetto trave IPE 140 mt.3,10 | F94: Carpenteria metallica | G94: 0 | O94: pz | Q94: =IFERROR(VLOOKUP($D94,LISTINO!$B:$I,6,FALSE),IFERROR(VLOOKUP($E94,LISTINO!$C:$I,5,FALSE),"")) | R94: =IF(AND(ISNUMBER(G94),ISNUMBER(Q94)),G94*Q94,"")
A95: PILASTRO CUSCINETTO | C95: 2 | D95: TTS.PC.001.IPEA140.31 | E95: Pilastro cuscinetto trave IPEA 140 mt.3,10 (alleggerita) | F95: Carpenteria metallica | G95: 0 | O95: pz | Q95: =IFERROR(VLOOKUP($D95,LISTINO!$B:$I,6,FALSE),IFERROR(VLOOKUP($E95,LISTINO!$C:$I,5,FALSE),"")) | R95: =IF(AND(ISNUMBER(G95),ISNUMBER(Q95)),G95*Q95,"")
A96: PILASTRO CUSCINETTO | C96: 2 | D96: TTS.PC.001.IPE140.32 | E96: Pilastro cuscinetto trave IPE 140 mt.3,20 | F96: Carpenteria metallica | G96: 0 | O96: pz | Q96: =IFERROR(VLOOKUP($D96,LISTINO!$B:$I,6,FALSE),IFERROR(VLOOKUP($E96,LISTINO!$C:$I,5,FALSE),"")) | R96: =IF(AND(ISNUMBER(G96),ISNUMBER(Q96)),G96*Q96,"")
A97: PILASTRO CUSCINETTO | C97: 2 | D97: TTS.PC.001.IPEA140.32 | E97: Pilastro cuscinetto trave IPEA 140 mt.3,20 (alleggerita) | F97: Carpenteria metallica | G97: 0 | O97: pz | Q97: =IFERROR(VLOOKUP($D97,LISTINO!$B:$I,6,FALSE),IFERROR(VLOOKUP($E97,LISTINO!$C:$I,5,FALSE),"")) | R97: =IF(AND(ISNUMBER(G97),ISNUMBER(Q97)),G97*Q97,"")
A98: PILASTRO CUSCINETTO | C98: 2 | D98: TTS.PC.001.IPE140.33 | E98: Pilastro cuscinetto trave IPE 140 mt.3,30 | F98: Carpenteria metallica | G98: 0 | O98: pz | Q98: =IFERROR(VLOOKUP($D98,LISTINO!$B:$I,6,FALSE),IFERROR(VLOOKUP($E98,LISTINO!$C:$I,5,FALSE),"")) | R98: =IF(AND(ISNUMBER(G98),ISNUMBER(Q98)),G98*Q98,"")
... A123: PILASTRO CUSCINETTO | C123: 2 | D123: TTS.PC.001.IPEA140.45 | E123: Pilastro cuscinetto trave IPEA 140 mt.4,50 (alleggerita) | F123: Carpenteria metallica | G123: 0 | O123: pz | Q123: =IFERROR(VLOOKUP($D123,LISTINO!$B:$I,6,FALSE),IFERROR(VLOOKUP($E123,LISTINO!$C:$I,5,FALSE),"")) | R123: =IF(AND(ISNUMBER(G123),ISNUMBER(Q123)),G123*Q123,"")
A124: PILASTRO CUSCINETTO | C124: 3 | D124: TTS.PF.002.IPE140 | E124: Piastra giunzione montanti centrale 200x100x4 (8 fori Ø 11) | F124: Carpenteria metallica | G124: 2 | H124: 4 | I124: 8 | J124: 8 | K124: 8 | L124: 16 | M124: 20 | O124: pz | Q124: =IFERROR(VLOOKUP($D124,LISTINO!$B:$I,6,FALSE),IFERROR(VLOOKUP($E124,LISTINO!$C:$I,5,FALSE),"")) | R124: =IF(AND(ISNUMBER(G124),ISNUMBER(Q124)),G124*Q124,"")
A125: PILASTRO CUSCINETTO | C125: 4 | D125: 10BZM10X40 | E125: Bullone testa esagonale M10X40 | F125: Bulloneria e minuteria | G125: 8 | H125: 16 | I125: 32 | J125: 32 | K125: 32 | L125: 64 | M125: 80 | O125: pz | Q125: =IFERROR(VLOOKUP($D125,LISTINO!$B:$I,6,FALSE),IFERROR(VLOOKUP($E125,LISTINO!$C:$I,5,FALSE),"")) | R125: =IF(AND(ISNUMBER(G125),ISNUMBER(Q125)),G125*Q125,"")
A126: PILASTRO CUSCINETTO | C126: 5 | D126: 10ROND10 | E126: Rondella zn da 10 | F126: Bulloneria e minuteria | G126: 8 | H126: 16 | I126: 32 | J126: 32 | K126: 32 | L126: 64 | M126: 80 | O126: pz | Q126: =IFERROR(VLOOKUP($D126,LISTINO!$B:$I,6,FALSE),IFERROR(VLOOKUP($E126,LISTINO!$C:$I,5,FALSE),"")) | R126: =IF(AND(ISNUMBER(G126),ISNUMBER(Q126)),G126*Q126,"")
A127: PILASTRO CUSCINETTO | C127: 6 | D127: 10ROND10 | E127: Rondella zn da 10 | F127: Bulloneria e minuteria | G127: 8 | H127: 16 | I127: 32 | J127: 32 | K127: 32 | L127: 64 | M127: 80 | O127: pz | Q127: =IFERROR(VLOOKUP($D127,LISTINO!$B:$I,6,FALSE),IFERROR(VLOOKUP($E127,LISTINO!$C:$I,5,FALSE),"")) | R127: =IF(AND(ISNUMBER(G127),ISNUMBER(Q127)),G127*Q127,"")
A128: PILASTRO CUSCINETTO | C128: 7 | D128: 10DAZAM10 | E128: Dado autobloccante M10 | F128: Bulloneria e minuteria | G128: 8 | H128: 16 | I128: 32 | J128: 32 | K128: 32 | L128: 64 | M128: 80 | O128: pz | Q128: =IFERROR(VLOOKUP($D128,LISTINO!$B:$I,6,FALSE),IFERROR(VLOOKUP($E128,LISTINO!$C:$I,5,FALSE),"")) | R128: =IF(AND(ISNUMBER(G128),ISNUMBER(Q128)),G128*Q128,"")
A129: PILASTRO CUSCINETTO | C129: 1 | D129: TTS.PF.003.IPE140 | E129: Piastra giunzione montanti esterna 240x70x6 (12 fori Ø 11) | F129: Carpenteria metallica | G129: 2 | H129: 4 | I129: 8 | J129: 8 | K129: 8 | L129: 16 | M129: 20 | O129: pz | Q129: =IFERROR(VLOOKUP($D129,LISTINO!$B:$I,6,FALSE),IFERROR(VLOOKUP($E129,LISTINO!$C:$I,5,FALSE),"")) | R129: =IF(AND(ISNUMBER(G129),ISNUMBER(Q129)),G129*Q129,"")
A130: PILASTRO CUSCINETTO | C130: 2 | D130: TTS.PF.004.IPE140 | E130: Piastra giunzione montanti interna 240x25x6 (6 fori Ø 11) | F130: Carpenteria metallica | G130: 4 | H130: 8 | I130: 16 | J130: 16 | K130: 16 | L130: 32 | M130: 40 | O130: pz | Q130: =IFERROR(VLOOKUP($D130,LISTINO!$B:$I,6,FALSE),IFERROR(VLOOKUP($E130,LISTINO!$C:$I,5,FALSE),"")) | R130: =IF(AND(ISNUMBER(G130),ISNUMBER(Q130)),G130*Q130,"")
A131: PILASTRO CUSCINETTO | C131: 3 | D131: 10BZM10X40 | E131: Bullone testa esagonale M10X40 | F131: Bulloneria e minuteria | G131: 24 | H131: 48 | I131: 96 | J131: 96 | K131: 96 | L131: 192 | M131: 240 | O131: pz | Q131: =IFERROR(VLOOKUP($D131,LISTINO!$B:$I,6,FALSE),IFERROR(VLOOKUP($E131,LISTINO!$C:$I,5,FALSE),"")) | R131: =IF(AND(ISNUMBER(G131),ISNUMBER(Q131)),G131*Q131,"")
A132: PILASTRO CUSCINETTO | C132: 4 | D132: 10ROND10 | E132: Rondella zn da 10 | F132: Bulloneria e minuteria | G132: 24 | H132: 48 | I132: 96 | J132: 96 | K132: 96 | L132: 192 | M132: 240 | O132: pz | Q132: =IFERROR(VLOOKUP($D132,LISTINO!$B:$I,6,FALSE),IFERROR(VLOOKUP($E132,LISTINO!$C:$I,5,FALSE),"")) | R132: =IF(AND(ISNUMBER(G132),ISNUMBER(Q132)),G132*Q132,"")
A133: PILASTRO CUSCINETTO | C133: 5 | D133: 10ROND10 | E133: Rondella zn da 10 | F133: Bulloneria e minuteria | G133: 24 | H133: 48 | I133: 96 | J133: 96 | K133: 96 | L133: 192 | M133: 240 | O133: pz | Q133: =IFERROR(VLOOKUP($D133,LISTINO!$B:$I,6,FALSE),IFERROR(VLOOKUP($E133,LISTINO!$C:$I,5,FALSE),"")) | R133: =IF(AND(ISNUMBER(G133),ISNUMBER(Q133)),G133*Q133,"")
A134: PILASTRO CUSCINETTO | C134: 6 | D134: 10DAZAM10 | E134: Dado autobloccante M10 | F134: Bulloneria e minuteria | G134: 24 | H134: 48 | I134: 96 | J134: 96 | K134: 96 | L134: 192 | M134: 240 | O134: pz | Q134: =IFERROR(VLOOKUP($D134,LISTINO!$B:$I,6,FALSE),IFERROR(VLOOKUP($E134,LISTINO!$C:$I,5,FALSE),"")) | R134: =IF(AND(ISNUMBER(G134),ISNUMBER(Q134)),G134*Q134,"")
...

Sheet RIEPILOGO
A1: RIEPILOGO LISTINO
A3: Componenti unici a listino | B3: 204
A4: Righe di distinta totali (tutti i kit) | B4: 357
A6: Componenti unici per categoria
A7: Carpenteria metallica | B7: 161
A8: Bulloneria e minuteria | B8: 31
A9: Motorizzazione | B9: 1
A10: Cuscinetti | B10: 1
A11: Quadristica ed elettrico | B11: 2
A12: Sensoristica e strumentazione | B12: 6
A13: Moduli fotovoltaici | B13: 2
A15: Legenda
A16: • LISTINO: un record per ogni componente; 'Prezzo unitario' da compilare a cura ufficio acquisti.
A17: • DISTINTA COMPLETA: tutte le righe di tutti i fogli della distinta originale (vista integrale).
A18: • Colonne 'Q.tà NN mod': quantità previste per le sei configurazioni di tracker (dove indicate in origine).
A19: • 'Già caricato altrove' = X: articolo evidenziato in rosso nella distinta originale (non riconteggiare).
A20: • 'Importo €' e 'TOTALE' si calcolano automaticamente dopo aver compilato i prezzi nel foglio LISTINO.
A21: • 'Peso elemento (kg)' (LISTINO e DISTINTA): colonna da compilare a mano, un valore per riga.
A22: • Righe DISTINTA con Q.tà = 0: referenze alternative (varianti di spessore o lunghezza) create al rev.5, poste sotto l'articolo base; impostare la Q.tà quando la variante viene scelta in configurazione.
A23: • Referenze 'IPEA' (codice ...IPEA140...): travi alleggerite, duplicato di ogni pilastro/supporto IPE 140; in DISTINTA sono righe con Q.tà = 0 sotto la versione IPE.
A24: • Foglio 'SCHEDA STRUTTURA': riferimento per tutta la carpenteria strutturale (travi IPE/IPEA e assi di rotazione). Blocco 'Profili' = peso teorico kg/m, % zincatura, costo acquisto €/kg e costo zincatura €/kg da compilare. Nell'elenco, per travi e assi: 'Peso elemento (kg)' = lunghezza × kg/m finale (con maggiorazione zincatura); 'Costo acquisto (€)' = peso × €/kg acquisto; 'Costo zincatura (€)' = peso × magg. % × €/kg zincatura, solo se la maggiorazione è presente. Nel LISTINO il 'Peso elemento' di travi e assi arriva da qui; gli altri pesi restano manuali.
