Workbook

Sheet SCHEDA STRUTTURA
A1: SCHEDA STRUTTURA — parametri peso e costo di acquisto/zincatura (compilare kg/m, % zincatura, €/kg acquisto e €/kg zincatura)
A2: Blocco 'Profili': travi IPE/IPEA e assi di rotazione con peso al metro, % zincatura, €/kg acquisto e €/kg zincatura. Peso elemento (kg) include la maggiorazione zincatura; Costo acquisto (€) = peso al netto × €/kg acquisto (indipendente dalla zincatura); Costo zincatura (€) = peso al netto × (1 + magg. %) × €/kg zincatura, solo se la maggiorazione è presente. I pezzi 'a pezzo' (piastre di giunzione, supporti, angolari, pali MAX, aste) sono nel foglio 'SCHEDA PEZZI SPECIALI'. L'omega supporto pannello e le sue staffe (supporto a L/V, gaffa) sono in fondo all'Elenco qui sotto.
A4: Profilo | B4: Peso teorico (kg/m) | C4: Magg. zincatura % | D4: Peso finale (kg/m) | E4: Costo acquisto (€/kg) | F4: Costo zincatura (€/kg)
A5: IPE 140 | B5: 12.9 | D5: =IF(ISNUMBER($B5),$B5*(1+IF(ISNUMBER($C5),$C5,0)),"") -> 12.9
A6: IPEA 140 | B6: 10.9 | D6: =IF(ISNUMBER($B6),$B6*(1+IF(ISNUMBER($C6),$C6,0)),"") -> 10.9
A7: ASSE 120x120x3 | B7: 11.8 | D7: =IF(ISNUMBER($B7),$B7*(1+IF(ISNUMBER($C7),$C7,0)),"") -> 11.8
A8: ASSE 120x120x2,5 | B8: 9.2 | D8: =IF(ISNUMBER($B8),$B8*(1+IF(ISNUMBER($C8),$C8,0)),"") -> 9.2
A9: OMEGA 2,0 | B9: 3.9 | D9: =IF(ISNUMBER($B9),$B9*(1+IF(ISNUMBER($C9),$C9,0)),"") -> 3.9
A10: OMEGA 1,8 | B10: 3.51 | D10: =IF(ISNUMBER($B10),$B10*(1+IF(ISNUMBER($C10),$C10,0)),"") -> 3.51
A12: Codice | B12: Descrizione | C12: Profilo | D12: Lunghezza (m) | E12: Peso elemento (kg) | F12: Costo acquisto (€) | G12: Costo zincatura (€)
A13: TTS.PC.001.IPE140.23 | B13: Pilastro cuscinetto trave IPE 140 mt.2,30 | C13: IPE 140 | D13: 2.3 | E13: =IF(AND(ISNUMBER($D13),ISNUMBER(VLOOKUP($C13,$A$5:$F$11,4,FALSE))),$D13*VLOOKUP($C13,$A$5:$F$11,4,FALSE),"") -> 29.67 | F13: =IF(AND(ISNUMBER($D13),ISNUMBER(VLOOKUP($C13,$A$5:$F$11,2,FALSE)),ISNUMBER(VLOOKUP($C13,$A$5:$F$11,5,FALSE))),$D13*VLOOKUP($C13,$A$5:$F$11,2,FALSE)*VLOOKUP($C13,$A$5:$F$11,5,FALSE),"") | G13: =IF(AND(ISNUMBER($D13),ISNUMBER(VLOOKUP($C13,$A$5:$F$11,2,FALSE)),ISNUMBER(VLOOKUP($C13,$A$5:$F$11,3,FALSE)),VLOOKUP($C13,$A$5:$F$11,3,FALSE)>0,ISNUMBER(VLOOKUP($C13,$A$5:$F$11,6,FALSE))),$D13*VLOOKUP($C13,$A$5:$F$11,2,FALSE)*(1+VLOOKUP($C13,$A$5:$F$11,3,FALSE))*VLOOKUP($C13,$A$5:$F$11,6,FALSE),"")
A14: TTS.PC.001.IPE140.23.FI | B14: Pilastro cuscinetto trave ipe140 x mt. 2,30 con foratura alloggiamento inverter | C14: IPE 140 | D14: 2.3 | E14: =IF(AND(ISNUMBER($D14),ISNUMBER(VLOOKUP($C14,$A$5:$F$11,4,FALSE))),$D14*VLOOKUP($C14,$A$5:$F$11,4,FALSE),"") -> 29.67 | F14: =IF(AND(ISNUMBER($D14),ISNUMBER(VLOOKUP($C14,$A$5:$F$11,2,FALSE)),ISNUMBER(VLOOKUP($C14,$A$5:$F$11,5,FALSE))),$D14*VLOOKUP($C14,$A$5:$F$11,2,FALSE)*VLOOKUP($C14,$A$5:$F$11,5,FALSE),"") | G14: =IF(AND(ISNUMBER($D14),ISNUMBER(VLOOKUP($C14,$A$5:$F$11,2,FALSE)),ISNUMBER(VLOOKUP($C14,$A$5:$F$11,3,FALSE)),VLOOKUP($C14,$A$5:$F$11,3,FALSE)>0,ISNUMBER(VLOOKUP($C14,$A$5:$F$11,6,FALSE))),$D14*VLOOKUP($C14,$A$5:$F$11,2,FALSE)*(1+VLOOKUP($C14,$A$5:$F$11,3,FALSE))*VLOOKUP($C14,$A$5:$F$11,6,FALSE),"")
A15: TTS.PC.001.IPE140.23.FQA | B15: Pilastro cuscinetto trave ipe140 x mt. 2,30 con foratura alloggiamento quadro area | C15: IPE 140 | D15: 2.3 | E15: =IF(AND(ISNUMBER($D15),ISNUMBER(VLOOKUP($C15,$A$5:$F$11,4,FALSE))),$D15*VLOOKUP($C15,$A$5:$F$11,4,FALSE),"") -> 29.67 | F15: =IF(AND(ISNUMBER($D15),ISNUMBER(VLOOKUP($C15,$A$5:$F$11,2,FALSE)),ISNUMBER(VLOOKUP($C15,$A$5:$F$11,5,FALSE))),$D15*VLOOKUP($C15,$A$5:$F$11,2,FALSE)*VLOOKUP($C15,$A$5:$F$11,5,FALSE),"") | G15: =IF(AND(ISNUMBER($D15),ISNUMBER(VLOOKUP($C15,$A$5:$F$11,2,FALSE)),ISNUMBER(VLOOKUP($C15,$A$5:$F$11,3,FALSE)),VLOOKUP($C15,$A$5:$F$11,3,FALSE)>0,ISNUMBER(VLOOKUP($C15,$A$5:$F$11,6,FALSE))),$D15*VLOOKUP($C15,$A$5:$F$11,2,FALSE)*(1+VLOOKUP($C15,$A$5:$F$11,3,FALSE))*VLOOKUP($C15,$A$5:$F$11,6,FALSE),"")
A16: TTS.PC.001.IPE140.28 | B16: Pilastro cuscinetto trave IPE 140 mt.2,80 | C16: IPE 140 | D16: 2.8 | E16: =IF(AND(ISNUMBER($D16),ISNUMBER(VLOOKUP($C16,$A$5:$F$11,4,FALSE))),$D16*VLOOKUP($C16,$A$5:$F$11,4,FALSE),"") -> 36.12 | F16: =IF(AND(ISNUMBER($D16),ISNUMBER(VLOOKUP($C16,$A$5:$F$11,2,FALSE)),ISNUMBER(VLOOKUP($C16,$A$5:$F$11,5,FALSE))),$D16*VLOOKUP($C16,$A$5:$F$11,2,FALSE)*VLOOKUP($C16,$A$5:$F$11,5,FALSE),"") | G16: =IF(AND(ISNUMBER($D16),ISNUMBER(VLOOKUP($C16,$A$5:$F$11,2,FALSE)),ISNUMBER(VLOOKUP($C16,$A$5:$F$11,3,FALSE)),VLOOKUP($C16,$A$5:$F$11,3,FALSE)>0,ISNUMBER(VLOOKUP($C16,$A$5:$F$11,6,FALSE))),$D16*VLOOKUP($C16,$A$5:$F$11,2,FALSE)*(1+VLOOKUP($C16,$A$5:$F$11,3,FALSE))*VLOOKUP($C16,$A$5:$F$11,6,FALSE),"")
A17: TTS.PC.001.IPE140.29 | B17: Pilastro cuscinetto trave IPE 140 mt.2,90 | C17: IPE 140 | D17: 2.9 | E17: =IF(AND(ISNUMBER($D17),ISNUMBER(VLOOKUP($C17,$A$5:$F$11,4,FALSE))),$D17*VLOOKUP($C17,$A$5:$F$11,4,FALSE),"") -> 37.41 | F17: =IF(AND(ISNUMBER($D17),ISNUMBER(VLOOKUP($C17,$A$5:$F$11,2,FALSE)),ISNUMBER(VLOOKUP($C17,$A$5:$F$11,5,FALSE))),$D17*VLOOKUP($C17,$A$5:$F$11,2,FALSE)*VLOOKUP($C17,$A$5:$F$11,5,FALSE),"") | G17: =IF(AND(ISNUMBER($D17),ISNUMBER(VLOOKUP($C17,$A$5:$F$11,2,FALSE)),ISNUMBER(VLOOKUP($C17,$A$5:$F$11,3,FALSE)),VLOOKUP($C17,$A$5:$F$11,3,FALSE)>0,ISNUMBER(VLOOKUP($C17,$A$5:$F$11,6,FALSE))),$D17*VLOOKUP($C17,$A$5:$F$11,2,FALSE)*(1+VLOOKUP($C17,$A$5:$F$11,3,FALSE))*VLOOKUP($C17,$A$5:$F$11,6,FALSE),"")
A18: TTS.PC.001.IPE140.30 | B18: Pilastro cuscinetto trave IPE 140 mt.3,00 | C18: IPE 140 | D18: 3 | E18: =IF(AND(ISNUMBER($D18),ISNUMBER(VLOOKUP($C18,$A$5:$F$11,4,FALSE))),$D18*VLOOKUP($C18,$A$5:$F$11,4,FALSE),"") -> 38.7 | F18: =IF(AND(ISNUMBER($D18),ISNUMBER(VLOOKUP($C18,$A$5:$F$11,2,FALSE)),ISNUMBER(VLOOKUP($C18,$A$5:$F$11,5,FALSE))),$D18*VLOOKUP($C18,$A$5:$F$11,2,FALSE)*VLOOKUP($C18,$A$5:$F$11,5,FALSE),"") | G18: =IF(AND(ISNUMBER($D18),ISNUMBER(VLOOKUP($C18,$A$5:$F$11,2,FALSE)),ISNUMBER(VLOOKUP($C18,$A$5:$F$11,3,FALSE)),VLOOKUP($C18,$A$5:$F$11,3,FALSE)>0,ISNUMBER(VLOOKUP($C18,$A$5:$F$11,6,FALSE))),$D18*VLOOKUP($C18,$A$5:$F$11,2,FALSE)*(1+VLOOKUP($C18,$A$5:$F$11,3,FALSE))*VLOOKUP($C18,$A$5:$F$11,6,FALSE),"")
A19: TTS.PC.001.IPE140.31 | B19: Pilastro cuscinetto trave IPE 140 mt.3,10 | C19: IPE 140 | D19: 3.1 | E19: =IF(AND(ISNUMBER($D19),ISNUMBER(VLOOKUP($C19,$A$5:$F$11,4,FALSE))),$D19*VLOOKUP($C19,$A$5:$F$11,4,FALSE),"") -> 39.99 | F19: =IF(AND(ISNUMBER($D19),ISNUMBER(VLOOKUP($C19,$A$5:$F$11,2,FALSE)),ISNUMBER(VLOOKUP($C19,$A$5:$F$11,5,FALSE))),$D19*VLOOKUP($C19,$A$5:$F$11,2,FALSE)*VLOOKUP($C19,$A$5:$F$11,5,FALSE),"") | G19: =IF(AND(ISNUMBER($D19),ISNUMBER(VLOOKUP($C19,$A$5:$F$11,2,FALSE)),ISNUMBER(VLOOKUP($C19,$A$5:$F$11,3,FALSE)),VLOOKUP($C19,$A$5:$F$11,3,FALSE)>0,ISNUMBER(VLOOKUP($C19,$A$5:$F$11,6,FALSE))),$D19*VLOOKUP($C19,$A$5:$F$11,2,FALSE)*(1+VLOOKUP($C19,$A$5:$F$11,3,FALSE))*VLOOKUP($C19,$A$5:$F$11,6,FALSE),"")
A20: TTS.PC.001.IPE140.32 | B20: Pilastro cuscinetto trave IPE 140 mt.3,20 | C20: IPE 140 | D20: 3.2 | E20: =IF(AND(ISNUMBER($D20),ISNUMBER(VLOOKUP($C20,$A$5:$F$11,4,FALSE))),$D20*VLOOKUP($C20,$A$5:$F$11,4,FALSE),"") -> 41.28 | F20: =IF(AND(ISNUMBER($D20),ISNUMBER(VLOOKUP($C20,$A$5:$F$11,2,FALSE)),ISNUMBER(VLOOKUP($C20,$A$5:$F$11,5,FALSE))),$D20*VLOOKUP($C20,$A$5:$F$11,2,FALSE)*VLOOKUP($C20,$A$5:$F$11,5,FALSE),"") | G20: =IF(AND(ISNUMBER($D20),ISNUMBER(VLOOKUP($C20,$A$5:$F$11,2,FALSE)),ISNUMBER(VLOOKUP($C20,$A$5:$F$11,3,FALSE)),VLOOKUP($C20,$A$5:$F$11,3,FALSE)>0,ISNUMBER(VLOOKUP($C20,$A$5:$F$11,6,FALSE))),$D20*VLOOKUP($C20,$A$5:$F$11,2,FALSE)*(1+VLOOKUP($C20,$A$5:$F$11,3,FALSE))*VLOOKUP($C20,$A$5:$F$11,6,FALSE),"")
A21: TTS.PC.001.IPE140.33 | B21: Pilastro cuscinetto trave IPE 140 mt.3,30 | C21: IPE 140 | D21: 3.3 | E21: =IF(AND(ISNUMBER($D21),ISNUMBER(VLOOKUP($C21,$A$5:$F$11,4,FALSE))),$D21*VLOOKUP($C21,$A$5:$F$11,4,FALSE),"") -> 42.57 | F21: =IF(AND(ISNUMBER($D21),ISNUMBER(VLOOKUP($C21,$A$5:$F$11,2,FALSE)),ISNUMBER(VLOOKUP($C21,$A$5:$F$11,5,FALSE))),$D21*VLOOKUP($C21,$A$5:$F$11,2,FALSE)*VLOOKUP($C21,$A$5:$F$11,5,FALSE),"") | G21: =IF(AND(ISNUMBER($D21),ISNUMBER(VLOOKUP($C21,$A$5:$F$11,2,FALSE)),ISNUMBER(VLOOKUP($C21,$A$5:$F$11,3,FALSE)),VLOOKUP($C21,$A$5:$F$11,3,FALSE)>0,ISNUMBER(VLOOKUP($C21,$A$5:$F$11,6,FALSE))),$D21*VLOOKUP($C21,$A$5:$F$11,2,FALSE)*(1+VLOOKUP($C21,$A$5:$F$11,3,FALSE))*VLOOKUP($C21,$A$5:$F$11,6,FALSE),"")
A22: TTS.PC.001.IPE140.34 | B22: Pilastro cuscinetto trave IPE 140 mt.3,40 | C22: IPE 140 | D22: 3.4 | E22: =IF(AND(ISNUMBER($D22),ISNUMBER(VLOOKUP($C22,$A$5:$F$11,4,FALSE))),$D22*VLOOKUP($C22,$A$5:$F$11,4,FALSE),"") -> 43.86 | F22: =IF(AND(ISNUMBER($D22),ISNUMBER(VLOOKUP($C22,$A$5:$F$11,2,FALSE)),ISNUMBER(VLOOKUP($C22,$A$5:$F$11,5,FALSE))),$D22*VLOOKUP($C22,$A$5:$F$11,2,FALSE)*VLOOKUP($C22,$A$5:$F$11,5,FALSE),"") | G22: =IF(AND(ISNUMBER($D22),ISNUMBER(VLOOKUP($C22,$A$5:$F$11,2,FALSE)),ISNUMBER(VLOOKUP($C22,$A$5:$F$11,3,FALSE)),VLOOKUP($C22,$A$5:$F$11,3,FALSE)>0,ISNUMBER(VLOOKUP($C22,$A$5:$F$11,6,FALSE))),$D22*VLOOKUP($C22,$A$5:$F$11,2,FALSE)*(1+VLOOKUP($C22,$A$5:$F$11,3,FALSE))*VLOOKUP($C22,$A$5:$F$11,6,FALSE),"")
A23: TTS.PC.001.IPE140.35 | B23: Pilastro cuscinetto trave IPE 140 mt.3,50 | C23: IPE 140 | D23: 3.5 | E23: =IF(AND(ISNUMBER($D23),ISNUMBER(VLOOKUP($C23,$A$5:$F$11,4,FALSE))),$D23*VLOOKUP($C23,$A$5:$F$11,4,FALSE),"") -> 45.15 | F23: =IF(AND(ISNUMBER($D23),ISNUMBER(VLOOKUP($C23,$A$5:$F$11,2,FALSE)),ISNUMBER(VLOOKUP($C23,$A$5:$F$11,5,FALSE))),$D23*VLOOKUP($C23,$A$5:$F$11,2,FALSE)*VLOOKUP($C23,$A$5:$F$11,5,FALSE),"") | G23: =IF(AND(ISNUMBER($D23),ISNUMBER(VLOOKUP($C23,$A$5:$F$11,2,FALSE)),ISNUMBER(VLOOKUP($C23,$A$5:$F$11,3,FALSE)),VLOOKUP($C23,$A$5:$F$11,3,FALSE)>0,ISNUMBER(VLOOKUP($C23,$A$5:$F$11,6,FALSE))),$D23*VLOOKUP($C23,$A$5:$F$11,2,FALSE)*(1+VLOOKUP($C23,$A$5:$F$11,3,FALSE))*VLOOKUP($C23,$A$5:$F$11,6,FALSE),"")
A24: TTS.PC.001.IPE140.36 | B24: Pilastro cuscinetto trave IPE 140 mt.3,60 | C24: IPE 140 | D24: 3.6 | E24: =IF(AND(ISNUMBER($D24),ISNUMBER(VLOOKUP($C24,$A$5:$F$11,4,FALSE))),$D24*VLOOKUP($C24,$A$5:$F$11,4,FALSE),"") -> 46.44 | F24: =IF(AND(ISNUMBER($D24),ISNUMBER(VLOOKUP($C24,$A$5:$F$11,2,FALSE)),ISNUMBER(VLOOKUP($C24,$A$5:$F$11,5,FALSE))),$D24*VLOOKUP($C24,$A$5:$F$11,2,FALSE)*VLOOKUP($C24,$A$5:$F$11,5,FALSE),"") | G24: =IF(AND(ISNUMBER($D24),ISNUMBER(VLOOKUP($C24,$A$5:$F$11,2,FALSE)),ISNUMBER(VLOOKUP($C24,$A$5:$F$11,3,FALSE)),VLOOKUP($C24,$A$5:$F$11,3,FALSE)>0,ISNUMBER(VLOOKUP($C24,$A$5:$F$11,6,FALSE))),$D24*VLOOKUP($C24,$A$5:$F$11,2,FALSE)*(1+VLOOKUP($C24,$A$5:$F$11,3,FALSE))*VLOOKUP($C24,$A$5:$F$11,6,FALSE),"")
... A138: TTS.AR.004.4800.25 | B138: Asse esterno 120x120x2,5 mm. lunghezza mt.4,800 | C138: ASSE 120x120x2,5 | D138: 4.8 | E138: =IF(AND(ISNUMBER($D138),ISNUMBER(VLOOKUP($C138,$A$5:$F$11,4,FALSE))),$D138*VLOOKUP($C138,$A$5:$F$11,4,FALSE),"") -> 44.16 | F138: =IF(AND(ISNUMBER($D138),ISNUMBER(VLOOKUP($C138,$A$5:$F$11,2,FALSE)),ISNUMBER(VLOOKUP($C138,$A$5:$F$11,5,FALSE))),$D138*VLOOKUP($C138,$A$5:$F$11,2,FALSE)*VLOOKUP($C138,$A$5:$F$11,5,FALSE),"") | G138: =IF(AND(ISNUMBER($D138),ISNUMBER(VLOOKUP($C138,$A$5:$F$11,2,FALSE)),ISNUMBER(VLOOKUP($C138,$A$5:$F$11,3,FALSE)),VLOOKUP($C138,$A$5:$F$11,3,FALSE)>0,ISNUMBER(VLOOKUP($C138,$A$5:$F$11,6,FALSE))),$D138*VLOOKUP($C138,$A$5:$F$11,2,FALSE)*(1+VLOOKUP($C138,$A$5:$F$11,3,FALSE))*VLOOKUP($C138,$A$5:$F$11,6,FALSE),"")
A139: TTS.AR.3011 | B139: Supporto a L superiore omega | E139: 0.8568
A140: TTS.AR.3012 | B140: Supporto a V inferiore omega | E140: 0.4095
A141: TTS.AR.3013 | B141: Gaffa sotto omega | E141: 1.278
A142: TTS.AR.3014 | B142: Omega supporto pannello | C142: OMEGA 2,0 | D142: 1.5 | E142: =IF(AND(ISNUMBER($D142),ISNUMBER(VLOOKUP($C142,$A$5:$F$11,4,FALSE))),$D142*VLOOKUP($C142,$A$5:$F$11,4,FALSE),"") -> 5.85 | F142: =IF(AND(ISNUMBER($D142),ISNUMBER(VLOOKUP($C142,$A$5:$F$11,2,FALSE)),ISNUMBER(VLOOKUP($C142,$A$5:$F$11,5,FALSE))),$D142*VLOOKUP($C142,$A$5:$F$11,2,FALSE)*VLOOKUP($C142,$A$5:$F$11,5,FALSE),"") | G142: =IF(AND(ISNUMBER($D142),ISNUMBER(VLOOKUP($C142,$A$5:$F$11,2,FALSE)),ISNUMBER(VLOOKUP($C142,$A$5:$F$11,3,FALSE)),VLOOKUP($C142,$A$5:$F$11,3,FALSE)>0,ISNUMBER(VLOOKUP($C142,$A$5:$F$11,6,FALSE))),$D142*VLOOKUP($C142,$A$5:$F$11,2,FALSE)*(1+VLOOKUP($C142,$A$5:$F$11,3,FALSE))*VLOOKUP($C142,$A$5:$F$11,6,FALSE),"")
A143: TTS.AR.3014.18 | B143: Omega supporto pannello mm1,8 | C143: OMEGA 1,8 | D143: 1.5 | E143: =IF(AND(ISNUMBER($D143),ISNUMBER(VLOOKUP($C143,$A$5:$F$11,4,FALSE))),$D143*VLOOKUP($C143,$A$5:$F$11,4,FALSE),"") -> 5.265 | F143: =IF(AND(ISNUMBER($D143),ISNUMBER(VLOOKUP($C143,$A$5:$F$11,2,FALSE)),ISNUMBER(VLOOKUP($C143,$A$5:$F$11,5,FALSE))),$D143*VLOOKUP($C143,$A$5:$F$11,2,FALSE)*VLOOKUP($C143,$A$5:$F$11,5,FALSE),"") | G143: =IF(AND(ISNUMBER($D143),ISNUMBER(VLOOKUP($C143,$A$5:$F$11,2,FALSE)),ISNUMBER(VLOOKUP($C143,$A$5:$F$11,3,FALSE)),VLOOKUP($C143,$A$5:$F$11,3,FALSE)>0,ISNUMBER(VLOOKUP($C143,$A$5:$F$11,6,FALSE))),$D143*VLOOKUP($C143,$A$5:$F$11,2,FALSE)*(1+VLOOKUP($C143,$A$5:$F$11,3,FALSE))*VLOOKUP($C143,$A$5:$F$11,6,FALSE),"")

Sheet SCHEDA PEZZI SPECIALI
A1: SCHEDA PEZZI SPECIALI — parametri peso e costo di acquisto/zincatura dei pezzi 'a pezzo' di carpenteria metallica (piastre di giunzione, supporti, angolari, omega, pali MAX, aste sensori)
A2: Un rigo per voce nel blocco 'Parametri'. Compilare Peso pezzo (kg) al netto, % zincatura, €/kg acquisto e €/kg zincatura. Peso elemento (kg) include la maggiorazione zincatura; Costo acquisto (€) = peso al netto × €/kg acquisto (indipendente dalla zincatura); Costo zincatura (€) = peso al netto × (1 + magg. %) × €/kg zincatura, solo se la maggiorazione è presente. La Descrizione si compila qui nei Parametri; nell'Elenco è richiamata automaticamente. Il LISTINO pesca il 'Peso elemento' dal blocco 'Elenco'.
A4: PEZZI SPECIALI — parametri (compilare Descrizione, Peso pezzo, % zincatura e €/kg)
A5: Voce | B5: Descrizione | C5: Peso pezzo (kg) | D5: Magg. zincatura % | E5: Peso finale (kg) | F5: Costo acquisto (€/kg) | G5: Costo zincatura (€/kg)
A6: TTS.PF.002.IPE140 | B6: Piastra giunzione montanti centrali 200x100x4 (8 fori Ø 11) | C6: 0.624 | E6: =IF(ISNUMBER($C6),$C6*(1+IF(ISNUMBER($D6),$D6,0)),"") -> 0.624
A7: TTS.PF.003.IPE140 | B7: Piastra giunzione montanti esterna 240x70x6 (12 fori Ø 11) | C7: 0.7862 | E7: =IF(ISNUMBER($C7),$C7*(1+IF(ISNUMBER($D7),$D7,0)),"") -> 0.7862
A8: TTS.PF.004.IPE140 | B8: Piastra giunzione montanti interna 240x25x6 (6 fori Ø 11) | C8: 0.2808 | E8: =IF(ISNUMBER($C8),$C8*(1+IF(ISNUMBER($D8),$D8,0)),"") -> 0.2808
A9: TTS.AR.2011 | B9: Gaffa giunzione asse | C9: 5.075 | E9: =IF(ISNUMBER($C9),$C9*(1+IF(ISNUMBER($D9),$D9,0)),"") -> 5.075
A10: TTS.AR.4011 | B10: Supporto superiore inclinometro | C10: 0.8424 | E10: =IF(ISNUMBER($C10),$C10*(1+IF(ISNUMBER($D10),$D10,0)),"") -> 0.8424
A11: TTS.AR.4012 | B11: Supporto inferiore inclinometro | C11: 2.9484 | E11: =IF(ISNUMBER($C11),$C11*(1+IF(ISNUMBER($D11),$D11,0)),"") -> 2.9484
A12: TTS.AR.5011 | B12: Piastra ad L supporto fine corsa | C12: 0.2184 | E12: =IF(ISNUMBER($C12),$C12*(1+IF(ISNUMBER($D12),$D12,0)),"") -> 0.2184
A13: TTS.AR.5012 | B13: Leva battente sensore fine corsa | C13: 0.6524 | E13: =IF(ISNUMBER($C13),$C13*(1+IF(ISNUMBER($D13),$D13,0)),"") -> 0.6524
A14: TTS.PC.002.IPE140 | B14: Supporto laterale testa cuscinetto | C14: 2.1528 | E14: =IF(ISNUMBER($C14),$C14*(1+IF(ISNUMBER($D14),$D14,0)),"") -> 2.1528
A15: TTS.PC.003.IPE140 | B15: Supporto testa cuscinetto | C15: 2.7256 | E15: =IF(ISNUMBER($C15),$C15*(1+IF(ISNUMBER($D15),$D15,0)),"") -> 2.7256
A16: TTS.PC.2011.1076 | B16: Angolare 40x40x4 lungo 1076 mm. supporto inferiore | C16: 2.685696 | E16: =IF(ISNUMBER($C16),$C16*(1+IF(ISNUMBER($D16),$D16,0)),"") -> 2.685696
A17: TTS.PC.2012.1076 | B17: Angolare 40x40x4 lungo1076 mm. supporto superiore | C17: 2.685696 | E17: =IF(ISNUMBER($C17),$C17*(1+IF(ISNUMBER($D17),$D17,0)),"") -> 2.685696
... A27: TTS.SM.002 | B27: Piatto 30X3X193 leva sensore temperatura pannello | C27: 0.136355 | E27: =IF(ISNUMBER($C27),$C27*(1+IF(ISNUMBER($D27),$D27,0)),"") -> 0.136355
A28: TTS.SM.003 | B28: Asta supporto anemometro | E28: =IF(ISNUMBER($C28),$C28*(1+IF(ISNUMBER($D28),$D28,0)),"")
A36: PEZZI SPECIALI — elenco (descrizione, peso e costi richiamati dai parametri qui sopra)
A37: Codice | B37: Descrizione | C37: Voce | D37: Peso elemento (kg) | E37: Costo acquisto (€) | F37: Costo zincatura (€)
A38: TTS.PF.002.IPE140 | B38: =IFERROR(VLOOKUP($C38,$A$6:$G$28,2,FALSE),"") -> Piastra giunzione montanti centrali 200x100x4 (8 fori Ø 11) | C38: TTS.PF.002.IPE140 | D38: =IF(ISNUMBER(VLOOKUP($C38,$A$6:$G$28,5,FALSE)),VLOOKUP($C38,$A$6:$G$28,5,FALSE),"") -> 0.624 | E38: =IF(AND(ISNUMBER(VLOOKUP($C38,$A$6:$G$28,3,FALSE)),ISNUMBER(VLOOKUP($C38,$A$6:$G$28,6,FALSE))),VLOOKUP($C38,$A$6:$G$28,3,FALSE)*VLOOKUP($C38,$A$6:$G$28,6,FALSE),"") | F38: =IF(AND(ISNUMBER(VLOOKUP($C38,$A$6:$G$28,3,FALSE)),ISNUMBER(VLOOKUP($C38,$A$6:$G$28,4,FALSE)),VLOOKUP($C38,$A$6:$G$28,4,FALSE)>0,ISNUMBER(VLOOKUP($C38,$A$6:$G$28,7,FALSE))),VLOOKUP($C38,$A$6:$G$28,3,FALSE)*(1+VLOOKUP($C38,$A$6:$G$28,4,FALSE))*VLOOKUP($C38,$A$6:$G$28,7,FALSE),"")
A39: TTS.PF.003.IPE140 | B39: =IFERROR(VLOOKUP($C39,$A$6:$G$28,2,FALSE),"") -> Piastra giunzione montanti esterna 240x70x6 (12 fori Ø 11) | C39: TTS.PF.003.IPE140 | D39: =IF(ISNUMBER(VLOOKUP($C39,$A$6:$G$28,5,FALSE)),VLOOKUP($C39,$A$6:$G$28,5,FALSE),"") -> 0.7862 | E39: =IF(AND(ISNUMBER(VLOOKUP($C39,$A$6:$G$28,3,FALSE)),ISNUMBER(VLOOKUP($C39,$A$6:$G$28,6,FALSE))),VLOOKUP($C39,$A$6:$G$28,3,FALSE)*VLOOKUP($C39,$A$6:$G$28,6,FALSE),"") | F39: =IF(AND(ISNUMBER(VLOOKUP($C39,$A$6:$G$28,3,FALSE)),ISNUMBER(VLOOKUP($C39,$A$6:$G$28,4,FALSE)),VLOOKUP($C39,$A$6:$G$28,4,FALSE)>0,ISNUMBER(VLOOKUP($C39,$A$6:$G$28,7,FALSE))),VLOOKUP($C39,$A$6:$G$28,3,FALSE)*(1+VLOOKUP($C39,$A$6:$G$28,4,FALSE))*VLOOKUP($C39,$A$6:$G$28,7,FALSE),"")
A40: TTS.PF.004.IPE140 | B40: =IFERROR(VLOOKUP($C40,$A$6:$G$28,2,FALSE),"") -> Piastra giunzione montanti interna 240x25x6 (6 fori Ø 11) | C40: TTS.PF.004.IPE140 | D40: =IF(ISNUMBER(VLOOKUP($C40,$A$6:$G$28,5,FALSE)),VLOOKUP($C40,$A$6:$G$28,5,FALSE),"") -> 0.2808 | E40: =IF(AND(ISNUMBER(VLOOKUP($C40,$A$6:$G$28,3,FALSE)),ISNUMBER(VLOOKUP($C40,$A$6:$G$28,6,FALSE))),VLOOKUP($C40,$A$6:$G$28,3,FALSE)*VLOOKUP($C40,$A$6:$G$28,6,FALSE),"") | F40: =IF(AND(ISNUMBER(VLOOKUP($C40,$A$6:$G$28,3,FALSE)),ISNUMBER(VLOOKUP($C40,$A$6:$G$28,4,FALSE)),VLOOKUP($C40,$A$6:$G$28,4,FALSE)>0,ISNUMBER(VLOOKUP($C40,$A$6:$G$28,7,FALSE))),VLOOKUP($C40,$A$6:$G$28,3,FALSE)*(1+VLOOKUP($C40,$A$6:$G$28,4,FALSE))*VLOOKUP($C40,$A$6:$G$28,7,FALSE),"")
A41: TTS.AR.2011 | B41: =IFERROR(VLOOKUP($C41,$A$6:$G$28,2,FALSE),"") -> Gaffa giunzione asse | C41: TTS.AR.2011 | D41: =IF(ISNUMBER(VLOOKUP($C41,$A$6:$G$28,5,FALSE)),VLOOKUP($C41,$A$6:$G$28,5,FALSE),"") -> 5.075 | E41: =IF(AND(ISNUMBER(VLOOKUP($C41,$A$6:$G$28,3,FALSE)),ISNUMBER(VLOOKUP($C41,$A$6:$G$28,6,FALSE))),VLOOKUP($C41,$A$6:$G$28,3,FALSE)*VLOOKUP($C41,$A$6:$G$28,6,FALSE),"") | F41: =IF(AND(ISNUMBER(VLOOKUP($C41,$A$6:$G$28,3,FALSE)),ISNUMBER(VLOOKUP($C41,$A$6:$G$28,4,FALSE)),VLOOKUP($C41,$A$6:$G$28,4,FALSE)>0,ISNUMBER(VLOOKUP($C41,$A$6:$G$28,7,FALSE))),VLOOKUP($C41,$A$6:$G$28,3,FALSE)*(1+VLOOKUP($C41,$A$6:$G$28,4,FALSE))*VLOOKUP($C41,$A$6:$G$28,7,FALSE),"")
A42: TTS.AR.4011 | B42: =IFERROR(VLOOKUP($C42,$A$6:$G$28,2,FALSE),"") -> Supporto superiore inclinometro | C42: TTS.AR.4011 | D42: =IF(ISNUMBER(VLOOKUP($C42,$A$6:$G$28,5,FALSE)),VLOOKUP($C42,$A$6:$G$28,5,FALSE),"") -> 0.8424 | E42: =IF(AND(ISNUMBER(VLOOKUP($C42,$A$6:$G$28,3,FALSE)),ISNUMBER(VLOOKUP($C42,$A$6:$G$28,6,FALSE))),VLOOKUP($C42,$A$6:$G$28,3,FALSE)*VLOOKUP($C42,$A$6:$G$28,6,FALSE),"") | F42: =IF(AND(ISNUMBER(VLOOKUP($C42,$A$6:$G$28,3,FALSE)),ISNUMBER(VLOOKUP($C42,$A$6:$G$28,4,FALSE)),VLOOKUP($C42,$A$6:$G$28,4,FALSE)>0,ISNUMBER(VLOOKUP($C42,$A$6:$G$28,7,FALSE))),VLOOKUP($C42,$A$6:$G$28,3,FALSE)*(1+VLOOKUP($C42,$A$6:$G$28,4,FALSE))*VLOOKUP($C42,$A$6:$G$28,7,FALSE),"")
A43: TTS.AR.4012 | B43: =IFERROR(VLOOKUP($C43,$A$6:$G$28,2,FALSE),"") -> Supporto inferiore inclinometro | C43: TTS.AR.4012 | D43: =IF(ISNUMBER(VLOOKUP($C43,$A$6:$G$28,5,FALSE)),VLOOKUP($C43,$A$6:$G$28,5,FALSE),"") -> 2.9484 | E43: =IF(AND(ISNUMBER(VLOOKUP($C43,$A$6:$G$28,3,FALSE)),ISNUMBER(VLOOKUP($C43,$A$6:$G$28,6,FALSE))),VLOOKUP($C43,$A$6:$G$28,3,FALSE)*VLOOKUP($C43,$A$6:$G$28,6,FALSE),"") | F43: =IF(AND(ISNUMBER(VLOOKUP($C43,$A$6:$G$28,3,FALSE)),ISNUMBER(VLOOKUP($C43,$A$6:$G$28,4,FALSE)),VLOOKUP($C43,$A$6:$G$28,4,FALSE)>0,ISNUMBER(VLOOKUP($C43,$A$6:$G$28,7,FALSE))),VLOOKUP($C43,$A$6:$G$28,3,FALSE)*(1+VLOOKUP($C43,$A$6:$G$28,4,FALSE))*VLOOKUP($C43,$A$6:$G$28,7,FALSE),"")
A44: TTS.AR.5011 | B44: =IFERROR(VLOOKUP($C44,$A$6:$G$28,2,FALSE),"") -> Piastra ad L supporto fine corsa | C44: TTS.AR.5011 | D44: =IF(ISNUMBER(VLOOKUP($C44,$A$6:$G$28,5,FALSE)),VLOOKUP($C44,$A$6:$G$28,5,FALSE),"") -> 0.2184 | E44: =IF(AND(ISNUMBER(VLOOKUP($C44,$A$6:$G$28,3,FALSE)),ISNUMBER(VLOOKUP($C44,$A$6:$G$28,6,FALSE))),VLOOKUP($C44,$A$6:$G$28,3,FALSE)*VLOOKUP($C44,$A$6:$G$28,6,FALSE),"") | F44: =IF(AND(ISNUMBER(VLOOKUP($C44,$A$6:$G$28,3,FALSE)),ISNUMBER(VLOOKUP($C44,$A$6:$G$28,4,FALSE)),VLOOKUP($C44,$A$6:$G$28,4,FALSE)>0,ISNUMBER(VLOOKUP($C44,$A$6:$G$28,7,FALSE))),VLOOKUP($C44,$A$6:$G$28,3,FALSE)*(1+VLOOKUP($C44,$A$6:$G$28,4,FALSE))*VLOOKUP($C44,$A$6:$G$28,7,FALSE),"")
A45: TTS.AR.5012 | B45: =IFERROR(VLOOKUP($C45,$A$6:$G$28,2,FALSE),"") -> Leva battente sensore fine corsa | C45: TTS.AR.5012 | D45: =IF(ISNUMBER(VLOOKUP($C45,$A$6:$G$28,5,FALSE)),VLOOKUP($C45,$A$6:$G$28,5,FALSE),"") -> 0.6524 | E45: =IF(AND(ISNUMBER(VLOOKUP($C45,$A$6:$G$28,3,FALSE)),ISNUMBER(VLOOKUP($C45,$A$6:$G$28,6,FALSE))),VLOOKUP($C45,$A$6:$G$28,3,FALSE)*VLOOKUP($C45,$A$6:$G$28,6,FALSE),"") | F45: =IF(AND(ISNUMBER(VLOOKUP($C45,$A$6:$G$28,3,FALSE)),ISNUMBER(VLOOKUP($C45,$A$6:$G$28,4,FALSE)),VLOOKUP($C45,$A$6:$G$28,4,FALSE)>0,ISNUMBER(VLOOKUP($C45,$A$6:$G$28,7,FALSE))),VLOOKUP($C45,$A$6:$G$28,3,FALSE)*(1+VLOOKUP($C45,$A$6:$G$28,4,FALSE))*VLOOKUP($C45,$A$6:$G$28,7,FALSE),"")
A46: TTS.PC.002.IPE140 | B46: =IFERROR(VLOOKUP($C46,$A$6:$G$28,2,FALSE),"") -> Supporto laterale testa cuscinetto | C46: TTS.PC.002.IPE140 | D46: =IF(ISNUMBER(VLOOKUP($C46,$A$6:$G$28,5,FALSE)),VLOOKUP($C46,$A$6:$G$28,5,FALSE),"") -> 2.1528 | E46: =IF(AND(ISNUMBER(VLOOKUP($C46,$A$6:$G$28,3,FALSE)),ISNUMBER(VLOOKUP($C46,$A$6:$G$28,6,FALSE))),VLOOKUP($C46,$A$6:$G$28,3,FALSE)*VLOOKUP($C46,$A$6:$G$28,6,FALSE),"") | F46: =IF(AND(ISNUMBER(VLOOKUP($C46,$A$6:$G$28,3,FALSE)),ISNUMBER(VLOOKUP($C46,$A$6:$G$28,4,FALSE)),VLOOKUP($C46,$A$6:$G$28,4,FALSE)>0,ISNUMBER(VLOOKUP($C46,$A$6:$G$28,7,FALSE))),VLOOKUP($C46,$A$6:$G$28,3,FALSE)*(1+VLOOKUP($C46,$A$6:$G$28,4,FALSE))*VLOOKUP($C46,$A$6:$G$28,7,FALSE),"")
A47: TTS.PC.003.IPE140 | B47: =IFERROR(VLOOKUP($C47,$A$6:$G$28,2,FALSE),"") -> Supporto testa cuscinetto | C47: TTS.PC.003.IPE140 | D47: =IF(ISNUMBER(VLOOKUP($C47,$A$6:$G$28,5,FALSE)),VLOOKUP($C47,$A$6:$G$28,5,FALSE),"") -> 2.7256 | E47: =IF(AND(ISNUMBER(VLOOKUP($C47,$A$6:$G$28,3,FALSE)),ISNUMBER(VLOOKUP($C47,$A$6:$G$28,6,FALSE))),VLOOKUP($C47,$A$6:$G$28,3,FALSE)*VLOOKUP($C47,$A$6:$G$28,6,FALSE),"") | F47: =IF(AND(ISNUMBER(VLOOKUP($C47,$A$6:$G$28,3,FALSE)),ISNUMBER(VLOOKUP($C47,$A$6:$G$28,4,FALSE)),VLOOKUP($C47,$A$6:$G$28,4,FALSE)>0,ISNUMBER(VLOOKUP($C47,$A$6:$G$28,7,FALSE))),VLOOKUP($C47,$A$6:$G$28,3,FALSE)*(1+VLOOKUP($C47,$A$6:$G$28,4,FALSE))*VLOOKUP($C47,$A$6:$G$28,7,FALSE),"")
A48: TTS.PC.2011.1076 | B48: =IFERROR(VLOOKUP($C48,$A$6:$G$28,2,FALSE),"") -> Angolare 40x40x4 lungo 1076 mm. supporto inferiore | C48: TTS.PC.2011.1076 | D48: =IF(ISNUMBER(VLOOKUP($C48,$A$6:$G$28,5,FALSE)),VLOOKUP($C48,$A$6:$G$28,5,FALSE),"") -> 2.685696 | E48: =IF(AND(ISNUMBER(VLOOKUP($C48,$A$6:$G$28,3,FALSE)),ISNUMBER(VLOOKUP($C48,$A$6:$G$28,6,FALSE))),VLOOKUP($C48,$A$6:$G$28,3,FALSE)*VLOOKUP($C48,$A$6:$G$28,6,FALSE),"") | F48: =IF(AND(ISNUMBER(VLOOKUP($C48,$A$6:$G$28,3,FALSE)),ISNUMBER(VLOOKUP($C48,$A$6:$G$28,4,FALSE)),VLOOKUP($C48,$A$6:$G$28,4,FALSE)>0,ISNUMBER(VLOOKUP($C48,$A$6:$G$28,7,FALSE))),VLOOKUP($C48,$A$6:$G$28,3,FALSE)*(1+VLOOKUP($C48,$A$6:$G$28,4,FALSE))*VLOOKUP($C48,$A$6:$G$28,7,FALSE),"")
A49: TTS.PC.2012.1076 | B49: =IFERROR(VLOOKUP($C49,$A$6:$G$28,2,FALSE),"") -> Angolare 40x40x4 lungo1076 mm. supporto superiore | C49: TTS.PC.2012.1076 | D49: =IF(ISNUMBER(VLOOKUP($C49,$A$6:$G$28,5,FALSE)),VLOOKUP($C49,$A$6:$G$28,5,FALSE),"") -> 2.685696 | E49: =IF(AND(ISNUMBER(VLOOKUP($C49,$A$6:$G$28,3,FALSE)),ISNUMBER(VLOOKUP($C49,$A$6:$G$28,6,FALSE))),VLOOKUP($C49,$A$6:$G$28,3,FALSE)*VLOOKUP($C49,$A$6:$G$28,6,FALSE),"") | F49: =IF(AND(ISNUMBER(VLOOKUP($C49,$A$6:$G$28,3,FALSE)),ISNUMBER(VLOOKUP($C49,$A$6:$G$28,4,FALSE)),VLOOKUP($C49,$A$6:$G$28,4,FALSE)>0,ISNUMBER(VLOOKUP($C49,$A$6:$G$28,7,FALSE))),VLOOKUP($C49,$A$6:$G$28,3,FALSE)*(1+VLOOKUP($C49,$A$6:$G$28,4,FALSE))*VLOOKUP($C49,$A$6:$G$28,7,FALSE),"")
... A60: TTS.SM.003 | B60: =IFERROR(VLOOKUP($C60,$A$6:$G$28,2,FALSE),"") -> Asta supporto anemometro | C60: TTS.SM.003 | D60: =IF(ISNUMBER(VLOOKUP($C60,$A$6:$G$28,5,FALSE)),VLOOKUP($C60,$A$6:$G$28,5,FALSE),"") | E60: =IF(AND(ISNUMBER(VLOOKUP($C60,$A$6:$G$28,3,FALSE)),ISNUMBER(VLOOKUP($C60,$A$6:$G$28,6,FALSE))),VLOOKUP($C60,$A$6:$G$28,3,FALSE)*VLOOKUP($C60,$A$6:$G$28,6,FALSE),"") | F60: =IF(AND(ISNUMBER(VLOOKUP($C60,$A$6:$G$28,3,FALSE)),ISNUMBER(VLOOKUP($C60,$A$6:$G$28,4,FALSE)),VLOOKUP($C60,$A$6:$G$28,4,FALSE)>0,ISNUMBER(VLOOKUP($C60,$A$6:$G$28,7,FALSE))),VLOOKUP($C60,$A$6:$G$28,3,FALSE)*(1+VLOOKUP($C60,$A$6:$G$28,4,FALSE))*VLOOKUP($C60,$A$6:$G$28,7,FALSE),"")

Sheet SCHEDA BULLONERIA
A1: SCHEDA BULLONERIA — peso unitario e costo dei minuteria/bulloneria commerciale (bulloni, dadi, rondelle)
A2: Un rigo per codice nel blocco 'Parametri'. Peso unitario (kg) pre-compilato con valori nominali da tabelle standard (DIN 933/931 bulloni, DIN 985 dadi autobloccanti, DIN 125A rondelle) — da confermare/aggiornare a mano. Compilare il Costo (€/pz). Nel blocco 'Elenco' peso e costo sono richiamati via VLOOKUP; il LISTINO pesca da qui 'Peso elemento (kg)' e 'Prezzo unitario €'.
A4: BULLONERIA — parametri (confermare Peso unitario, compilare Costo €/pz)
A5: Codice | B5: Descrizione | C5: Peso unitario (kg) | D5: Costo (€/pz)
A6: 06TAP120X120 | B6: Tappo profilato 120x120
A7: 10BZ10X30 | B7: Bullone testa esagonale M10X30 | C7: 0.0245
A8: 10BZ10X40 | B8: Bullone testa esagonale zn M10X40 | C8: 0.0305
A9: 10BZ16X140 | B9: Bullone testa esagonale M16x140 mezzo filetto | C9: 0.21
A10: 10BZM10X160 | B10: Bullone testa esagonale zn M10X160 | C10: 0.095
A11: 10BZM10X30 | B11: Bullone testa esagonale zn M10X30 | C11: 0.0245
A12: 10BZM10X40 | B12: Bullone testa esagonale M10X40 | C12: 0.0305
A13: 10BZM16X25 | B13: Bullone testa esagonale zn M16X25 | C13: 0.052
A14: 10BZM16X60 | B14: Bullone testa esagonale M16X60 | C14: 0.11
A15: 10BZM5X20 | B15: Bullone testa esagonale zn M5x20 | C15: 0.0031
A16: 10BZM5X30 | B16: Bullone testa esagonale zn M5x30 | C16: 0.0042
A17: 10BZM6X150 | B17: Bullone testa esagonale zn M6X150 | C17: 0.026
A18: 10BZM6X20 | B18: Bullone testa esagonale zn M6X20 | C18: 0.0054
... A36: M5X30 8.8 ISO1207 | B36: Bullone testa esagonale con intaglio M5x30 | C36: 0.0042
A38: BULLONERIA — elenco (peso e costo richiamati dai parametri qui sopra)
A39: Codice | B39: Descrizione | C39: Peso elemento (kg) | D39: Costo (€)
A40: 06TAP120X120 | B40: =IFERROR(VLOOKUP($A40,$A$6:$D$36,2,FALSE),"") -> Tappo profilato 120x120 | C40: =IF(ISNUMBER(VLOOKUP($A40,$A$6:$D$36,3,FALSE)),VLOOKUP($A40,$A$6:$D$36,3,FALSE),"") | D40: =IF(ISNUMBER(VLOOKUP($A40,$A$6:$D$36,4,FALSE)),VLOOKUP($A40,$A$6:$D$36,4,FALSE),"")
A41: 10BZ10X30 | B41: =IFERROR(VLOOKUP($A41,$A$6:$D$36,2,FALSE),"") -> Bullone testa esagonale M10X30 | C41: =IF(ISNUMBER(VLOOKUP($A41,$A$6:$D$36,3,FALSE)),VLOOKUP($A41,$A$6:$D$36,3,FALSE),"") -> 0.0245 | D41: =IF(ISNUMBER(VLOOKUP($A41,$A$6:$D$36,4,FALSE)),VLOOKUP($A41,$A$6:$D$36,4,FALSE),"")
A42: 10BZ10X40 | B42: =IFERROR(VLOOKUP($A42,$A$6:$D$36,2,FALSE),"") -> Bullone testa esagonale zn M10X40 | C42: =IF(ISNUMBER(VLOOKUP($A42,$A$6:$D$36,3,FALSE)),VLOOKUP($A42,$A$6:$D$36,3,FALSE),"") -> 0.0305 | D42: =IF(ISNUMBER(VLOOKUP($A42,$A$6:$D$36,4,FALSE)),VLOOKUP($A42,$A$6:$D$36,4,FALSE),"")
A43: 10BZ16X140 | B43: =IFERROR(VLOOKUP($A43,$A$6:$D$36,2,FALSE),"") -> Bullone testa esagonale M16x140 mezzo filetto | C43: =IF(ISNUMBER(VLOOKUP($A43,$A$6:$D$36,3,FALSE)),VLOOKUP($A43,$A$6:$D$36,3,FALSE),"") -> 0.21 | D43: =IF(ISNUMBER(VLOOKUP($A43,$A$6:$D$36,4,FALSE)),VLOOKUP($A43,$A$6:$D$36,4,FALSE),"")
A44: 10BZM10X160 | B44: =IFERROR(VLOOKUP($A44,$A$6:$D$36,2,FALSE),"") -> Bullone testa esagonale zn M10X160 | C44: =IF(ISNUMBER(VLOOKUP($A44,$A$6:$D$36,3,FALSE)),VLOOKUP($A44,$A$6:$D$36,3,FALSE),"") -> 0.095 | D44: =IF(ISNUMBER(VLOOKUP($A44,$A$6:$D$36,4,FALSE)),VLOOKUP($A44,$A$6:$D$36,4,FALSE),"")
A45: 10BZM10X30 | B45: =IFERROR(VLOOKUP($A45,$A$6:$D$36,2,FALSE),"") -> Bullone testa esagonale zn M10X30 | C45: =IF(ISNUMBER(VLOOKUP($A45,$A$6:$D$36,3,FALSE)),VLOOKUP($A45,$A$6:$D$36,3,FALSE),"") -> 0.0245 | D45: =IF(ISNUMBER(VLOOKUP($A45,$A$6:$D$36,4,FALSE)),VLOOKUP($A45,$A$6:$D$36,4,FALSE),"")
A46: 10BZM10X40 | B46: =IFERROR(VLOOKUP($A46,$A$6:$D$36,2,FALSE),"") -> Bullone testa esagonale M10X40 | C46: =IF(ISNUMBER(VLOOKUP($A46,$A$6:$D$36,3,FALSE)),VLOOKUP($A46,$A$6:$D$36,3,FALSE),"") -> 0.0305 | D46: =IF(ISNUMBER(VLOOKUP($A46,$A$6:$D$36,4,FALSE)),VLOOKUP($A46,$A$6:$D$36,4,FALSE),"")
A47: 10BZM16X25 | B47: =IFERROR(VLOOKUP($A47,$A$6:$D$36,2,FALSE),"") -> Bullone testa esagonale zn M16X25 | C47: =IF(ISNUMBER(VLOOKUP($A47,$A$6:$D$36,3,FALSE)),VLOOKUP($A47,$A$6:$D$36,3,FALSE),"") -> 0.052 | D47: =IF(ISNUMBER(VLOOKUP($A47,$A$6:$D$36,4,FALSE)),VLOOKUP($A47,$A$6:$D$36,4,FALSE),"")
A48: 10BZM16X60 | B48: =IFERROR(VLOOKUP($A48,$A$6:$D$36,2,FALSE),"") -> Bullone testa esagonale M16X60 | C48: =IF(ISNUMBER(VLOOKUP($A48,$A$6:$D$36,3,FALSE)),VLOOKUP($A48,$A$6:$D$36,3,FALSE),"") -> 0.11 | D48: =IF(ISNUMBER(VLOOKUP($A48,$A$6:$D$36,4,FALSE)),VLOOKUP($A48,$A$6:$D$36,4,FALSE),"")
A49: 10BZM5X20 | B49: =IFERROR(VLOOKUP($A49,$A$6:$D$36,2,FALSE),"") -> Bullone testa esagonale zn M5x20 | C49: =IF(ISNUMBER(VLOOKUP($A49,$A$6:$D$36,3,FALSE)),VLOOKUP($A49,$A$6:$D$36,3,FALSE),"") -> 0.0031 | D49: =IF(ISNUMBER(VLOOKUP($A49,$A$6:$D$36,4,FALSE)),VLOOKUP($A49,$A$6:$D$36,4,FALSE),"")
A50: 10BZM5X30 | B50: =IFERROR(VLOOKUP($A50,$A$6:$D$36,2,FALSE),"") -> Bullone testa esagonale zn M5x30 | C50: =IF(ISNUMBER(VLOOKUP($A50,$A$6:$D$36,3,FALSE)),VLOOKUP($A50,$A$6:$D$36,3,FALSE),"") -> 0.0042 | D50: =IF(ISNUMBER(VLOOKUP($A50,$A$6:$D$36,4,FALSE)),VLOOKUP($A50,$A$6:$D$36,4,FALSE),"")
A51: 10BZM6X150 | B51: =IFERROR(VLOOKUP($A51,$A$6:$D$36,2,FALSE),"") -> Bullone testa esagonale zn M6X150 | C51: =IF(ISNUMBER(VLOOKUP($A51,$A$6:$D$36,3,FALSE)),VLOOKUP($A51,$A$6:$D$36,3,FALSE),"") -> 0.026 | D51: =IF(ISNUMBER(VLOOKUP($A51,$A$6:$D$36,4,FALSE)),VLOOKUP($A51,$A$6:$D$36,4,FALSE),"")
... A70: M5X30 8.8 ISO1207 | B70: =IFERROR(VLOOKUP($A70,$A$6:$D$36,2,FALSE),"") -> Bullone testa esagonale con intaglio M5x30 | C70: =IF(ISNUMBER(VLOOKUP($A70,$A$6:$D$36,3,FALSE)),VLOOKUP($A70,$A$6:$D$36,3,FALSE),"") -> 0.0042 | D70: =IF(ISNUMBER(VLOOKUP($A70,$A$6:$D$36,4,FALSE)),VLOOKUP($A70,$A$6:$D$36,4,FALSE),"")

Sheet SCHEDA ELETTROMECCANICA
A1: SCHEDA ELETTROMECCANICA — peso unitario e costo dei materiali elettromeccanici commerciali
A2: Motoriduttore, cuscinetto asse, quadri/box, sensori e strumentazione. Articoli acquistati completi: compilare a mano 'Peso unitario (kg)' e 'Costo (€/pz)'. Il LISTINO pesca da qui 'Peso elemento (kg)' e 'Prezzo unitario €' per questi codici.
A4: Codice | B4: Descrizione | C4: Peso unitario (kg) | D4: Costo (€/pz)
A5: CHSD7-60-S112-24.15.300-L1.2 | B5: Motoriduttore | C5: 50 | D5: 300
A6: ESQM_2_0_120_1 | B6: Cuscinetto asse di rotazione | C6: 2 | D6: 13
A7: 15T-JUNCTBOXIP65 | B7: Box centralina meteo
A8: B04601 | B8: Quadro in vetroresina Pedro VTR 01
A9: 10S-FC | B9: Sensore fine corsa elettrico
A10: 15T-PIRANOMETRO | B10: Piranometro
A11: 15T-SENSVELVEN | B11: Anemometro
A12: 15T-TERMARIA | B12: Termometro Aria_ mSTA.l
A13: 15T-TERMCONTP10 | B13: Termometro a contatto P100_STC-i
A14: TK1024S | B14: Inclinometro

Sheet LISTINO
A1: LISTINO COMPONENTI — Tracker TTS moduli 1303 (rev. 5)
A2: Elenco unico di tutti i componenti presenti nella distinta materiali. Compilare la colonna 'Prezzo unitario' per ottenere un listino valorizzato.
A4: N° | B4: Codice | C4: Descrizione | D4: Categoria | E4: U.M. | F4: Peso elemento (kg) | G4: Prezzo unitario € | H4: Presente nei kit / assiemi | I4: N° righe distinta
A5: 1 | B5: TTS.AR.001.7200 | C5: Asse lato motore 120x120x3 mm. lunghezza mt.7,20 | D5: Carpenteria metallica | E5: pz | F5: =IFERROR(VLOOKUP($B5,'SCHEDA STRUTTURA'!$A$13:$E$413,5,FALSE),"") -> 84.96 | H5: ASSI DI ROTAZIONE 1303 | I5: 2
A6: 2 | B6: TTS.AR.001.7200.25 | C6: Asse lato motore 120x120x2,5 mm. lunghezza mt.7,20 | D6: Carpenteria metallica | E6: pz | F6: =IFERROR(VLOOKUP($B6,'SCHEDA STRUTTURA'!$A$13:$E$413,5,FALSE),"") -> 66.24 | H6: ASSI DI ROTAZIONE 1303 | I6: 1
A7: 3 | B7: TTS.AR.001.8250 | C7: Asse lato motore 120x120x3 mm. lunghezza mt.8,25 | D7: Carpenteria metallica | E7: pz | F7: =IFERROR(VLOOKUP($B7,'SCHEDA STRUTTURA'!$A$13:$E$413,5,FALSE),"") -> 97.35 | H7: ASSI DI ROTAZIONE 1303 | I7: 1
A8: 4 | B8: TTS.AR.001.8250.25 | C8: Asse lato motore 120x120x2,5 mm. lunghezza mt.8,25 | D8: Carpenteria metallica | E8: pz | F8: =IFERROR(VLOOKUP($B8,'SCHEDA STRUTTURA'!$A$13:$E$413,5,FALSE),"") -> 75.9 | H8: ASSI DI ROTAZIONE 1303 | I8: 1
A9: 5 | B9: TTS.AR.001.8700 | C9: Asse lato motore 120x120x3 mm. lunghezza mt.8,70 | D9: Carpenteria metallica | E9: pz | F9: =IFERROR(VLOOKUP($B9,'SCHEDA STRUTTURA'!$A$13:$E$413,5,FALSE),"") -> 102.66 | H9: ASSI DI ROTAZIONE 1303 | I9: 3
A10: 6 | B10: TTS.AR.001.8700.25 | C10: Asse lato motore 120x120x2,5 mm. lunghezza mt.8,70 | D10: Carpenteria metallica | E10: pz | F10: =IFERROR(VLOOKUP($B10,'SCHEDA STRUTTURA'!$A$13:$E$413,5,FALSE),"") -> 80.04 | H10: ASSI DI ROTAZIONE 1303 | I10: 1
A11: 7 | B11: TTS.AR.002.5000 | C11: Asse esterno 120x120x3 mm. lunghezza mt.5,00 | D11: Carpenteria metallica | E11: pz | F11: =IFERROR(VLOOKUP($B11,'SCHEDA STRUTTURA'!$A$13:$E$413,5,FALSE),"") -> 59 | H11: ASSI DI ROTAZIONE 1303 | I11: 1
A12: 8 | B12: TTS.AR.002.5000.25 | C12: Asse esterno 120x120x2,5 mm. lunghezza mt.5,00 | D12: Carpenteria metallica | E12: pz | F12: =IFERROR(VLOOKUP($B12,'SCHEDA STRUTTURA'!$A$13:$E$413,5,FALSE),"") -> 46 | H12: ASSI DI ROTAZIONE 1303 | I12: 1
A13: 9 | B13: TTS.AR.002.6150 | C13: Asse esterno 120x120x3 mm. lunghezza mt.6,15 | D13: Carpenteria metallica | E13: pz | F13: =IFERROR(VLOOKUP($B13,'SCHEDA STRUTTURA'!$A$13:$E$413,5,FALSE),"") -> 72.57 | H13: ASSI DI ROTAZIONE 1303 | I13: 1
A14: 10 | B14: TTS.AR.002.6150.25 | C14: Asse esterno 120x120x2,5 mm. lunghezza mt.6,15 | D14: Carpenteria metallica | E14: pz | F14: =IFERROR(VLOOKUP($B14,'SCHEDA STRUTTURA'!$A$13:$E$413,5,FALSE),"") -> 56.58 | H14: ASSI DI ROTAZIONE 1303 | I14: 1
A15: 11 | B15: TTS.AR.002.6300 | C15: Asse esterno 120x120x3 mm. lunghezza mt.6,30 | D15: Carpenteria metallica | E15: pz | F15: =IFERROR(VLOOKUP($B15,'SCHEDA STRUTTURA'!$A$13:$E$413,5,FALSE),"") -> 74.34 | H15: ASSI DI ROTAZIONE 1303 | I15: 1
A16: 12 | B16: TTS.AR.002.6300.25 | C16: Asse esterno 120x120x2,5 mm. lunghezza mt.6,30 | D16: Carpenteria metallica | E16: pz | F16: =IFERROR(VLOOKUP($B16,'SCHEDA STRUTTURA'!$A$13:$E$413,5,FALSE),"") -> 57.96 | H16: ASSI DI ROTAZIONE 1303 | I16: 1
... A26: 22 | B26: TTS.AR.004.4800.25 | C26: Asse esterno 120x120x2,5 mm. lunghezza mt.4,800 | D26: Carpenteria metallica | E26: pz | F26: =IFERROR(VLOOKUP($B26,'SCHEDA STRUTTURA'!$A$13:$E$413,5,FALSE),"") -> 44.16 | H26: ASSI DI ROTAZIONE 1303 | I26: 1
A27: 23 | B27: TTS.AR.2011 | C27: Gaffa giunzione asse | D27: Carpenteria metallica | E27: pz | F27: =IFERROR(VLOOKUP($B27,'SCHEDA PEZZI SPECIALI'!$A$38:$F$400,4,FALSE),"") -> 5.075 | H27: ASSI DI ROTAZIONE 1303 | I27: 5
A28: 24 | B28: TTS.AR.3011 | C28: Supporto a L superiore omega | D28: Carpenteria metallica | E28: pz | F28: =IFERROR(VLOOKUP($B28,'SCHEDA STRUTTURA'!$A$13:$E$413,5,FALSE),"") -> 0.8568 | H28: KIT OMEGA+pannelli | I28: 1
A29: 25 | B29: TTS.AR.3012 | C29: Supporto a V inferiore omega | D29: Carpenteria metallica | E29: pz | F29: =IFERROR(VLOOKUP($B29,'SCHEDA STRUTTURA'!$A$13:$E$413,5,FALSE),"") -> 0.4095 | H29: KIT OMEGA+pannelli | I29: 1
A30: 26 | B30: TTS.AR.3013 | C30: Gaffa sotto omega | D30: Carpenteria metallica | E30: pz | F30: =IFERROR(VLOOKUP($B30,'SCHEDA STRUTTURA'!$A$13:$E$413,5,FALSE),"") -> 1.278 | H30: KIT OMEGA+pannelli | I30: 1
A31: 27 | B31: TTS.AR.3014 | C31: Omega supporto pannello | D31: Carpenteria metallica | E31: pz | F31: =IFERROR(VLOOKUP($B31,'SCHEDA STRUTTURA'!$A$13:$E$413,5,FALSE),"") -> 5.85 | H31: KIT OMEGA+pannelli | I31: 1
A32: 28 | B32: TTS.AR.3014.18 | C32: Omega supporto pannello mm1,8 | D32: Carpenteria metallica | E32: pz | F32: =IFERROR(VLOOKUP($B32,'SCHEDA STRUTTURA'!$A$13:$E$413,5,FALSE),"") -> 5.265 | H32: KIT OMEGA+pannelli | I32: 1
A33: 29 | B33: TTS.AR.4011 | C33: Supporto superiore inclinometro | D33: Carpenteria metallica | E33: pz | F33: =IFERROR(VLOOKUP($B33,'SCHEDA PEZZI SPECIALI'!$A$38:$F$400,4,FALSE),"") -> 0.8424 | H33: KIT INCLINOMETRO | I33: 1
A34: 30 | B34: TTS.AR.4012 | C34: Supporto inferiore inclinometro | D34: Carpenteria metallica | E34: pz | F34: =IFERROR(VLOOKUP($B34,'SCHEDA PEZZI SPECIALI'!$A$38:$F$400,4,FALSE),"") -> 2.9484 | H34: KIT INCLINOMETRO | I34: 1
A35: 31 | B35: TTS.AR.5011 | C35: Piastra ad L supporto fine corsa | D35: Carpenteria metallica | E35: pz | F35: =IFERROR(VLOOKUP($B35,'SCHEDA PEZZI SPECIALI'!$A$38:$F$400,4,FALSE),"") -> 0.2184 | H35: KIT FINE CORSA | I35: 1
A36: 32 | B36: TTS.AR.5012 | C36: Leva battente sensore fine corsa | D36: Carpenteria metallica | E36: pz | F36: =IFERROR(VLOOKUP($B36,'SCHEDA PEZZI SPECIALI'!$A$38:$F$400,4,FALSE),"") -> 0.6524 | H36: KIT FINE CORSA | I36: 1
A37: 33 | B37: TTS.PC.001.IPE140.23 | C37: Pilastro cuscinetto trave IPE 140 mt.2,30 | D37: Carpenteria metallica | E37: pz | F37: =IFERROR(VLOOKUP($B37,'SCHEDA STRUTTURA'!$A$13:$E$413,5,FALSE),"") -> 29.67 | H37: PILASTRO CUSCINETTO | I37: 1
A38: 34 | B38: TTS.PC.001.IPEA140.23 | C38: Pilastro cuscinetto trave IPEA 140 mt.2,30 (alleggerita) | D38: Carpenteria metallica | E38: pz | F38: =IFERROR(VLOOKUP($B38,'SCHEDA STRUTTURA'!$A$13:$E$413,5,FALSE),"") -> 25.07 | H38: PILASTRO CUSCINETTO | I38: 1
A39: 35 | B39: TTS.PC.001.IPE140.28 | C39: Pilastro cuscinetto trave IPE 140 mt.2,80 | D39: Carpenteria metallica | E39: pz | F39: =IFERROR(VLOOKUP($B39,'SCHEDA STRUTTURA'!$A$13:$E$413,5,FALSE),"") -> 36.12 | H39: PILASTRO CUSCINETTO | I39: 1
A40: 36 | B40: TTS.PC.001.IPEA140.28 | C40: Pilastro cuscinetto trave IPEA 140 mt.2,80 (alleggerita) | D40: Carpenteria metallica | E40: pz | F40: =IFERROR(VLOOKUP($B40,'SCHEDA STRUTTURA'!$A$13:$E$413,5,FALSE),"") -> 30.52 | H40: PILASTRO CUSCINETTO | I40: 1
A41: 37 | B41: TTS.PC.001.IPE140.29 | C41: Pilastro cuscinetto trave IPE 140 mt.2,90 | D41: Carpenteria metallica | E41: pz | F41: =IFERROR(VLOOKUP($B41,'SCHEDA STRUTTURA'!$A$13:$E$413,5,FALSE),"") -> 37.41 | H41: PILASTRO CUSCINETTO | I41: 1
A42: 38 | B42: TTS.PC.001.IPEA140.29 | C42: Pilastro cuscinetto trave IPEA 140 mt.2,90 (alleggerita) | D42: Carpenteria metallica | E42: pz | F42: =IFERROR(VLOOKUP($B42,'SCHEDA STRUTTURA'!$A$13:$E$413,5,FALSE),"") -> 31.61 | H42: PILASTRO CUSCINETTO | I42: 1
A43: 39 | B43: TTS.PC.001.IPE140.30 | C43: Pilastro cuscinetto trave IPE 140 mt.3,00 | D43: Carpenteria metallica | E43: pz | F43: =IFERROR(VLOOKUP($B43,'SCHEDA STRUTTURA'!$A$13:$E$413,5,FALSE),"") -> 38.7 | H43: PILASTRO CUSCINETTO | I43: 1
A44: 40 | B44: TTS.PC.001.IPEA140.30 | C44: Pilastro cuscinetto trave IPEA 140 mt.3,00 (alleggerita) | D44: Carpenteria metallica | E44: pz | F44: =IFERROR(VLOOKUP($B44,'SCHEDA STRUTTURA'!$A$13:$E$413,5,FALSE),"") -> 32.7 | H44: PILASTRO CUSCINETTO | I44: 1
A45: 41 | B45: TTS.PC.001.IPE140.31 | C45: Pilastro cuscinetto trave IPE 140 mt.3,10 | D45: Carpenteria metallica | E45: pz | F45: =IFERROR(VLOOKUP($B45,'SCHEDA STRUTTURA'!$A$13:$E$413,5,FALSE),"") -> 39.99 | H45: PILASTRO CUSCINETTO | I45: 1
A46: 42 | B46: TTS.PC.001.IPEA140.31 | C46: Pilastro cuscinetto trave IPEA 140 mt.3,10 (alleggerita) | D46: Carpenteria metallica | E46: pz | F46: =IFERROR(VLOOKUP($B46,'SCHEDA STRUTTURA'!$A$13:$E$413,5,FALSE),"") -> 33.79 | H46: PILASTRO CUSCINETTO | I46: 1
A47: 43 | B47: TTS.PC.001.IPE140.32 | C47: Pilastro cuscinetto trave IPE 140 mt.3,20 | D47: Carpenteria metallica | E47: pz | F47: =IFERROR(VLOOKUP($B47,'SCHEDA STRUTTURA'!$A$13:$E$413,5,FALSE),"") -> 41.28 | H47: PILASTRO CUSCINETTO | I47: 1
A48: 44 | B48: TTS.PC.001.IPEA140.32 | C48: Pilastro cuscinetto trave IPEA 140 mt.3,20 (alleggerita) | D48: Carpenteria metallica | E48: pz | F48: =IFERROR(VLOOKUP($B48,'SCHEDA STRUTTURA'!$A$13:$E$413,5,FALSE),"") -> 34.88 | H48: PILASTRO CUSCINETTO | I48: 1
... A78: 74 | B78: TTS.PC.001.IPEA140.23.FQA | C78: Pilastro cuscinetto trave ipea140 x mt. 2,30 con foratura alloggiamento quadro area (alleggerita) | D78: Carpenteria metallica | E78: pz | F78: =IFERROR(VLOOKUP($B78,'SCHEDA STRUTTURA'!$A$13:$E$413,5,FALSE),"") -> 25.07 | H78: kit quadri area | I78: 1
A79: 75 | B79: TTS.PC.002.IPE140 | C79: Supporto laterale testa cuscinetto | D79: Carpenteria metallica | E79: pz | F79: =IFERROR(VLOOKUP($B79,'SCHEDA PEZZI SPECIALI'!$A$38:$F$400,4,FALSE),"") -> 2.1528 | H79: PILASTRO CUSCINETTO | I79: 1
...

Sheet DISTINTA COMPLETA
A1: Assieme / Kit | B1: Sezione | C1: Pos. | D1: Codice | E1: Descrizione | F1: Categoria | G1: Q.tà | H1: Q.tà 12 mod | I1: Q.tà 18 mod | J1: Q.tà 20 mod | K1: Q.tà 22 mod | L1: Q.tà 36 mod | M1: Q.tà 40 mod | N1: Già caricato altrove | O1: U.M. | P1: Peso elemento (kg) | Q1: Prezzo unitario € | R1: Importo €
A2: PILASTRO MOTORE | C2: 1 | D2: TTS.PF.001.IPE140.30 | E2: Pilastro fondazione trave IPE140 mt.3,00 | F2: Carpenteria metallica | G2: 1 | O2: pz | Q2: =IFERROR(VLOOKUP($D2,LISTINO!$B:$I,6,FALSE),IFERROR(VLOOKUP($E2,LISTINO!$C:$I,5,FALSE),"")) -> 0 | R2: =IF(AND(ISNUMBER(G2),ISNUMBER(Q2)),G2*Q2,"") -> 0
A3: PILASTRO MOTORE | C3: 1 | D3: TTS.PF.001.IPEA140.30 | E3: Pilastro fondazione trave IPEA140 mt.3,00 (alleggerita) | F3: Carpenteria metallica | G3: 0 | O3: pz | Q3: =IFERROR(VLOOKUP($D3,LISTINO!$B:$I,6,FALSE),IFERROR(VLOOKUP($E3,LISTINO!$C:$I,5,FALSE),"")) -> 0 | R3: =IF(AND(ISNUMBER(G3),ISNUMBER(Q3)),G3*Q3,"") -> 0
A4: PILASTRO MOTORE | C4: 1 | D4: TTS.PF.001.IPE140.26 | E4: Pilastro fondazione trave IPE140 mt.2,60 | F4: Carpenteria metallica | G4: 0 | O4: pz | Q4: =IFERROR(VLOOKUP($D4,LISTINO!$B:$I,6,FALSE),IFERROR(VLOOKUP($E4,LISTINO!$C:$I,5,FALSE),"")) -> 0 | R4: =IF(AND(ISNUMBER(G4),ISNUMBER(Q4)),G4*Q4,"") -> 0
A5: PILASTRO MOTORE | C5: 1 | D5: TTS.PF.001.IPEA140.26 | E5: Pilastro fondazione trave IPEA140 mt.2,60 (alleggerita) | F5: Carpenteria metallica | G5: 0 | O5: pz | Q5: =IFERROR(VLOOKUP($D5,LISTINO!$B:$I,6,FALSE),IFERROR(VLOOKUP($E5,LISTINO!$C:$I,5,FALSE),"")) -> 0 | R5: =IF(AND(ISNUMBER(G5),ISNUMBER(Q5)),G5*Q5,"") -> 0
A6: PILASTRO MOTORE | C6: 1 | D6: TTS.PF.001.IPE140.27 | E6: Pilastro fondazione trave IPE140 mt.2,70 | F6: Carpenteria metallica | G6: 0 | O6: pz | Q6: =IFERROR(VLOOKUP($D6,LISTINO!$B:$I,6,FALSE),IFERROR(VLOOKUP($E6,LISTINO!$C:$I,5,FALSE),"")) -> 0 | R6: =IF(AND(ISNUMBER(G6),ISNUMBER(Q6)),G6*Q6,"") -> 0
A7: PILASTRO MOTORE | C7: 1 | D7: TTS.PF.001.IPEA140.27 | E7: Pilastro fondazione trave IPEA140 mt.2,70 (alleggerita) | F7: Carpenteria metallica | G7: 0 | O7: pz | Q7: =IFERROR(VLOOKUP($D7,LISTINO!$B:$I,6,FALSE),IFERROR(VLOOKUP($E7,LISTINO!$C:$I,5,FALSE),"")) -> 0 | R7: =IF(AND(ISNUMBER(G7),ISNUMBER(Q7)),G7*Q7,"") -> 0
A8: PILASTRO MOTORE | C8: 1 | D8: TTS.PF.001.IPE140.28 | E8: Pilastro fondazione trave IPE140 mt.2,80 | F8: Carpenteria metallica | G8: 0 | O8: pz | Q8: =IFERROR(VLOOKUP($D8,LISTINO!$B:$I,6,FALSE),IFERROR(VLOOKUP($E8,LISTINO!$C:$I,5,FALSE),"")) -> 0 | R8: =IF(AND(ISNUMBER(G8),ISNUMBER(Q8)),G8*Q8,"") -> 0
A9: PILASTRO MOTORE | C9: 1 | D9: TTS.PF.001.IPEA140.28 | E9: Pilastro fondazione trave IPEA140 mt.2,80 (alleggerita) | F9: Carpenteria metallica | G9: 0 | O9: pz | Q9: =IFERROR(VLOOKUP($D9,LISTINO!$B:$I,6,FALSE),IFERROR(VLOOKUP($E9,LISTINO!$C:$I,5,FALSE),"")) -> 0 | R9: =IF(AND(ISNUMBER(G9),ISNUMBER(Q9)),G9*Q9,"") -> 0
A10: PILASTRO MOTORE | C10: 1 | D10: TTS.PF.001.IPE140.29 | E10: Pilastro fondazione trave IPE140 mt.2,90 | F10: Carpenteria metallica | G10: 0 | O10: pz | Q10: =IFERROR(VLOOKUP($D10,LISTINO!$B:$I,6,FALSE),IFERROR(VLOOKUP($E10,LISTINO!$C:$I,5,FALSE),"")) -> 0 | R10: =IF(AND(ISNUMBER(G10),ISNUMBER(Q10)),G10*Q10,"") -> 0
A11: PILASTRO MOTORE | C11: 1 | D11: TTS.PF.001.IPEA140.29 | E11: Pilastro fondazione trave IPEA140 mt.2,90 (alleggerita) | F11: Carpenteria metallica | G11: 0 | O11: pz | Q11: =IFERROR(VLOOKUP($D11,LISTINO!$B:$I,6,FALSE),IFERROR(VLOOKUP($E11,LISTINO!$C:$I,5,FALSE),"")) -> 0 | R11: =IF(AND(ISNUMBER(G11),ISNUMBER(Q11)),G11*Q11,"") -> 0
A12: PILASTRO MOTORE | C12: 1 | D12: TTS.PF.001.IPE140.31 | E12: Pilastro fondazione trave IPE140 mt.3,10 | F12: Carpenteria metallica | G12: 0 | O12: pz | Q12: =IFERROR(VLOOKUP($D12,LISTINO!$B:$I,6,FALSE),IFERROR(VLOOKUP($E12,LISTINO!$C:$I,5,FALSE),"")) -> 0 | R12: =IF(AND(ISNUMBER(G12),ISNUMBER(Q12)),G12*Q12,"") -> 0
A13: PILASTRO MOTORE | C13: 1 | D13: TTS.PF.001.IPEA140.31 | E13: Pilastro fondazione trave IPEA140 mt.3,10 (alleggerita) | F13: Carpenteria metallica | G13: 0 | O13: pz | Q13: =IFERROR(VLOOKUP($D13,LISTINO!$B:$I,6,FALSE),IFERROR(VLOOKUP($E13,LISTINO!$C:$I,5,FALSE),"")) -> 0 | R13: =IF(AND(ISNUMBER(G13),ISNUMBER(Q13)),G13*Q13,"") -> 0
... A82: PILASTRO MOTORE | C82: 6 | D82: 10DAZAM16 | E82: Dado autobloccante M16 | F82: Bulloneria e minuteria | G82: 4 | O82: pz | Q82: =IFERROR(VLOOKUP($D82,LISTINO!$B:$I,6,FALSE),IFERROR(VLOOKUP($E82,LISTINO!$C:$I,5,FALSE),"")) | R82: =IF(AND(ISNUMBER(G82),ISNUMBER(Q82)),G82*Q82,"")
A83: PILASTRO CUSCINETTO | C83: 1 | D83: TTS.PF.001.IPE140.30 | E83: Pilastro fondazione trave IPE140 mt3,00 | F83: Carpenteria metallica | G83: 1 | H83: 2 | I83: 4 | J83: 4 | K83: 4 | L83: 8 | M83: 10 | O83: pz | Q83: =IFERROR(VLOOKUP($D83,LISTINO!$B:$I,6,FALSE),IFERROR(VLOOKUP($E83,LISTINO!$C:$I,5,FALSE),"")) -> 0 | R83: =IF(AND(ISNUMBER(G83),ISNUMBER(Q83)),G83*Q83,"") -> 0
A84: PILASTRO CUSCINETTO | C84: 2 | D84: TTS.PC.001.IPE140.23 | E84: Pilastro cuscinetto trave IPE 140 mt.2,30 | F84: Carpenteria metallica | G84: 1 | H84: 2 | I84: 4 | J84: 4 | K84: 4 | L84: 8 | M84: 10 | O84: pz | Q84: =IFERROR(VLOOKUP($D84,LISTINO!$B:$I,6,FALSE),IFERROR(VLOOKUP($E84,LISTINO!$C:$I,5,FALSE),"")) -> 0 | R84: =IF(AND(ISNUMBER(G84),ISNUMBER(Q84)),G84*Q84,"") -> 0
A85: PILASTRO CUSCINETTO | C85: 2 | D85: TTS.PC.001.IPEA140.23 | E85: Pilastro cuscinetto trave IPEA 140 mt.2,30 (alleggerita) | F85: Carpenteria metallica | G85: 0 | O85: pz | Q85: =IFERROR(VLOOKUP($D85,LISTINO!$B:$I,6,FALSE),IFERROR(VLOOKUP($E85,LISTINO!$C:$I,5,FALSE),"")) -> 0 | R85: =IF(AND(ISNUMBER(G85),ISNUMBER(Q85)),G85*Q85,"") -> 0
A86: PILASTRO CUSCINETTO | C86: 2 | D86: TTS.PC.001.IPE140.28 | E86: Pilastro cuscinetto trave IPE 140 mt.2,80 | F86: Carpenteria metallica | G86: 0 | O86: pz | Q86: =IFERROR(VLOOKUP($D86,LISTINO!$B:$I,6,FALSE),IFERROR(VLOOKUP($E86,LISTINO!$C:$I,5,FALSE),"")) -> 0 | R86: =IF(AND(ISNUMBER(G86),ISNUMBER(Q86)),G86*Q86,"") -> 0
A87: PILASTRO CUSCINETTO | C87: 2 | D87: TTS.PC.001.IPEA140.28 | E87: Pilastro cuscinetto trave IPEA 140 mt.2,80 (alleggerita) | F87: Carpenteria metallica | G87: 0 | O87: pz | Q87: =IFERROR(VLOOKUP($D87,LISTINO!$B:$I,6,FALSE),IFERROR(VLOOKUP($E87,LISTINO!$C:$I,5,FALSE),"")) -> 0 | R87: =IF(AND(ISNUMBER(G87),ISNUMBER(Q87)),G87*Q87,"") -> 0
A88: PILASTRO CUSCINETTO | C88: 2 | D88: TTS.PC.001.IPE140.29 | E88: Pilastro cuscinetto trave IPE 140 mt.2,90 | F88: Carpenteria metallica | G88: 0 | O88: pz | Q88: =IFERROR(VLOOKUP($D88,LISTINO!$B:$I,6,FALSE),IFERROR(VLOOKUP($E88,LISTINO!$C:$I,5,FALSE),"")) -> 0 | R88: =IF(AND(ISNUMBER(G88),ISNUMBER(Q88)),G88*Q88,"") -> 0
A89: PILASTRO CUSCINETTO | C89: 2 | D89: TTS.PC.001.IPEA140.29 | E89: Pilastro cuscinetto trave IPEA 140 mt.2,90 (alleggerita) | F89: Carpenteria metallica | G89: 0 | O89: pz | Q89: =IFERROR(VLOOKUP($D89,LISTINO!$B:$I,6,FALSE),IFERROR(VLOOKUP($E89,LISTINO!$C:$I,5,FALSE),"")) -> 0 | R89: =IF(AND(ISNUMBER(G89),ISNUMBER(Q89)),G89*Q89,"") -> 0
A90: PILASTRO CUSCINETTO | C90: 2 | D90: TTS.PC.001.IPE140.30 | E90: Pilastro cuscinetto trave IPE 140 mt.3,00 | F90: Carpenteria metallica | G90: 0 | O90: pz | Q90: =IFERROR(VLOOKUP($D90,LISTINO!$B:$I,6,FALSE),IFERROR(VLOOKUP($E90,LISTINO!$C:$I,5,FALSE),"")) -> 0 | R90: =IF(AND(ISNUMBER(G90),ISNUMBER(Q90)),G90*Q90,"") -> 0
A91: PILASTRO CUSCINETTO | C91: 2 | D91: TTS.PC.001.IPEA140.30 | E91: Pilastro cuscinetto trave IPEA 140 mt.3,00 (alleggerita) | F91: Carpenteria metallica | G91: 0 | O91: pz | Q91: =IFERROR(VLOOKUP($D91,LISTINO!$B:$I,6,FALSE),IFERROR(VLOOKUP($E91,LISTINO!$C:$I,5,FALSE),"")) -> 0 | R91: =IF(AND(ISNUMBER(G91),ISNUMBER(Q91)),G91*Q91,"") -> 0
A92: PILASTRO CUSCINETTO | C92: 2 | D92: TTS.PC.001.IPE140.31 | E92: Pilastro cuscinetto trave IPE 140 mt.3,10 | F92: Carpenteria metallica | G92: 0 | O92: pz | Q92: =IFERROR(VLOOKUP($D92,LISTINO!$B:$I,6,FALSE),IFERROR(VLOOKUP($E92,LISTINO!$C:$I,5,FALSE),"")) -> 0 | R92: =IF(AND(ISNUMBER(G92),ISNUMBER(Q92)),G92*Q92,"") -> 0
A93: PILASTRO CUSCINETTO | C93: 2 | D93: TTS.PC.001.IPEA140.31 | E93: Pilastro cuscinetto trave IPEA 140 mt.3,10 (alleggerita) | F93: Carpenteria metallica | G93: 0 | O93: pz | Q93: =IFERROR(VLOOKUP($D93,LISTINO!$B:$I,6,FALSE),IFERROR(VLOOKUP($E93,LISTINO!$C:$I,5,FALSE),"")) -> 0 | R93: =IF(AND(ISNUMBER(G93),ISNUMBER(Q93)),G93*Q93,"") -> 0
A94: PILASTRO CUSCINETTO | C94: 2 | D94: TTS.PC.001.IPE140.32 | E94: Pilastro cuscinetto trave IPE 140 mt.3,20 | F94: Carpenteria metallica | G94: 0 | O94: pz | Q94: =IFERROR(VLOOKUP($D94,LISTINO!$B:$I,6,FALSE),IFERROR(VLOOKUP($E94,LISTINO!$C:$I,5,FALSE),"")) -> 0 | R94: =IF(AND(ISNUMBER(G94),ISNUMBER(Q94)),G94*Q94,"") -> 0
A95: PILASTRO CUSCINETTO | C95: 2 | D95: TTS.PC.001.IPEA140.32 | E95: Pilastro cuscinetto trave IPEA 140 mt.3,20 (alleggerita) | F95: Carpenteria metallica | G95: 0 | O95: pz | Q95: =IFERROR(VLOOKUP($D95,LISTINO!$B:$I,6,FALSE),IFERROR(VLOOKUP($E95,LISTINO!$C:$I,5,FALSE),"")) -> 0 | R95: =IF(AND(ISNUMBER(G95),ISNUMBER(Q95)),G95*Q95,"") -> 0
A96: PILASTRO CUSCINETTO | C96: 2 | D96: TTS.PC.001.IPE140.33 | E96: Pilastro cuscinetto trave IPE 140 mt.3,30 | F96: Carpenteria metallica | G96: 0 | O96: pz | Q96: =IFERROR(VLOOKUP($D96,LISTINO!$B:$I,6,FALSE),IFERROR(VLOOKUP($E96,LISTINO!$C:$I,5,FALSE),"")) -> 0 | R96: =IF(AND(ISNUMBER(G96),ISNUMBER(Q96)),G96*Q96,"") -> 0
... A121: PILASTRO CUSCINETTO | C121: 2 | D121: TTS.PC.001.IPEA140.45 | E121: Pilastro cuscinetto trave IPEA 140 mt.4,50 (alleggerita) | F121: Carpenteria metallica | G121: 0 | O121: pz | Q121: =IFERROR(VLOOKUP($D121,LISTINO!$B:$I,6,FALSE),IFERROR(VLOOKUP($E121,LISTINO!$C:$I,5,FALSE),"")) -> 0 | R121: =IF(AND(ISNUMBER(G121),ISNUMBER(Q121)),G121*Q121,"") -> 0
A122: PILASTRO CUSCINETTO | C122: 3 | D122: TTS.PF.002.IPE140 | E122: Piastra giunzione montanti centrale 200x100x4 (8 fori Ø 11) | F122: Carpenteria metallica | G122: 2 | H122: 4 | I122: 8 | J122: 8 | K122: 8 | L122: 16 | M122: 20 | O122: pz | Q122: =IFERROR(VLOOKUP($D122,LISTINO!$B:$I,6,FALSE),IFERROR(VLOOKUP($E122,LISTINO!$C:$I,5,FALSE),"")) -> 0 | R122: =IF(AND(ISNUMBER(G122),ISNUMBER(Q122)),G122*Q122,"") -> 0
A123: PILASTRO CUSCINETTO | C123: 4 | D123: 10BZM10X40 | E123: Bullone testa esagonale M10X40 | F123: Bulloneria e minuteria | G123: 8 | H123: 16 | I123: 32 | J123: 32 | K123: 32 | L123: 64 | M123: 80 | O123: pz | Q123: =IFERROR(VLOOKUP($D123,LISTINO!$B:$I,6,FALSE),IFERROR(VLOOKUP($E123,LISTINO!$C:$I,5,FALSE),"")) | R123: =IF(AND(ISNUMBER(G123),ISNUMBER(Q123)),G123*Q123,"")
A124: PILASTRO CUSCINETTO | C124: 5 | D124: 10ROND10 | E124: Rondella zn da 10 | F124: Bulloneria e minuteria | G124: 8 | H124: 16 | I124: 32 | J124: 32 | K124: 32 | L124: 64 | M124: 80 | O124: pz | Q124: =IFERROR(VLOOKUP($D124,LISTINO!$B:$I,6,FALSE),IFERROR(VLOOKUP($E124,LISTINO!$C:$I,5,FALSE),"")) | R124: =IF(AND(ISNUMBER(G124),ISNUMBER(Q124)),G124*Q124,"")
A125: PILASTRO CUSCINETTO | C125: 6 | D125: 10ROND10 | E125: Rondella zn da 10 | F125: Bulloneria e minuteria | G125: 8 | H125: 16 | I125: 32 | J125: 32 | K125: 32 | L125: 64 | M125: 80 | O125: pz | Q125: =IFERROR(VLOOKUP($D125,LISTINO!$B:$I,6,FALSE),IFERROR(VLOOKUP($E125,LISTINO!$C:$I,5,FALSE),"")) | R125: =IF(AND(ISNUMBER(G125),ISNUMBER(Q125)),G125*Q125,"")
A126: PILASTRO CUSCINETTO | C126: 7 | D126: 10DAZAM10 | E126: Dado autobloccante M10 | F126: Bulloneria e minuteria | G126: 8 | H126: 16 | I126: 32 | J126: 32 | K126: 32 | L126: 64 | M126: 80 | O126: pz | Q126: =IFERROR(VLOOKUP($D126,LISTINO!$B:$I,6,FALSE),IFERROR(VLOOKUP($E126,LISTINO!$C:$I,5,FALSE),"")) | R126: =IF(AND(ISNUMBER(G126),ISNUMBER(Q126)),G126*Q126,"")
A127: PILASTRO CUSCINETTO | C127: 1 | D127: TTS.PF.003.IPE140 | E127: Piastra giunzione montanti esterna 240x70x6 (12 fori Ø 11) | F127: Carpenteria metallica | G127: 2 | H127: 4 | I127: 8 | J127: 8 | K127: 8 | L127: 16 | M127: 20 | O127: pz | Q127: =IFERROR(VLOOKUP($D127,LISTINO!$B:$I,6,FALSE),IFERROR(VLOOKUP($E127,LISTINO!$C:$I,5,FALSE),"")) -> 0 | R127: =IF(AND(ISNUMBER(G127),ISNUMBER(Q127)),G127*Q127,"") -> 0
A128: PILASTRO CUSCINETTO | C128: 2 | D128: TTS.PF.004.IPE140 | E128: Piastra giunzione montanti interna 240x25x6 (6 fori Ø 11) | F128: Carpenteria metallica | G128: 4 | H128: 8 | I128: 16 | J128: 16 | K128: 16 | L128: 32 | M128: 40 | O128: pz | Q128: =IFERROR(VLOOKUP($D128,LISTINO!$B:$I,6,FALSE),IFERROR(VLOOKUP($E128,LISTINO!$C:$I,5,FALSE),"")) -> 0 | R128: =IF(AND(ISNUMBER(G128),ISNUMBER(Q128)),G128*Q128,"") -> 0
A129: PILASTRO CUSCINETTO | C129: 3 | D129: 10BZM10X40 | E129: Bullone testa esagonale M10X40 | F129: Bulloneria e minuteria | G129: 24 | H129: 48 | I129: 96 | J129: 96 | K129: 96 | L129: 192 | M129: 240 | O129: pz | Q129: =IFERROR(VLOOKUP($D129,LISTINO!$B:$I,6,FALSE),IFERROR(VLOOKUP($E129,LISTINO!$C:$I,5,FALSE),"")) | R129: =IF(AND(ISNUMBER(G129),ISNUMBER(Q129)),G129*Q129,"")
A130: PILASTRO CUSCINETTO | C130: 4 | D130: 10ROND10 | E130: Rondella zn da 10 | F130: Bulloneria e minuteria | G130: 24 | H130: 48 | I130: 96 | J130: 96 | K130: 96 | L130: 192 | M130: 240 | O130: pz | Q130: =IFERROR(VLOOKUP($D130,LISTINO!$B:$I,6,FALSE),IFERROR(VLOOKUP($E130,LISTINO!$C:$I,5,FALSE),"")) | R130: =IF(AND(ISNUMBER(G130),ISNUMBER(Q130)),G130*Q130,"")
A131: PILASTRO CUSCINETTO | C131: 5 | D131: 10ROND10 | E131: Rondella zn da 10 | F131: Bulloneria e minuteria | G131: 24 | H131: 48 | I131: 96 | J131: 96 | K131: 96 | L131: 192 | M131: 240 | O131: pz | Q131: =IFERROR(VLOOKUP($D131,LISTINO!$B:$I,6,FALSE),IFERROR(VLOOKUP($E131,LISTINO!$C:$I,5,FALSE),"")) | R131: =IF(AND(ISNUMBER(G131),ISNUMBER(Q131)),G131*Q131,"")
A132: PILASTRO CUSCINETTO | C132: 6 | D132: 10DAZAM10 | E132: Dado autobloccante M10 | F132: Bulloneria e minuteria | G132: 24 | H132: 48 | I132: 96 | J132: 96 | K132: 96 | L132: 192 | M132: 240 | O132: pz | Q132: =IFERROR(VLOOKUP($D132,LISTINO!$B:$I,6,FALSE),IFERROR(VLOOKUP($E132,LISTINO!$C:$I,5,FALSE),"")) | R132: =IF(AND(ISNUMBER(G132),ISNUMBER(Q132)),G132*Q132,"")
...

Sheet RIEPILOGO
A1: RIEPILOGO LISTINO
A3: Componenti unici a listino | B3: 198
A4: Righe di distinta totali (tutti i kit) | B4: 343
A6: Componenti unici per categoria
A7: Carpenteria metallica | B7: 155
A8: Bulloneria e minuteria | B8: 31
A9: Motorizzazione | B9: 1
A10: Cuscinetti | B10: 1
A11: Quadristica ed elettrico | B11: 2
A12: Sensoristica e strumentazione | B12: 6
A13: Moduli fotovoltaici | B13: 2
A15: Legenda
A16: • LISTINO: un record per ogni componente; 'Prezzo unitario' da compilare a cura ufficio acquisti.
A17: • DISTINTA COMPLETA: tutte le righe di tutti i fogli della distinta originale (vista integrale).
A18: • Colonne 'Q.tà NN mod': quantità previste per le sei configurazioni di tracker (dove indicate in origine).
A19: • 'Già caricato altrove' = X: articolo evidenziato in rosso nella distinta originale (non riconteggiare).
A20: • 'Importo €' e 'TOTALE' si calcolano automaticamente dopo aver compilato i prezzi nel foglio LISTINO.
A21: • 'Peso elemento (kg)' (LISTINO e DISTINTA): colonna da compilare a mano, un valore per riga.
A22: • Righe DISTINTA con Q.tà = 0: referenze alternative (varianti di spessore o lunghezza) create al rev.5, poste sotto l'articolo base; impostare la Q.tà quando la variante viene scelta in configurazione.
A23: • Referenze 'IPEA' (codice ...IPEA140...): travi alleggerite, duplicato di ogni pilastro/supporto IPE 140; in DISTINTA sono righe con Q.tà = 0 sotto la versione IPE.
A24: • Foglio 'SCHEDA STRUTTURA': riferimento per la carpenteria strutturale a barra. Blocco 'Profili' = travi IPE/IPEA e assi di rotazione (kg/m); per ogni codice il 'Peso elemento (kg)' = lunghezza × kg/m finale. Costo acquisto (€) = peso al netto × €/kg acquisto; Costo zincatura (€) = peso al netto × (1 + magg. %) × €/kg zincatura, solo se la maggiorazione è presente.
A25: • Foglio 'SCHEDA PEZZI SPECIALI': pezzi 'a pezzo' di carpenteria metallica (piastre di giunzione montanti, supporti testa cuscinetto/riduttore, angolari, omega, pali MAX, aste sensori). Blocco 'Parametri' = una voce per pezzo con Peso pezzo (kg), % zincatura, €/kg acquisto e €/kg zincatura; blocco 'Elenco' = peso e costi calcolati via VLOOKUP. Nel LISTINO il 'Peso elemento' di travi, assi e pezzi speciali arriva da questi due fogli; gli altri pesi restano manuali. Escluso il pezzo senza codice 'Omega alloggiamento kit sensore termometro a contatto' (LISTINO riga 165).
A26: • Foglio 'SCHEDA BULLONERIA': bulloneria e minuteria commerciale (bulloni, dadi autobloccanti, rondelle). Blocco 'Parametri' = Peso unitario (kg) [valori nominali DIN, da confermare] e Costo (€/pz); blocco 'Elenco' = peso e costo via VLOOKUP. Nel LISTINO 'Peso elemento' e 'Prezzo unitario €' dei 31 codici di questa categoria arrivano da qui.
A27: • Foglio 'SCHEDA ELETTROMECCANICA': tabella unica dei materiali elettromeccanici commerciali (motoriduttore, cuscinetto, quadri/box, sensori). Peso unitario (kg) e Costo (€/pz) da compilare a mano; nel LISTINO 'Peso elemento' e 'Prezzo unitario €' di questi codici arrivano da qui.
